Workbook
Name CAP_A: Handicaps!#REF!
Name CAP_B: Handicaps!$B$7
Name HDCP_GRP_A1: Handicaps!#REF!
Name HDCP_GRP_A2: Handicaps!#REF!
Name HDCP_GRP_A3: Handicaps!#REF!
Name HDCP_GRP_A4: Handicaps!#REF!
Name HDCP_GRP_B1: Handicaps!$B$2
Name HDCP_GRP_B2: Handicaps!$B$3
Name HDCP_GRP_B3: Handicaps!$B$4
Name HDCP_GRP_B4: Handicaps!$B$5
Name HDCP_V_B1: Handicaps!$C$2
Name HDCP_V_B2: Handicaps!$C$3
Name HDCP_V_B3: Handicaps!$C$4
Name HDCP_V_B4: Handicaps!$C$5
Name POINTS_CAP_A: Handicaps!#REF!
Name POINTS_CAP_B: Handicaps!$C$7

Sheet Stage Data - A
B1: Handicap Group | D1: Stage 1 | J1: Stage 2 | P1: Stage 3 | V1: Stage 4 | AB1: Stage 5 | AH1: Stage 6 | AN1: Base Points | AO1: Adjusted Points
D2: Position | E2: Time | F2: Points | J2: Position | K2: Time | L2: Points | P2: Position | Q2: Time | R2: Points | V2: Position | W2: Time | X2: Points | AB2: Position | AC2: Time | AD2: Points | AH2: Position | AI2: Time | AJ2: Points
A3: Name | F3: Base | G3: Handicap | H3: Adjusted | L3: Base | M3: Handicap | N3: Adjusted | R3: Base | S3: Handicap | T3: Adjusted | X3: Base | Y3: Handicap | Z3: Adjusted | AD3: Base | AE3: Handicap | AF3: Adjusted | AJ3: Base | AK3: Handicap | AL3: Adjusted
A5: Raif Oz | B5: 2 | D5: 4 | E5: 0.011597222 | F5: =IF(COUNT(D$5:D$48)=0,"",IF(ISNUMBER(D5),POINTS_CAP_B-D5,0)) -> 31 | G5: =IF(COUNT(D$5:D$48)=0,"", IFERROR(CHOOSE($B5,HDCP_V_B1,HDCP_V_B2,HDCP_V_B3,HDCP_V_B4),0)) -> 5 | H5: =IF(COUNT(D$5:D$48)=0,"",MIN(F5+G5,POINTS_CAP_B)) -> 35 | J5: 6 | K5: 0.021064815 | L5: =IF(COUNT(J$5:J$48)=0,"",IF(ISNUMBER(J5),POINTS_CAP_B-J5,0)) -> 29 | M5: =IF(COUNT(J$5:J$48)=0,"", IFERROR(CHOOSE($B5,HDCP_V_B1,HDCP_V_B2,HDCP_V_B3,HDCP_V_B4),0)) -> 5 | N5: =IF(COUNT(J$5:J$48)=0,"",MIN(L5+M5,POINTS_CAP_B)) -> 34 | P5: 4 | Q5: 0.017418981 | R5: =IF(COUNT(P$5:P$48)=0,"",IF(ISNUMBER(P5),POINTS_CAP_B-P5,0)) -> 31 | S5: =IF(COUNT(P$5:P$48)=0,"", IFERROR(CHOOSE($B5,HDCP_V_B1,HDCP_V_B2,HDCP_V_B3,HDCP_V_B4),0)) -> 5 | T5: =IF(COUNT(P$5:P$48)=0,"",MIN(R5+S5,POINTS_CAP_B)) -> 35 | V5: 5 | W5: 0.034699074 | X5: =IF(COUNT(V$5:V$48)=0,"",IF(ISNUMBER(V5),POINTS_CAP_B-V5,0)) -> 30 | Y5: =IF(COUNT(V$5:V$48)=0,"", IFERROR(CHOOSE($B5,HDCP_V_B1,HDCP_V_B2,HDCP_V_B3,HDCP_V_B4),0)) -> 5 | Z5: =IF(COUNT(V$5:V$48)=0,"",MIN(X5+Y5,POINTS_CAP_B)) -> 35 | AB5: 4 | AC5: 0.035335648 | AD5: =IF(COUNT(AB$5:AB$48)=0,"",IF(ISNUMBER(AB5),POINTS_CAP_B-AB5,0)) -> 31 | AE5: =IF(COUNT(AB$5:AB$48)=0,"", IFERROR(CHOOSE($B5,HDCP_V_B1,HDCP_V_B2,HDCP_V_B3,HDCP_V_B4),0)) -> 5 | AF5: =IF(COUNT(AB$5:AB$48)=0,"",MIN(AD5+AE5,POINTS_CAP_B)) -> 35 | AH5: 3 | AI5: 0.02494213 | AJ5: =IF(COUNT(AH$5:AH$48)=0,"",IF(ISNUMBER(AH5),POINTS_CAP_B-AH5,0)) -> 32 | AK5: =IF(COUNT(AH$5:AH$48)=0,"", IFERROR(CHOOSE($B5,HDCP_V_B1,HDCP_V_B2,HDCP_V_B3,HDCP_V_B4),0)) -> 5 | AL5: =IF(COUNT(AH$5:AH$48)=0,"",MIN(AJ5+AK5,POINTS_CAP_B)) -> 35 | AN5: =SUM(F5,L5,R5,X5,AD5,AJ5) -> 184 | AO5: =SUM(H5,N5,T5,Z5,AF5,AL5) -> 209
A6: Judah Rand | B6: 1 | D6: 5 | E6: 0.011608796 | F6: =IF(COUNT(D$5:D$48)=0,"",IF(ISNUMBER(D6),POINTS_CAP_B-D6,0)) -> 30 | G6: =IF(COUNT(D$5:D$48)=0,"", IFERROR(CHOOSE($B6,HDCP_V_B1,HDCP_V_B2,HDCP_V_B3,HDCP_V_B4),0)) -> 0 | H6: =IF(COUNT(D$5:D$48)=0,"",MIN(F6+G6,POINTS_CAP_B)) -> 30 | J6: 1 | K6: 0.020810185 | L6: =IF(COUNT(J$5:J$48)=0,"",IF(ISNUMBER(J6),POINTS_CAP_B-J6,0)) -> 34 | M6: =IF(COUNT(J$5:J$48)=0,"", IFERROR(CHOOSE($B6,HDCP_V_B1,HDCP_V_B2,HDCP_V_B3,HDCP_V_B4),0)) -> 0 | N6: =IF(COUNT(J$5:J$48)=0,"",MIN(L6+M6,POINTS_CAP_B)) -> 34 | P6: 1 | Q6: 0.017094907 | R6: =IF(COUNT(P$5:P$48)=0,"",IF(ISNUMBER(P6),POINTS_CAP_B-P6,0)) -> 34 | S6: =IF(COUNT(P$5:P$48)=0,"", IFERROR(CHOOSE($B6,HDCP_V_B1,HDCP_V_B2,HDCP_V_B3,HDCP_V_B4),0)) -> 0 | T6: =IF(COUNT(P$5:P$48)=0,"",MIN(R6+S6,POINTS_CAP_B)) -> 34 | V6: 1 | W6: 0.031782407 | X6: =IF(COUNT(V$5:V$48)=0,"",IF(ISNUMBER(V6),POINTS_CAP_B-V6,0)) -> 34 | Y6: =IF(COUNT(V$5:V$48)=0,"", IFERROR(CHOOSE($B6,HDCP_V_B1,HDCP_V_B2,HDCP_V_B3,HDCP_V_B4),0)) -> 0 | Z6: =IF(COUNT(V$5:V$48)=0,"",MIN(X6+Y6,POINTS_CAP_B)) -> 34 | AB6: 1 | AC6: 0.034155093 | AD6: =IF(COUNT(AB$5:AB$48)=0,"",IF(ISNUMBER(AB6),POINTS_CAP_B-AB6,0)) -> 34 | AE6: =IF(COUNT(AB$5:AB$48)=0,"", IFERROR(CHOOSE($B6,HDCP_V_B1,HDCP_V_B2,HDCP_V_B3,HDCP_V_B4),0)) -> 0 | AF6: =IF(COUNT(AB$5:AB$48)=0,"",MIN(AD6+AE6,POINTS_CAP_B)) -> 34 | AH6: 2 | AI6: 0.024849537 | AJ6: =IF(COUNT(AH$5:AH$48)=0,"",IF(ISNUMBER(AH6),POINTS_CAP_B-AH6,0)) -> 33 | AK6: =IF(COUNT(AH$5:AH$48)=0,"", IFERROR(CHOOSE($B6,HDCP_V_B1,HDCP_V_B2,HDCP_V_B3,HDCP_V_B4),0)) -> 0 | AL6: =IF(COUNT(AH$5:AH$48)=0,"",MIN(AJ6+AK6,POINTS_CAP_B)) -> 33 | AN6: =SUM(F6,L6,R6,X6,AD6,AJ6) -> 199 | AO6: =SUM(H6,N6,T6,Z6,AF6,AL6) -> 199
A7: Tobi Rosenkranz | B7: 2 | D7: 8 | E7: 0.011724537 | F7: =IF(COUNT(D$5:D$48)=0,"",IF(ISNUMBER(D7),POINTS_CAP_B-D7,0)) -> 27 | G7: =IF(COUNT(D$5:D$48)=0,"", IFERROR(CHOOSE($B7,HDCP_V_B1,HDCP_V_B2,HDCP_V_B3,HDCP_V_B4),0)) -> 5 | H7: =IF(COUNT(D$5:D$48)=0,"",MIN(F7+G7,POINTS_CAP_B)) -> 32 | J7: 3 | K7: 0.020868056 | L7: =IF(COUNT(J$5:J$48)=0,"",IF(ISNUMBER(J7),POINTS_CAP_B-J7,0)) -> 32 | M7: =IF(COUNT(J$5:J$48)=0,"", IFERROR(CHOOSE($B7,HDCP_V_B1,HDCP_V_B2,HDCP_V_B3,HDCP_V_B4),0)) -> 5 | N7: =IF(COUNT(J$5:J$48)=0,"",MIN(L7+M7,POINTS_CAP_B)) -> 35 | P7: 4 | Q7: 0.017418981 | R7: =IF(COUNT(P$5:P$48)=0,"",IF(ISNUMBER(P7),POINTS_CAP_B-P7,0)) -> 31 | S7: =IF(COUNT(P$5:P$48)=0,"", IFERROR(CHOOSE($B7,HDCP_V_B1,HDCP_V_B2,HDCP_V_B3,HDCP_V_B4),0)) -> 5 | T7: =IF(COUNT(P$5:P$48)=0,"",MIN(R7+S7,POINTS_CAP_B)) -> 35 | V7: 10 | W7: 0.037164352 | X7: =IF(COUNT(V$5:V$48)=0,"",IF(ISNUMBER(V7),POINTS_CAP_B-V7,0)) -> 25 | Y7: =IF(COUNT(V$5:V$48)=0,"", IFERROR(CHOOSE($B7,HDCP_V_B1,HDCP_V_B2,HDCP_V_B3,HDCP_V_B4),0)) -> 5 | Z7: =IF(COUNT(V$5:V$48)=0,"",MIN(X7+Y7,POINTS_CAP_B)) -> 30 | AB7: 5 | AC7: 0.035381944 | AD7: =IF(COUNT(AB$5:AB$48)=0,"",IF(ISNUMBER(AB7),POINTS_CAP_B-AB7,0)) -> 30 | AE7: =IF(COUNT(AB$5:AB$48)=0,"", IFERROR(CHOOSE($B7,HDCP_V_B1,HDCP_V_B2,HDCP_V_B3,HDCP_V_B4),0)) -> 5 | AF7: =IF(COUNT(AB$5:AB$48)=0,"",MIN(AD7+AE7,POINTS_CAP_B)) -> 35 | AH7: 5 | AI7: 0.025555556 | AJ7: =IF(COUNT(AH$5:AH$48)=0,"",IF(ISNUMBER(AH7),POINTS_CAP_B-AH7,0)) -> 30 | AK7: =IF(COUNT(AH$5:AH$48)=0,"", IFERROR(CHOOSE($B7,HDCP_V_B1,HDCP_V_B2,HDCP_V_B3,HDCP_V_B4),0)) -> 5 | AL7: =IF(COUNT(AH$5:AH$48)=0,"",MIN(AJ7+AK7,POINTS_CAP_B)) -> 35 | AN7: =SUM(F7,L7,R7,X7,AD7,AJ7) -> 175 | AO7: =SUM(H7,N7,T7,Z7,AF7,AL7) -> 202
A8: Seb Ashton | B8: 1 | D8: 5 | E8: 0.011608796 | F8: =IF(COUNT(D$5:D$48)=0,"",IF(ISNUMBER(D8),POINTS_CAP_B-D8,0)) -> 30 | G8: =IF(COUNT(D$5:D$48)=0,"", IFERROR(CHOOSE($B8,HDCP_V_B1,HDCP_V_B2,HDCP_V_B3,HDCP_V_B4),0)) -> 0 | H8: =IF(COUNT(D$5:D$48)=0,"",MIN(F8+G8,POINTS_CAP_B)) -> 30 | J8: 2 | K8: 0.020810185 | L8: =IF(COUNT(J$5:J$48)=0,"",IF(ISNUMBER(J8),POINTS_CAP_B-J8,0)) -> 33 | M8: =IF(COUNT(J$5:J$48)=0,"", IFERROR(CHOOSE($B8,HDCP_V_B1,HDCP_V_B2,HDCP_V_B3,HDCP_V_B4),0)) -> 0 | N8: =IF(COUNT(J$5:J$48)=0,"",MIN(L8+M8,POINTS_CAP_B)) -> 33 | P8: 2 | Q8: 0.017106481 | R8: =IF(COUNT(P$5:P$48)=0,"",IF(ISNUMBER(P8),POINTS_CAP_B-P8,0)) -> 33 | S8: =IF(COUNT(P$5:P$48)=0,"", IFERROR(CHOOSE($B8,HDCP_V_B1,HDCP_V_B2,HDCP_V_B3,HDCP_V_B4),0)) -> 0 | T8: =IF(COUNT(P$5:P$48)=0,"",MIN(R8+S8,POINTS_CAP_B)) -> 33 | V8: 3 | W8: 0.033148148 | X8: =IF(COUNT(V$5:V$48)=0,"",IF(ISNUMBER(V8),POINTS_CAP_B-V8,0)) -> 32 | Y8: =IF(COUNT(V$5:V$48)=0,"", IFERROR(CHOOSE($B8,HDCP_V_B1,HDCP_V_B2,HDCP_V_B3,HDCP_V_B4),0)) -> 0 | Z8: =IF(COUNT(V$5:V$48)=0,"",MIN(X8+Y8,POINTS_CAP_B)) -> 32 | AB8: 2 | AC8: 0.034247685 | AD8: =IF(COUNT(AB$5:AB$48)=0,"",IF(ISNUMBER(AB8),POINTS_CAP_B-AB8,0)) -> 33 | AE8: =IF(COUNT(AB$5:AB$48)=0,"", IFERROR(CHOOSE($B8,HDCP_V_B1,HDCP_V_B2,HDCP_V_B3,HDCP_V_B4),0)) -> 0 | AF8: =IF(COUNT(AB$5:AB$48)=0,"",MIN(AD8+AE8,POINTS_CAP_B)) -> 33 | AH8: 3 | AI8: 0.02494213 | AJ8: =IF(COUNT(AH$5:AH$48)=0,"",IF(ISNUMBER(AH8),POINTS_CAP_B-AH8,0)) -> 32 | AK8: =IF(COUNT(AH$5:AH$48)=0,"", IFERROR(CHOOSE($B8,HDCP_V_B1,HDCP_V_B2,HDCP_V_B3,HDCP_V_B4),0)) -> 0 | AL8: =IF(COUNT(AH$5:AH$48)=0,"",MIN(AJ8+AK8,POINTS_CAP_B)) -> 32 | AN8: =SUM(F8,L8,R8,X8,AD8,AJ8) -> 193 | AO8: =SUM(H8,N8,T8,Z8,AF8,AL8) -> 193
A9: Henrik Persson | B9: 2 | D9: 2 | E9: 0.0115625 | F9: =IF(COUNT(D$5:D$48)=0,"",IF(ISNUMBER(D9),POINTS_CAP_B-D9,0)) -> 33 | G9: =IF(COUNT(D$5:D$48)=0,"", IFERROR(CHOOSE($B9,HDCP_V_B1,HDCP_V_B2,HDCP_V_B3,HDCP_V_B4),0)) -> 5 | H9: =IF(COUNT(D$5:D$48)=0,"",MIN(F9+G9,POINTS_CAP_B)) -> 35 | J9: 7 | K9: 0.021076389 | L9: =IF(COUNT(J$5:J$48)=0,"",IF(ISNUMBER(J9),POINTS_CAP_B-J9,0)) -> 28 | M9: =IF(COUNT(J$5:J$48)=0,"", IFERROR(CHOOSE($B9,HDCP_V_B1,HDCP_V_B2,HDCP_V_B3,HDCP_V_B4),0)) -> 5 | N9: =IF(COUNT(J$5:J$48)=0,"",MIN(L9+M9,POINTS_CAP_B)) -> 33 | P9: 3 | Q9: 0.017407407 | R9: =IF(COUNT(P$5:P$48)=0,"",IF(ISNUMBER(P9),POINTS_CAP_B-P9,0)) -> 32 | S9: =IF(COUNT(P$5:P$48)=0,"", IFERROR(CHOOSE($B9,HDCP_V_B1,HDCP_V_B2,HDCP_V_B3,HDCP_V_B4),0)) -> 5 | T9: =IF(COUNT(P$5:P$48)=0,"",MIN(R9+S9,POINTS_CAP_B)) -> 35 | V9: 8 | W9: 0.036180556 | X9: =IF(COUNT(V$5:V$48)=0,"",IF(ISNUMBER(V9),POINTS_CAP_B-V9,0)) -> 27 | Y9: =IF(COUNT(V$5:V$48)=0,"", IFERROR(CHOOSE($B9,HDCP_V_B1,HDCP_V_B2,HDCP_V_B3,HDCP_V_B4),0)) -> 5 | Z9: =IF(COUNT(V$5:V$48)=0,"",MIN(X9+Y9,POINTS_CAP_B)) -> 32 | AB9: 8 | AC9: 0.036469907 | AD9: =IF(COUNT(AB$5:AB$48)=0,"",IF(ISNUMBER(AB9),POINTS_CAP_B-AB9,0)) -> 27 | AE9: =IF(COUNT(AB$5:AB$48)=0,"", IFERROR(CHOOSE($B9,HDCP_V_B1,HDCP_V_B2,HDCP_V_B3,HDCP_V_B4),0)) -> 5 | AF9: =IF(COUNT(AB$5:AB$48)=0,"",MIN(AD9+AE9,POINTS_CAP_B)) -> 32 | AH9: 9 | AI9: 0.025613426 | AJ9: =IF(COUNT(AH$5:AH$48)=0,"",IF(ISNUMBER(AH9),POINTS_CAP_B-AH9,0)) -> 26 | AK9: =IF(COUNT(AH$5:AH$48)=0,"", IFERROR(CHOOSE($B9,HDCP_V_B1,HDCP_V_B2,HDCP_V_B3,HDCP_V_B4),0)) -> 5 | AL9: =IF(COUNT(AH$5:AH$48)=0,"",MIN(AJ9+AK9,POINTS_CAP_B)) -> 31 | AN9: =SUM(F9,L9,R9,X9,AD9,AJ9) -> 173 | AO9: =SUM(H9,N9,T9,Z9,AF9,AL9) -> 198
A10: Alice Lethbridge | B10: 2 | D10: 1 | E10: 0.011539352 | F10: =IF(COUNT(D$5:D$48)=0,"",IF(ISNUMBER(D10),POINTS_CAP_B-D10,0)) -> 34 | G10: =IF(COUNT(D$5:D$48)=0,"", IFERROR(CHOOSE($B10,HDCP_V_B1,HDCP_V_B2,HDCP_V_B3,HDCP_V_B4),0)) -> 5 | H10: =IF(COUNT(D$5:D$48)=0,"",MIN(F10+G10,POINTS_CAP_B)) -> 35 | J10: 5 | K10: 0.021053241 | L10: =IF(COUNT(J$5:J$48)=0,"",IF(ISNUMBER(J10),POINTS_CAP_B-J10,0)) -> 30 | M10: =IF(COUNT(J$5:J$48)=0,"", IFERROR(CHOOSE($B10,HDCP_V_B1,HDCP_V_B2,HDCP_V_B3,HDCP_V_B4),0)) -> 5 | N10: =IF(COUNT(J$5:J$48)=0,"",MIN(L10+M10,POINTS_CAP_B)) -> 35 | P10: 4 | Q10: 0.017418981 | R10: =IF(COUNT(P$5:P$48)=0,"",IF(ISNUMBER(P10),POINTS_CAP_B-P10,0)) -> 31 | S10: =IF(COUNT(P$5:P$48)=0,"", IFERROR(CHOOSE($B10,HDCP_V_B1,HDCP_V_B2,HDCP_V_B3,HDCP_V_B4),0)) -> 5 | T10: =IF(COUNT(P$5:P$48)=0,"",MIN(R10+S10,POINTS_CAP_B)) -> 35 | V10: 6 | W10: 0.035821759 | X10: =IF(COUNT(V$5:V$48)=0,"",IF(ISNUMBER(V10),POINTS_CAP_B-V10,0)) -> 29 | Y10: =IF(COUNT(V$5:V$48)=0,"", IFERROR(CHOOSE($B10,HDCP_V_B1,HDCP_V_B2,HDCP_V_B3,HDCP_V_B4),0)) -> 5 | Z10: =IF(COUNT(V$5:V$48)=0,"",MIN(X10+Y10,POINTS_CAP_B)) -> 34 | AB10: 7 | AC10: 0.036365741 | AD10: =IF(COUNT(AB$5:AB$48)=0,"",IF(ISNUMBER(AB10),POINTS_CAP_B-AB10,0)) -> 28 | AE10: =IF(COUNT(AB$5:AB$48)=0,"", IFERROR(CHOOSE($B10,HDCP_V_B1,HDCP_V_B2,HDCP_V_B3,HDCP_V_B4),0)) -> 5 | AF10: =IF(COUNT(AB$5:AB$48)=0,"",MIN(AD10+AE10,POINTS_CAP_B)) -> 33 | AH10: 16 | AI10: 0.026469907 | AJ10: =IF(COUNT(AH$5:AH$48)=0,"",IF(ISNUMBER(AH10),POINTS_CAP_B-AH10,0)) -> 19 | AK10: =IF(COUNT(AH$5:AH$48)=0,"", IFERROR(CHOOSE($B10,HDCP_V_B1,HDCP_V_B2,HDCP_V_B3,HDCP_V_B4),0)) -> 5 | AL10: =IF(COUNT(AH$5:AH$48)=0,"",MIN(AJ10+AK10,POINTS_CAP_B)) -> 24 | AN10: =SUM(F10,L10,R10,X10,AD10,AJ10) -> 171 | AO10: =SUM(H10,N10,T10,Z10,AF10,AL10) -> 196
A11: Tom Kennett | B11: 1 | D11: 2 | E11: 0.0115625 | F11: =IF(COUNT(D$5:D$48)=0,"",IF(ISNUMBER(D11),POINTS_CAP_B-D11,0)) -> 33 | G11: =IF(COUNT(D$5:D$48)=0,"", IFERROR(CHOOSE($B11,HDCP_V_B1,HDCP_V_B2,HDCP_V_B3,HDCP_V_B4),0)) -> 0 | H11: =IF(COUNT(D$5:D$48)=0,"",MIN(F11+G11,POINTS_CAP_B)) -> 33 | J11: 9 | K11: 0.021226852 | L11: =IF(COUNT(J$5:J$48)=0,"",IF(ISNUMBER(J11),POINTS_CAP_B-J11,0)) -> 26 | M11: =IF(COUNT(J$5:J$48)=0,"", IFERROR(CHOOSE($B11,HDCP_V_B1,HDCP_V_B2,HDCP_V_B3,HDCP_V_B4),0)) -> 0 | N11: =IF(COUNT(J$5:J$48)=0,"",MIN(L11+M11,POINTS_CAP_B)) -> 26 | P11: 7 | Q11: 0.017430556 | R11: =IF(COUNT(P$5:P$48)=0,"",IF(ISNUMBER(P11),POINTS_CAP_B-P11,0)) -> 28 | S11: =IF(COUNT(P$5:P$48)=0,"", IFERROR(CHOOSE($B11,HDCP_V_B1,HDCP_V_B2,HDCP_V_B3,HDCP_V_B4),0)) -> 0 | T11: =IF(COUNT(P$5:P$48)=0,"",MIN(R11+S11,POINTS_CAP_B)) -> 28 | V11: 4 | W11: 0.034270833 | X11: =IF(COUNT(V$5:V$48)=0,"",IF(ISNUMBER(V11),POINTS_CAP_B-V11,0)) -> 31 | Y11: =IF(COUNT(V$5:V$48)=0,"", IFERROR(CHOOSE($B11,HDCP_V_B1,HDCP_V_B2,HDCP_V_B3,HDCP_V_B4),0)) -> 0 | Z11: =IF(COUNT(V$5:V$48)=0,"",MIN(X11+Y11,POINTS_CAP_B)) -> 31 | AB11: 3 | AC11: 0.034409722 | AD11: =IF(COUNT(AB$5:AB$48)=0,"",IF(ISNUMBER(AB11),POINTS_CAP_B-AB11,0)) -> 32 | AE11: =IF(COUNT(AB$5:AB$48)=0,"", IFERROR(CHOOSE($B11,HDCP_V_B1,HDCP_V_B2,HDCP_V_B3,HDCP_V_B4),0)) -> 0 | AF11: =IF(COUNT(AB$5:AB$48)=0,"",MIN(AD11+AE11,POINTS_CAP_B)) -> 32 | AH11: 1 | AI11: 0.0246875 | AJ11: =IF(COUNT(AH$5:AH$48)=0,"",IF(ISNUMBER(AH11),POINTS_CAP_B-AH11,0)) -> 34 | AK11: =IF(COUNT(AH$5:AH$48)=0,"", IFERROR(CHOOSE($B11,HDCP_V_B1,HDCP_V_B2,HDCP_V_B3,HDCP_V_B4),0)) -> 0 | AL11: =IF(COUNT(AH$5:AH$48)=0,"",MIN(AJ11+AK11,POINTS_CAP_B)) -> 34 | AN11: =SUM(F11,L11,R11,X11,AD11,AJ11) -> 184 | AO11: =SUM(H11,N11,T11,Z11,AF11,AL11) -> 184
A12: Bill McClatchie | B12: 3 | D12: 10 | E12: 0.011759259 | F12: =IF(COUNT(D$5:D$48)=0,"",IF(ISNUMBER(D12),POINTS_CAP_B-D12,0)) -> 25 | G12: =IF(COUNT(D$5:D$48)=0,"", IFERROR(CHOOSE($B12,HDCP_V_B1,HDCP_V_B2,HDCP_V_B3,HDCP_V_B4),0)) -> 10 | H12: =IF(COUNT(D$5:D$48)=0,"",MIN(F12+G12,POINTS_CAP_B)) -> 35 | J12: 10 | K12: 0.021342593 | L12: =IF(COUNT(J$5:J$48)=0,"",IF(ISNUMBER(J12),POINTS_CAP_B-J12,0)) -> 25 | M12: =IF(COUNT(J$5:J$48)=0,"", IFERROR(CHOOSE($B12,HDCP_V_B1,HDCP_V_B2,HDCP_V_B3,HDCP_V_B4),0)) -> 10 | N12: =IF(COUNT(J$5:J$48)=0,"",MIN(L12+M12,POINTS_CAP_B)) -> 35 | P12: 9 | Q12: 0.017604167 | R12: =IF(COUNT(P$5:P$48)=0,"",IF(ISNUMBER(P12),POINTS_CAP_B-P12,0)) -> 26 | S12: =IF(COUNT(P$5:P$48)=0,"", IFERROR(CHOOSE($B12,HDCP_V_B1,HDCP_V_B2,HDCP_V_B3,HDCP_V_B4),0)) -> 10 | T12: =IF(COUNT(P$5:P$48)=0,"",MIN(R12+S12,POINTS_CAP_B)) -> 35 | V12: 16 | W12: 0.038032407 | X12: =IF(COUNT(V$5:V$48)=0,"",IF(ISNUMBER(V12),POINTS_CAP_B-V12,0)) -> 19 | Y12: =IF(COUNT(V$5:V$48)=0,"", IFERROR(CHOOSE($B12,HDCP_V_B1,HDCP_V_B2,HDCP_V_B3,HDCP_V_B4),0)) -> 10 | Z12: =IF(COUNT(V$5:V$48)=0,"",MIN(X12+Y12,POINTS_CAP_B)) -> 29 | AB12: 14 | AC12: 0.037847222 | AD12: =IF(COUNT(AB$5:AB$48)=0,"",IF(ISNUMBER(AB12),POINTS_CAP_B-AB12,0)) -> 21 | AE12: =IF(COUNT(AB$5:AB$48)=0,"", IFERROR(CHOOSE($B12,HDCP_V_B1,HDCP_V_B2,HDCP_V_B3,HDCP_V_B4),0)) -> 10 | AF12: =IF(COUNT(AB$5:AB$48)=0,"",MIN(AD12+AE12,POINTS_CAP_B)) -> 31 | AH12: 7 | AI12: 0.02556713 | AJ12: =IF(COUNT(AH$5:AH$48)=0,"",IF(ISNUMBER(AH12),POINTS_CAP_B-AH12,0)) -> 28 | AK12: =IF(COUNT(AH$5:AH$48)=0,"", IFERROR(CHOOSE($B12,HDCP_V_B1,HDCP_V_B2,HDCP_V_B3,HDCP_V_B4),0)) -> 10 | AL12: =IF(COUNT(AH$5:AH$48)=0,"",MIN(AJ12+AK12,POINTS_CAP_B)) -> 35 | AN12: =SUM(F12,L12,R12,X12,AD12,AJ12) -> 144 | AO12: =SUM(H12,N12,T12,Z12,AF12,AL12) -> 200
A13: Neal Beauchamp | B13: 2 | D13: 7 | E13: 0.01162037 | F13: =IF(COUNT(D$5:D$48)=0,"",IF(ISNUMBER(D13),POINTS_CAP_B-D13,0)) -> 28 | G13: =IF(COUNT(D$5:D$48)=0,"", IFERROR(CHOOSE($B13,HDCP_V_B1,HDCP_V_B2,HDCP_V_B3,HDCP_V_B4),0)) -> 5 | H13: =IF(COUNT(D$5:D$48)=0,"",MIN(F13+G13,POINTS_CAP_B)) -> 33 | J13: 4 | K13: 0.021018519 | L13: =IF(COUNT(J$5:J$48)=0,"",IF(ISNUMBER(J13),POINTS_CAP_B-J13,0)) -> 31 | M13: =IF(COUNT(J$5:J$48)=0,"", IFERROR(CHOOSE($B13,HDCP_V_B1,HDCP_V_B2,HDCP_V_B3,HDCP_V_B4),0)) -> 5 | N13: =IF(COUNT(J$5:J$48)=0,"",MIN(L13+M13,POINTS_CAP_B)) -> 35 | P13: 8 | Q13: 0.01744213 | R13: =IF(COUNT(P$5:P$48)=0,"",IF(ISNUMBER(P13),POINTS_CAP_B-P13,0)) -> 27 | S13: =IF(COUNT(P$5:P$48)=0,"", IFERROR(CHOOSE($B13,HDCP_V_B1,HDCP_V_B2,HDCP_V_B3,HDCP_V_B4),0)) -> 5 | T13: =IF(COUNT(P$5:P$48)=0,"",MIN(R13+S13,POINTS_CAP_B)) -> 32 | V13: 12 | W13: 0.037291667 | X13: =IF(COUNT(V$5:V$48)=0,"",IF(ISNUMBER(V13),POINTS_CAP_B-V13,0)) -> 23 | Y13: =IF(COUNT(V$5:V$48)=0,"", IFERROR(CHOOSE($B13,HDCP_V_B1,HDCP_V_B2,HDCP_V_B3,HDCP_V_B4),0)) -> 5 | Z13: =IF(COUNT(V$5:V$48)=0,"",MIN(X13+Y13,POINTS_CAP_B)) -> 28 | AB13: 9 | AC13: 0.036527778 | AD13: =IF(COUNT(AB$5:AB$48)=0,"",IF(ISNUMBER(AB13),POINTS_CAP_B-AB13,0)) -> 26 | AE13: =IF(COUNT(AB$5:AB$48)=0,"", IFERROR(CHOOSE($B13,HDCP_V_B1,HDCP_V_B2,HDCP_V_B3,HDCP_V_B4),0)) -> 5 | AF13: =IF(COUNT(AB$5:AB$48)=0,"",MIN(AD13+AE13,POINTS_CAP_B)) -> 31 | AH13: 8 | AI13: 0.025601852 | AJ13: =IF(COUNT(AH$5:AH$48)=0,"",IF(ISNUMBER(AH13),POINTS_CAP_B-AH13,0)) -> 27 | AK13: =IF(COUNT(AH$5:AH$48)=0,"", IFERROR(CHOOSE($B13,HDCP_V_B1,HDCP_V_B2,HDCP_V_B3,HDCP_V_B4),0)) -> 5 | AL13: =IF(COUNT(AH$5:AH$48)=0,"",MIN(AJ13+AK13,POINTS_CAP_B)) -> 32 | AN13: =SUM(F13,L13,R13,X13,AD13,AJ13) -> 162 | AO13: =SUM(H13,N13,T13,Z13,AF13,AL13) -> 191
A14: Eamon Mason | B14: 4 | D14: 19 | E14: 0.012083333 | F14: =IF(COUNT(D$5:D$48)=0,"",IF(ISNUMBER(D14),POINTS_CAP_B-D14,0)) -> 16 | G14: =IF(COUNT(D$5:D$48)=0,"", IFERROR(CHOOSE($B14,HDCP_V_B1,HDCP_V_B2,HDCP_V_B3,HDCP_V_B4),0)) -> 15 | H14: =IF(COUNT(D$5:D$48)=0,"",MIN(F14+G14,POINTS_CAP_B)) -> 31 | J14: 12 | K14: 0.021516204 | L14: =IF(COUNT(J$5:J$48)=0,"",IF(ISNUMBER(J14),POINTS_CAP_B-J14,0)) -> 23 | M14: =IF(COUNT(J$5:J$48)=0,"", IFERROR(CHOOSE($B14,HDCP_V_B1,HDCP_V_B2,HDCP_V_B3,HDCP_V_B4),0)) -> 15 | N14: =IF(COUNT(J$5:J$48)=0,"",MIN(L14+M14,POINTS_CAP_B)) -> 35 | P14: 15 | Q14: 0.01818287 | R14: =IF(COUNT(P$5:P$48)=0,"",IF(ISNUMBER(P14),POINTS_CAP_B-P14,0)) -> 20 | S14: =IF(COUNT(P$5:P$48)=0,"", IFERROR(CHOOSE($B14,HDCP_V_B1,HDCP_V_B2,HDCP_V_B3,HDCP_V_B4),0)) -> 15 | T14: =IF(COUNT(P$5:P$48)=0,"",MIN(R14+S14,POINTS_CAP_B)) -> 35 | V14: 18 | W14: 0.040150463 | X14: =IF(COUNT(V$5:V$48)=0,"",IF(ISNUMBER(V14),POINTS_CAP_B-V14,0)) -> 17 | Y14: =IF(COUNT(V$5:V$48)=0,"", IFERROR(CHOOSE($B14,HDCP_V_B1,HDCP_V_B2,HDCP_V_B3,HDCP_V_B4),0)) -> 15 | Z14: =IF(COUNT(V$5:V$48)=0,"",MIN(X14+Y14,POINTS_CAP_B)) -> 32 | AB14: 15 | AC14: 0.037858796 | AD14: =IF(COUNT(AB$5:AB$48)=0,"",IF(ISNUMBER(AB14),POINTS_CAP_B-AB14,0)) -> 20 | AE14: =IF(COUNT(AB$5:AB$48)=0,"", IFERROR(CHOOSE($B14,HDCP_V_B1,HDCP_V_B2,HDCP_V_B3,HDCP_V_B4),0)) -> 15 | AF14: =IF(COUNT(AB$5:AB$48)=0,"",MIN(AD14+AE14,POINTS_CAP_B)) -> 35 | AH14: 15 | AI14: 0.026388889 | AJ14: =IF(COUNT(AH$5:AH$48)=0,"",IF(ISNUMBER(AH14),POINTS_CAP_B-AH14,0)) -> 20 | AK14: =IF(COUNT(AH$5:AH$48)=0,"", IFERROR(CHOOSE($B14,HDCP_V_B1,HDCP_V_B2,HDCP_V_B3,HDCP_V_B4),0)) -> 15 | AL14: =IF(COUNT(AH$5:AH$48)=0,"",MIN(AJ14+AK14,POINTS_CAP_B)) -> 35 | AN14: =SUM(F14,L14,R14,X14,AD14,AJ14) -> 116 | AO14: =SUM(H14,N14,T14,Z14,AF14,AL14) -> 203
A15: Denis Whelan | B15: 3 | D15: 15 | E15: 0.011967593 | F15: =IF(COUNT(D$5:D$48)=0,"",IF(ISNUMBER(D15),POINTS_CAP_B-D15,0)) -> 20 | G15: =IF(COUNT(D$5:D$48)=0,"", IFERROR(CHOOSE($B15,HDCP_V_B1,HDCP_V_B2,HDCP_V_B3,HDCP_V_B4),0)) -> 10 | H15: =IF(COUNT(D$5:D$48)=0,"",MIN(F15+G15,POINTS_CAP_B)) -> 30 | J15: 14 | K15: 0.021712963 | L15: =IF(COUNT(J$5:J$48)=0,"",IF(ISNUMBER(J15),POINTS_CAP_B-J15,0)) -> 21 | M15: =IF(COUNT(J$5:J$48)=0,"", IFERROR(CHOOSE($B15,HDCP_V_B1,HDCP_V_B2,HDCP_V_B3,HDCP_V_B4),0)) -> 10 | N15: =IF(COUNT(J$5:J$48)=0,"",MIN(L15+M15,POINTS_CAP_B)) -> 31 | P15: 13 | Q15: 0.018125 | R15: =IF(COUNT(P$5:P$48)=0,"",IF(ISNUMBER(P15),POINTS_CAP_B-P15,0)) -> 22 | S15: =IF(COUNT(P$5:P$48)=0,"", IFERROR(CHOOSE($B15,HDCP_V_B1,HDCP_V_B2,HDCP_V_B3,HDCP_V_B4),0)) -> 10 | T15: =IF(COUNT(P$5:P$48)=0,"",MIN(R15+S15,POINTS_CAP_B)) -> 32 | V15: 14 | W15: 0.037766204 | X15: =IF(COUNT(V$5:V$48)=0,"",IF(ISNUMBER(V15),POINTS_CAP_B-V15,0)) -> 21 | Y15: =IF(COUNT(V$5:V$48)=0,"", IFERROR(CHOOSE($B15,HDCP_V_B1,HDCP_V_B2,HDCP_V_B3,HDCP_V_B4),0)) -> 10 | Z15: =IF(COUNT(V$5:V$48)=0,"",MIN(X15+Y15,POINTS_CAP_B)) -> 31 | AB15: 11 | AC15: 0.037256944 | AD15: =IF(COUNT(AB$5:AB$48)=0,"",IF(ISNUMBER(AB15),POINTS_CAP_B-AB15,0)) -> 24 | AE15: =IF(COUNT(AB$5:AB$48)=0,"", IFERROR(CHOOSE($B15,HDCP_V_B1,HDCP_V_B2,HDCP_V_B3,HDCP_V_B4),0)) -> 10 | AF15: =IF(COUNT(AB$5:AB$48)=0,"",MIN(AD15+AE15,POINTS_CAP_B)) -> 34 | AH15: 13 | AI15: 0.026030093 | AJ15: =IF(COUNT(AH$5:AH$48)=0,"",IF(ISNUMBER(AH15),POINTS_CAP_B-AH15,0)) -> 22 | AK15: =IF(COUNT(AH$5:AH$48)=0,"", IFERROR(CHOOSE($B15,HDCP_V_B1,HDCP_V_B2,HDCP_V_B3,HDCP_V_B4),0)) -> 10 | AL15: =IF(COUNT(AH$5:AH$48)=0,"",MIN(AJ15+AK15,POINTS_CAP_B)) -> 32 | AN15: =SUM(F15,L15,R15,X15,AD15,AJ15) -> 130 | AO15: =SUM(H15,N15,T15,Z15,AF15,AL15) -> 190
A16: Tom Herbert | B16: 2 | D16: 13 | E16: 0.011840278 | F16: =IF(COUNT(D$5:D$48)=0,"",IF(ISNUMBER(D16),POINTS_CAP_B-D16,0)) -> 22 | G16: =IF(COUNT(D$5:D$48)=0,"", IFERROR(CHOOSE($B16,HDCP_V_B1,HDCP_V_B2,HDCP_V_B3,HDCP_V_B4),0)) -> 5 | H16: =IF(COUNT(D$5:D$48)=0,"",MIN(F16+G16,POINTS_CAP_B)) -> 27 | J16: 8 | K16: 0.021122685 | L16: =IF(COUNT(J$5:J$48)=0,"",IF(ISNUMBER(J16),POINTS_CAP_B-J16,0)) -> 27 | M16: =IF(COUNT(J$5:J$48)=0,"", IFERROR(CHOOSE($B16,HDCP_V_B1,HDCP_V_B2,HDCP_V_B3,HDCP_V_B4),0)) -> 5 | N16: =IF(COUNT(J$5:J$48)=0,"",MIN(L16+M16,POINTS_CAP_B)) -> 32 | P16: 10 | Q16: 0.017627315 | R16: =IF(COUNT(P$5:P$48)=0,"",IF(ISNUMBER(P16),POINTS_CAP_B-P16,0)) -> 25 | S16: =IF(COUNT(P$5:P$48)=0,"", IFERROR(CHOOSE($B16,HDCP_V_B1,HDCP_V_B2,HDCP_V_B3,HDCP_V_B4),0)) -> 5 | T16: =IF(COUNT(P$5:P$48)=0,"",MIN(R16+S16,POINTS_CAP_B)) -> 30 | V16: 11 | W16: 0.037175926 | X16: =IF(COUNT(V$5:V$48)=0,"",IF(ISNUMBER(V16),POINTS_CAP_B-V16,0)) -> 24 | Y16: =IF(COUNT(V$5:V$48)=0,"", IFERROR(CHOOSE($B16,HDCP_V_B1,HDCP_V_B2,HDCP_V_B3,HDCP_V_B4),0)) -> 5 | Z16: =IF(COUNT(V$5:V$48)=0,"",MIN(X16+Y16,POINTS_CAP_B)) -> 29 | AB16: 13 | AC16: 0.037615741 | AD16: =IF(COUNT(AB$5:AB$48)=0,"",IF(ISNUMBER(AB16),POINTS_CAP_B-AB16,0)) -> 22 | AE16: =IF(COUNT(AB$5:AB$48)=0,"", IFERROR(CHOOSE($B16,HDCP_V_B1,HDCP_V_B2,HDCP_V_B3,HDCP_V_B4),0)) -> 5 | AF16: =IF(COUNT(AB$5:AB$48)=0,"",MIN(AD16+AE16,POINTS_CAP_B)) -> 27 | AH16: 10 | AI16: 0.025902778 | AJ16: =IF(COUNT(AH$5:AH$48)=0,"",IF(ISNUMBER(AH16),POINTS_CAP_B-AH16,0)) -> 25 | AK16: =IF(COUNT(AH$5:AH$48)=0,"", IFERROR(CHOOSE($B16,HDCP_V_B1,HDCP_V_B2,HDCP_V_B3,HDCP_V_B4),0)) -> 5 | AL16: =IF(COUNT(AH$5:AH$48)=0,"",MIN(AJ16+AK16,POINTS_CAP_B)) -> 30 | AN16: =SUM(F16,L16,R16,X16,AD16,AJ16) -> 145 | AO16: =SUM(H16,N16,T16,Z16,AF16,AL16) -> 175
... A21: Conor Walsh | B21: 1 | D21: 14 | E21: 0.011944444 | F21: =IF(COUNT(D$5:D$48)=0,"",IF(ISNUMBER(D21),POINTS_CAP_B-D21,0)) -> 21 | G21: =IF(COUNT(D$5:D$48)=0,"", IFERROR(CHOOSE($B21,HDCP_V_B1,HDCP_V_B2,HDCP_V_B3,HDCP_V_B4),0)) -> 0 | H21: =IF(COUNT(D$5:D$48)=0,"",MIN(F21+G21,POINTS_CAP_B)) -> 21 | J21: 17 | K21: 0.02212963 | L21: =IF(COUNT(J$5:J$48)=0,"",IF(ISNUMBER(J21),POINTS_CAP_B-J21,0)) -> 18 | M21: =IF(COUNT(J$5:J$48)=0,"", IFERROR(CHOOSE($B21,HDCP_V_B1,HDCP_V_B2,HDCP_V_B3,HDCP_V_B4),0)) -> 0 | N21: =IF(COUNT(J$5:J$48)=0,"",MIN(L21+M21,POINTS_CAP_B)) -> 18 | P21: 16 | Q21: 0.018287037 | R21: =IF(COUNT(P$5:P$48)=0,"",IF(ISNUMBER(P21),POINTS_CAP_B-P21,0)) -> 19 | S21: =IF(COUNT(P$5:P$48)=0,"", IFERROR(CHOOSE($B21,HDCP_V_B1,HDCP_V_B2,HDCP_V_B3,HDCP_V_B4),0)) -> 0 | T21: =IF(COUNT(P$5:P$48)=0,"",MIN(R21+S21,POINTS_CAP_B)) -> 19 | V21: 2 | W21: 0.032662037 | X21: =IF(COUNT(V$5:V$48)=0,"",IF(ISNUMBER(V21),POINTS_CAP_B-V21,0)) -> 33 | Y21: =IF(COUNT(V$5:V$48)=0,"", IFERROR(CHOOSE($B21,HDCP_V_B1,HDCP_V_B2,HDCP_V_B3,HDCP_V_B4),0)) -> 0 | Z21: =IF(COUNT(V$5:V$48)=0,"",MIN(X21+Y21,POINTS_CAP_B)) -> 33 | AB21: 10 | AC21: 0.0365625 | AD21: =IF(COUNT(AB$5:AB$48)=0,"",IF(ISNUMBER(AB21),POINTS_CAP_B-AB21,0)) -> 25 | AE21: =IF(COUNT(AB$5:AB$48)=0,"", IFERROR(CHOOSE($B21,HDCP_V_B1,HDCP_V_B2,HDCP_V_B3,HDCP_V_B4),0)) -> 0 | AF21: =IF(COUNT(AB$5:AB$48)=0,"",MIN(AD21+AE21,POINTS_CAP_B)) -> 25 | AH21: 5 | AI21: 0.025555556 | AJ21: =IF(COUNT(AH$5:AH$48)=0,"",IF(ISNUMBER(AH21),POINTS_CAP_B-AH21,0)) -> 30 | AK21: =IF(COUNT(AH$5:AH$48)=0,"", IFERROR(CHOOSE($B21,HDCP_V_B1,HDCP_V_B2,HDCP_V_B3,HDCP_V_B4),0)) -> 0 | AL21: =IF(COUNT(AH$5:AH$48)=0,"",MIN(AJ21+AK21,POINTS_CAP_B)) -> 30 | AN21: =SUM(F21,L21,R21,X21,AD21,AJ21) -> 146 | AO21: =SUM(H21,N21,T21,Z21,AF21,AL21) -> 146
A22: Richard Turner | B22: 4 | D22: 18 | E22: 0.012025463 | F22: =IF(COUNT(D$5:D$48)=0,"",IF(ISNUMBER(D22),POINTS_CAP_B-D22,0)) -> 17 | G22: =IF(COUNT(D$5:D$48)=0,"", IFERROR(CHOOSE($B22,HDCP_V_B1,HDCP_V_B2,HDCP_V_B3,HDCP_V_B4),0)) -> 15 | H22: =IF(COUNT(D$5:D$48)=0,"",MIN(F22+G22,POINTS_CAP_B)) -> 32 | J22: 15 | K22: 0.021770833 | L22: =IF(COUNT(J$5:J$48)=0,"",IF(ISNUMBER(J22),POINTS_CAP_B-J22,0)) -> 20 | M22: =IF(COUNT(J$5:J$48)=0,"", IFERROR(CHOOSE($B22,HDCP_V_B1,HDCP_V_B2,HDCP_V_B3,HDCP_V_B4),0)) -> 15 | N22: =IF(COUNT(J$5:J$48)=0,"",MIN(L22+M22,POINTS_CAP_B)) -> 35 | P22: 26 | Q22: 0.019398148 | R22: =IF(COUNT(P$5:P$48)=0,"",IF(ISNUMBER(P22),POINTS_CAP_B-P22,0)) -> 9 | S22: =IF(COUNT(P$5:P$48)=0,"", IFERROR(CHOOSE($B22,HDCP_V_B1,HDCP_V_B2,HDCP_V_B3,HDCP_V_B4),0)) -> 15 | T22: =IF(COUNT(P$5:P$48)=0,"",MIN(R22+S22,POINTS_CAP_B)) -> 24 | X22: =IF(COUNT(V$5:V$48)=0,"",IF(ISNUMBER(V22),POINTS_CAP_B-V22,0)) -> 0 | Y22: =IF(COUNT(V$5:V$48)=0,"", IFERROR(CHOOSE($B22,HDCP_V_B1,HDCP_V_B2,HDCP_V_B3,HDCP_V_B4),0)) -> 15 | Z22: =IF(COUNT(V$5:V$48)=0,"",MIN(X22+Y22,POINTS_CAP_B)) -> 15 | AD22: =IF(COUNT(AB$5:AB$48)=0,"",IF(ISNUMBER(AB22),POINTS_CAP_B-AB22,0)) -> 0 | AE22: =IF(COUNT(AB$5:AB$48)=0,"", IFERROR(CHOOSE($B22,HDCP_V_B1,HDCP_V_B2,HDCP_V_B3,HDCP_V_B4),0)) -> 15 | AF22: =IF(COUNT(AB$5:AB$48)=0,"",MIN(AD22+AE22,POINTS_CAP_B)) -> 15 | AJ22: =IF(COUNT(AH$5:AH$48)=0,"",IF(ISNUMBER(AH22),POINTS_CAP_B-AH22,0)) -> 0 | AK22: =IF(COUNT(AH$5:AH$48)=0,"", IFERROR(CHOOSE($B22,HDCP_V_B1,HDCP_V_B2,HDCP_V_B3,HDCP_V_B4),0)) -> 15 | AL22: =IF(COUNT(AH$5:AH$48)=0,"",MIN(AJ22+AK22,POINTS_CAP_B)) -> 15 | AN22: =SUM(F22,L22,R22,X22,AD22,AJ22) -> 46 | AO22: =SUM(H22,N22,T22,Z22,AF22,AL22) -> 136
A23: David Willis | B23: 3 | D23: 15 | E23: 0.011967593 | F23: =IF(COUNT(D$5:D$48)=0,"",IF(ISNUMBER(D23),POINTS_CAP_B-D23,0)) -> 20 | G23: =IF(COUNT(D$5:D$48)=0,"", IFERROR(CHOOSE($B23,HDCP_V_B1,HDCP_V_B2,HDCP_V_B3,HDCP_V_B4),0)) -> 10 | H23: =IF(COUNT(D$5:D$48)=0,"",MIN(F23+G23,POINTS_CAP_B)) -> 30 | J23: 20 | K23: 0.022465278 | L23: =IF(COUNT(J$5:J$48)=0,"",IF(ISNUMBER(J23),POINTS_CAP_B-J23,0)) -> 15 | M23: =IF(COUNT(J$5:J$48)=0,"", IFERROR(CHOOSE($B23,HDCP_V_B1,HDCP_V_B2,HDCP_V_B3,HDCP_V_B4),0)) -> 10 | N23: =IF(COUNT(J$5:J$48)=0,"",MIN(L23+M23,POINTS_CAP_B)) -> 25 | P23: 22 | Q23: 0.018796296 | R23: =IF(COUNT(P$5:P$48)=0,"",IF(ISNUMBER(P23),POINTS_CAP_B-P23,0)) -> 13 | S23: =IF(COUNT(P$5:P$48)=0,"", IFERROR(CHOOSE($B23,HDCP_V_B1,HDCP_V_B2,HDCP_V_B3,HDCP_V_B4),0)) -> 10 | T23: =IF(COUNT(P$5:P$48)=0,"",MIN(R23+S23,POINTS_CAP_B)) -> 23 | V23: 13 | W23: 0.037372685 | X23: =IF(COUNT(V$5:V$48)=0,"",IF(ISNUMBER(V23),POINTS_CAP_B-V23,0)) -> 22 | Y23: =IF(COUNT(V$5:V$48)=0,"", IFERROR(CHOOSE($B23,HDCP_V_B1,HDCP_V_B2,HDCP_V_B3,HDCP_V_B4),0)) -> 10 | Z23: =IF(COUNT(V$5:V$48)=0,"",MIN(X23+Y23,POINTS_CAP_B)) -> 32 | AB23: 18 | AC23: 0.038842593 | AD23: =IF(COUNT(AB$5:AB$48)=0,"",IF(ISNUMBER(AB23),POINTS_CAP_B-AB23,0)) -> 17 | AE23: =IF(COUNT(AB$5:AB$48)=0,"", IFERROR(CHOOSE($B23,HDCP_V_B1,HDCP_V_B2,HDCP_V_B3,HDCP_V_B4),0)) -> 10 | AF23: =IF(COUNT(AB$5:AB$48)=0,"",MIN(AD23+AE23,POINTS_CAP_B)) -> 27 | AJ23: =IF(COUNT(AH$5:AH$48)=0,"",IF(ISNUMBER(AH23),POINTS_CAP_B-AH23,0)) -> 0 | AK23: =IF(COUNT(AH$5:AH$48)=0,"", IFERROR(CHOOSE($B23,HDCP_V_B1,HDCP_V_B2,HDCP_V_B3,HDCP_V_B4),0)) -> 10 | AL23: =IF(COUNT(AH$5:AH$48)=0,"",MIN(AJ23+AK23,POINTS_CAP_B)) -> 10 | AN23: =SUM(F23,L23,R23,X23,AD23,AJ23) -> 87 | AO23: =SUM(H23,N23,T23,Z23,AF23,AL23) -> 147
A24: Ellen Lockett | B24: 4 | F24: =IF(COUNT(D$5:D$48)=0,"",IF(ISNUMBER(D24),POINTS_CAP_B-D24,0)) -> 0 | G24: =IF(COUNT(D$5:D$48)=0,"", IFERROR(CHOOSE($B24,HDCP_V_B1,HDCP_V_B2,HDCP_V_B3,HDCP_V_B4),0)) -> 15 | H24: =IF(COUNT(D$5:D$48)=0,"",MIN(F24+G24,POINTS_CAP_B)) -> 15 | J24: 23 | K24: 0.022951389 | L24: =IF(COUNT(J$5:J$48)=0,"",IF(ISNUMBER(J24),POINTS_CAP_B-J24,0)) -> 12 | M24: =IF(COUNT(J$5:J$48)=0,"", IFERROR(CHOOSE($B24,HDCP_V_B1,HDCP_V_B2,HDCP_V_B3,HDCP_V_B4),0)) -> 15 | N24: =IF(COUNT(J$5:J$48)=0,"",MIN(L24+M24,POINTS_CAP_B)) -> 27 | P24: 21 | Q24: 0.018680556 | R24: =IF(COUNT(P$5:P$48)=0,"",IF(ISNUMBER(P24),POINTS_CAP_B-P24,0)) -> 14 | S24: =IF(COUNT(P$5:P$48)=0,"", IFERROR(CHOOSE($B24,HDCP_V_B1,HDCP_V_B2,HDCP_V_B3,HDCP_V_B4),0)) -> 15 | T24: =IF(COUNT(P$5:P$48)=0,"",MIN(R24+S24,POINTS_CAP_B)) -> 29 | V24: 21 | W24: 0.041979167 | X24: =IF(COUNT(V$5:V$48)=0,"",IF(ISNUMBER(V24),POINTS_CAP_B-V24,0)) -> 14 | Y24: =IF(COUNT(V$5:V$48)=0,"", IFERROR(CHOOSE($B24,HDCP_V_B1,HDCP_V_B2,HDCP_V_B3,HDCP_V_B4),0)) -> 15 | Z24: =IF(COUNT(V$5:V$48)=0,"",MIN(X24+Y24,POINTS_CAP_B)) -> 29 | AB24: 21 | AC24: 0.041226852 | AD24: =IF(COUNT(AB$5:AB$48)=0,"",IF(ISNUMBER(AB24),POINTS_CAP_B-AB24,0)) -> 14 | AE24: =IF(COUNT(AB$5:AB$48)=0,"", IFERROR(CHOOSE($B24,HDCP_V_B1,HDCP_V_B2,HDCP_V_B3,HDCP_V_B4),0)) -> 15 | AF24: =IF(COUNT(AB$5:AB$48)=0,"",MIN(AD24+AE24,POINTS_CAP_B)) -> 29 | AH24: 17 | AI24: 0.026990741 | AJ24: =IF(COUNT(AH$5:AH$48)=0,"",IF(ISNUMBER(AH24),POINTS_CAP_B-AH24,0)) -> 18 | AK24: =IF(COUNT(AH$5:AH$48)=0,"", IFERROR(CHOOSE($B24,HDCP_V_B1,HDCP_V_B2,HDCP_V_B3,HDCP_V_B4),0)) -> 15 | AL24: =IF(COUNT(AH$5:AH$48)=0,"",MIN(AJ24+AK24,POINTS_CAP_B)) -> 33 | AN24: =SUM(F24,L24,R24,X24,AD24,AJ24) -> 72 | AO24: =SUM(H24,N24,T24,Z24,AF24,AL24) -> 162
A25: Paul Davey | B25: 4 | D25: 27 | E25: 0.012604167 | F25: =IF(COUNT(D$5:D$48)=0,"",IF(ISNUMBER(D25),POINTS_CAP_B-D25,0)) -> 8 | G25: =IF(COUNT(D$5:D$48)=0,"", IFERROR(CHOOSE($B25,HDCP_V_B1,HDCP_V_B2,HDCP_V_B3,HDCP_V_B4),0)) -> 15 | H25: =IF(COUNT(D$5:D$48)=0,"",MIN(F25+G25,POINTS_CAP_B)) -> 23 | J25: 22 | K25: 0.022534722 | L25: =IF(COUNT(J$5:J$48)=0,"",IF(ISNUMBER(J25),POINTS_CAP_B-J25,0)) -> 13 | M25: =IF(COUNT(J$5:J$48)=0,"", IFERROR(CHOOSE($B25,HDCP_V_B1,HDCP_V_B2,HDCP_V_B3,HDCP_V_B4),0)) -> 15 | N25: =IF(COUNT(J$5:J$48)=0,"",MIN(L25+M25,POINTS_CAP_B)) -> 28 | P25: 25 | Q25: 0.019178241 | R25: =IF(COUNT(P$5:P$48)=0,"",IF(ISNUMBER(P25),POINTS_CAP_B-P25,0)) -> 10 | S25: =IF(COUNT(P$5:P$48)=0,"", IFERROR(CHOOSE($B25,HDCP_V_B1,HDCP_V_B2,HDCP_V_B3,HDCP_V_B4),0)) -> 15 | T25: =IF(COUNT(P$5:P$48)=0,"",MIN(R25+S25,POINTS_CAP_B)) -> 25 | V25: 22 | W25: 0.042546296 | X25: =IF(COUNT(V$5:V$48)=0,"",IF(ISNUMBER(V25),POINTS_CAP_B-V25,0)) -> 13 | Y25: =IF(COUNT(V$5:V$48)=0,"", IFERROR(CHOOSE($B25,HDCP_V_B1,HDCP_V_B2,HDCP_V_B3,HDCP_V_B4),0)) -> 15 | Z25: =IF(COUNT(V$5:V$48)=0,"",MIN(X25+Y25,POINTS_CAP_B)) -> 28 | AB25: 19 | AC25: 0.039918981 | AD25: =IF(COUNT(AB$5:AB$48)=0,"",IF(ISNUMBER(AB25),POINTS_CAP_B-AB25,0)) -> 16 | AE25: =IF(COUNT(AB$5:AB$48)=0,"", IFERROR(CHOOSE($B25,HDCP_V_B1,HDCP_V_B2,HDCP_V_B3,HDCP_V_B4),0)) -> 15 | AF25: =IF(COUNT(AB$5:AB$48)=0,"",MIN(AD25+AE25,POINTS_CAP_B)) -> 31 | AH25: 18 | AI25: 0.027164352 | AJ25: =IF(COUNT(AH$5:AH$48)=0,"",IF(ISNUMBER(AH25),POINTS_CAP_B-AH25,0)) -> 17 | AK25: =IF(COUNT(AH$5:AH$48)=0,"", IFERROR(CHOOSE($B25,HDCP_V_B1,HDCP_V_B2,HDCP_V_B3,HDCP_V_B4),0)) -> 15 | AL25: =IF(COUNT(AH$5:AH$48)=0,"",MIN(AJ25+AK25,POINTS_CAP_B)) -> 32 | AN25: =SUM(F25,L25,R25,X25,AD25,AJ25) -> 77 | AO25: =SUM(H25,N25,T25,Z25,AF25,AL25) -> 167
A26: Barry Moulder | B26: 3 | D26: 22 | E26: 0.012314815 | F26: =IF(COUNT(D$5:D$48)=0,"",IF(ISNUMBER(D26),POINTS_CAP_B-D26,0)) -> 13 | G26: =IF(COUNT(D$5:D$48)=0,"", IFERROR(CHOOSE($B26,HDCP_V_B1,HDCP_V_B2,HDCP_V_B3,HDCP_V_B4),0)) -> 10 | H26: =IF(COUNT(D$5:D$48)=0,"",MIN(F26+G26,POINTS_CAP_B)) -> 23 | J26: 24 | K26: 0.022974537 | L26: =IF(COUNT(J$5:J$48)=0,"",IF(ISNUMBER(J26),POINTS_CAP_B-J26,0)) -> 11 | M26: =IF(COUNT(J$5:J$48)=0,"", IFERROR(CHOOSE($B26,HDCP_V_B1,HDCP_V_B2,HDCP_V_B3,HDCP_V_B4),0)) -> 10 | N26: =IF(COUNT(J$5:J$48)=0,"",MIN(L26+M26,POINTS_CAP_B)) -> 21 | P26: 17 | Q26: 0.018344907 | R26: =IF(COUNT(P$5:P$48)=0,"",IF(ISNUMBER(P26),POINTS_CAP_B-P26,0)) -> 18 | S26: =IF(COUNT(P$5:P$48)=0,"", IFERROR(CHOOSE($B26,HDCP_V_B1,HDCP_V_B2,HDCP_V_B3,HDCP_V_B4),0)) -> 10 | T26: =IF(COUNT(P$5:P$48)=0,"",MIN(R26+S26,POINTS_CAP_B)) -> 28 | V26: 15 | W26: 0.037881944 | X26: =IF(COUNT(V$5:V$48)=0,"",IF(ISNUMBER(V26),POINTS_CAP_B-V26,0)) -> 20 | Y26: =IF(COUNT(V$5:V$48)=0,"", IFERROR(CHOOSE($B26,HDCP_V_B1,HDCP_V_B2,HDCP_V_B3,HDCP_V_B4),0)) -> 10 | Z26: =IF(COUNT(V$5:V$48)=0,"",MIN(X26+Y26,POINTS_CAP_B)) -> 30 | AB26: 17 | AC26: 0.038726852 | AD26: =IF(COUNT(AB$5:AB$48)=0,"",IF(ISNUMBER(AB26),POINTS_CAP_B-AB26,0)) -> 18 | AE26: =IF(COUNT(AB$5:AB$48)=0,"", IFERROR(CHOOSE($B26,HDCP_V_B1,HDCP_V_B2,HDCP_V_B3,HDCP_V_B4),0)) -> 10 | AF26: =IF(COUNT(AB$5:AB$48)=0,"",MIN(AD26+AE26,POINTS_CAP_B)) -> 28 | AH26: 21 | AI26: 0.027627315 | AJ26: =IF(COUNT(AH$5:AH$48)=0,"",IF(ISNUMBER(AH26),POINTS_CAP_B-AH26,0)) -> 14 | AK26: =IF(COUNT(AH$5:AH$48)=0,"", IFERROR(CHOOSE($B26,HDCP_V_B1,HDCP_V_B2,HDCP_V_B3,HDCP_V_B4),0)) -> 10 | AL26: =IF(COUNT(AH$5:AH$48)=0,"",MIN(AJ26+AK26,POINTS_CAP_B)) -> 24 | AN26: =SUM(F26,L26,R26,X26,AD26,AJ26) -> 94 | AO26: =SUM(H26,N26,T26,Z26,AF26,AL26) -> 154
A27: Alan Grant | B27: 3 | D27: 25 | E27: 0.012407407 | F27: =IF(COUNT(D$5:D$48)=0,"",IF(ISNUMBER(D27),POINTS_CAP_B-D27,0)) -> 10 | G27: =IF(COUNT(D$5:D$48)=0,"", IFERROR(CHOOSE($B27,HDCP_V_B1,HDCP_V_B2,HDCP_V_B3,HDCP_V_B4),0)) -> 10 | H27: =IF(COUNT(D$5:D$48)=0,"",MIN(F27+G27,POINTS_CAP_B)) -> 20 | J27: 18 | K27: 0.022349537 | L27: =IF(COUNT(J$5:J$48)=0,"",IF(ISNUMBER(J27),POINTS_CAP_B-J27,0)) -> 17 | M27: =IF(COUNT(J$5:J$48)=0,"", IFERROR(CHOOSE($B27,HDCP_V_B1,HDCP_V_B2,HDCP_V_B3,HDCP_V_B4),0)) -> 10 | N27: =IF(COUNT(J$5:J$48)=0,"",MIN(L27+M27,POINTS_CAP_B)) -> 27 | P27: 23 | Q27: 0.018865741 | R27: =IF(COUNT(P$5:P$48)=0,"",IF(ISNUMBER(P27),POINTS_CAP_B-P27,0)) -> 12 | S27: =IF(COUNT(P$5:P$48)=0,"", IFERROR(CHOOSE($B27,HDCP_V_B1,HDCP_V_B2,HDCP_V_B3,HDCP_V_B4),0)) -> 10 | T27: =IF(COUNT(P$5:P$48)=0,"",MIN(R27+S27,POINTS_CAP_B)) -> 22 | V27: 19 | W27: 0.04125 | X27: =IF(COUNT(V$5:V$48)=0,"",IF(ISNUMBER(V27),POINTS_CAP_B-V27,0)) -> 16 | Y27: =IF(COUNT(V$5:V$48)=0,"", IFERROR(CHOOSE($B27,HDCP_V_B1,HDCP_V_B2,HDCP_V_B3,HDCP_V_B4),0)) -> 10 | Z27: =IF(COUNT(V$5:V$48)=0,"",MIN(X27+Y27,POINTS_CAP_B)) -> 26 | AB27: 20 | AC27: 0.039976852 | AD27: =IF(COUNT(AB$5:AB$48)=0,"",IF(ISNUMBER(AB27),POINTS_CAP_B-AB27,0)) -> 15 | AE27: =IF(COUNT(AB$5:AB$48)=0,"", IFERROR(CHOOSE($B27,HDCP_V_B1,HDCP_V_B2,HDCP_V_B3,HDCP_V_B4),0)) -> 10 | AF27: =IF(COUNT(AB$5:AB$48)=0,"",MIN(AD27+AE27,POINTS_CAP_B)) -> 25 | AH27: 13 | AI27: 0.026030093 | AJ27: =IF(COUNT(AH$5:AH$48)=0,"",IF(ISNUMBER(AH27),POINTS_CAP_B-AH27,0)) -> 22 | AK27: =IF(COUNT(AH$5:AH$48)=0,"", IFERROR(CHOOSE($B27,HDCP_V_B1,HDCP_V_B2,HDCP_V_B3,HDCP_V_B4),0)) -> 10 | AL27: =IF(COUNT(AH$5:AH$48)=0,"",MIN(AJ27+AK27,POINTS_CAP_B)) -> 32 | AN27: =SUM(F27,L27,R27,X27,AD27,AJ27) -> 92 | AO27: =SUM(H27,N27,T27,Z27,AF27,AL27) -> 152
A28: Richard Southcott | B28: 4 | D28: 23 | E28: 0.012372685 | F28: =IF(COUNT(D$5:D$48)=0,"",IF(ISNUMBER(D28),POINTS_CAP_B-D28,0)) -> 12 | G28: =IF(COUNT(D$5:D$48)=0,"", IFERROR(CHOOSE($B28,HDCP_V_B1,HDCP_V_B2,HDCP_V_B3,HDCP_V_B4),0)) -> 15 | H28: =IF(COUNT(D$5:D$48)=0,"",MIN(F28+G28,POINTS_CAP_B)) -> 27 | L28: =IF(COUNT(J$5:J$48)=0,"",IF(ISNUMBER(J28),POINTS_CAP_B-J28,0)) -> 0 | M28: =IF(COUNT(J$5:J$48)=0,"", IFERROR(CHOOSE($B28,HDCP_V_B1,HDCP_V_B2,HDCP_V_B3,HDCP_V_B4),0)) -> 15 | N28: =IF(COUNT(J$5:J$48)=0,"",MIN(L28+M28,POINTS_CAP_B)) -> 15 | R28: =IF(COUNT(P$5:P$48)=0,"",IF(ISNUMBER(P28),POINTS_CAP_B-P28,0)) -> 0 | S28: =IF(COUNT(P$5:P$48)=0,"", IFERROR(CHOOSE($B28,HDCP_V_B1,HDCP_V_B2,HDCP_V_B3,HDCP_V_B4),0)) -> 15 | T28: =IF(COUNT(P$5:P$48)=0,"",MIN(R28+S28,POINTS_CAP_B)) -> 15 | X28: =IF(COUNT(V$5:V$48)=0,"",IF(ISNUMBER(V28),POINTS_CAP_B-V28,0)) -> 0 | Y28: =IF(COUNT(V$5:V$48)=0,"", IFERROR(CHOOSE($B28,HDCP_V_B1,HDCP_V_B2,HDCP_V_B3,HDCP_V_B4),0)) -> 15 | Z28: =IF(COUNT(V$5:V$48)=0,"",MIN(X28+Y28,POINTS_CAP_B)) -> 15 | AD28: =IF(COUNT(AB$5:AB$48)=0,"",IF(ISNUMBER(AB28),POINTS_CAP_B-AB28,0)) -> 0 | AE28: =IF(COUNT(AB$5:AB$48)=0,"", IFERROR(CHOOSE($B28,HDCP_V_B1,HDCP_V_B2,HDCP_V_B3,HDCP_V_B4),0)) -> 15 | AF28: =IF(COUNT(AB$5:AB$48)=0,"",MIN(AD28+AE28,POINTS_CAP_B)) -> 15 | AJ28: =IF(COUNT(AH$5:AH$48)=0,"",IF(ISNUMBER(AH28),POINTS_CAP_B-AH28,0)) -> 0 | AK28: =IF(COUNT(AH$5:AH$48)=0,"", IFERROR(CHOOSE($B28,HDCP_V_B1,HDCP_V_B2,HDCP_V_B3,HDCP_V_B4),0)) -> 15 | AL28: =IF(COUNT(AH$5:AH$48)=0,"",MIN(AJ28+AK28,POINTS_CAP_B)) -> 15 | AN28: =SUM(F28,L28,R28,X28,AD28,AJ28) -> 12 | AO28: =SUM(H28,N28,T28,Z28,AF28,AL28) -> 102
A29: Matt De Freitas | B29: 2 | D29: 11 | E29: 0.011770833 | F29: =IF(COUNT(D$5:D$48)=0,"",IF(ISNUMBER(D29),POINTS_CAP_B-D29,0)) -> 24 | G29: =IF(COUNT(D$5:D$48)=0,"", IFERROR(CHOOSE($B29,HDCP_V_B1,HDCP_V_B2,HDCP_V_B3,HDCP_V_B4),0)) -> 5 | H29: =IF(COUNT(D$5:D$48)=0,"",MIN(F29+G29,POINTS_CAP_B)) -> 29 | J29: 13 | K29: 0.021643519 | L29: =IF(COUNT(J$5:J$48)=0,"",IF(ISNUMBER(J29),POINTS_CAP_B-J29,0)) -> 22 | M29: =IF(COUNT(J$5:J$48)=0,"", IFERROR(CHOOSE($B29,HDCP_V_B1,HDCP_V_B2,HDCP_V_B3,HDCP_V_B4),0)) -> 5 | N29: =IF(COUNT(J$5:J$48)=0,"",MIN(L29+M29,POINTS_CAP_B)) -> 27 | P29: 14 | Q29: 0.018159722 | R29: =IF(COUNT(P$5:P$48)=0,"",IF(ISNUMBER(P29),POINTS_CAP_B-P29,0)) -> 21 | S29: =IF(COUNT(P$5:P$48)=0,"", IFERROR(CHOOSE($B29,HDCP_V_B1,HDCP_V_B2,HDCP_V_B3,HDCP_V_B4),0)) -> 5 | T29: =IF(COUNT(P$5:P$48)=0,"",MIN(R29+S29,POINTS_CAP_B)) -> 26 | X29: =IF(COUNT(V$5:V$48)=0,"",IF(ISNUMBER(V29),POINTS_CAP_B-V29,0)) -> 0 | Y29: =IF(COUNT(V$5:V$48)=0,"", IFERROR(CHOOSE($B29,HDCP_V_B1,HDCP_V_B2,HDCP_V_B3,HDCP_V_B4),0)) -> 5 | Z29: =IF(COUNT(V$5:V$48)=0,"",MIN(X29+Y29,POINTS_CAP_B)) -> 5 | AD29: =IF(COUNT(AB$5:AB$48)=0,"",IF(ISNUMBER(AB29),POINTS_CAP_B-AB29,0)) -> 0 | AE29: =IF(COUNT(AB$5:AB$48)=0,"", IFERROR(CHOOSE($B29,HDCP_V_B1,HDCP_V_B2,HDCP_V_B3,HDCP_V_B4),0)) -> 5 | AF29: =IF(COUNT(AB$5:AB$48)=0,"",MIN(AD29+AE29,POINTS_CAP_B)) -> 5 | AJ29: =IF(COUNT(AH$5:AH$48)=0,"",IF(ISNUMBER(AH29),POINTS_CAP_B-AH29,0)) -> 0 | AK29: =IF(COUNT(AH$5:AH$48)=0,"", IFERROR(CHOOSE($B29,HDCP_V_B1,HDCP_V_B2,HDCP_V_B3,HDCP_V_B4),0)) -> 5 | AL29: =IF(COUNT(AH$5:AH$48)=0,"",MIN(AJ29+AK29,POINTS_CAP_B)) -> 5 | AN29: =SUM(F29,L29,R29,X29,AD29,AJ29) -> 67 | AO29: =SUM(H29,N29,T29,Z29,AF29,AL29) -> 97
A30: Harry Bunnell | B30: 4 | D30: 28 | E30: 0.013020833 | F30: =IF(COUNT(D$5:D$48)=0,"",IF(ISNUMBER(D30),POINTS_CAP_B-D30,0)) -> 7 | G30: =IF(COUNT(D$5:D$48)=0,"", IFERROR(CHOOSE($B30,HDCP_V_B1,HDCP_V_B2,HDCP_V_B3,HDCP_V_B4),0)) -> 15 | H30: =IF(COUNT(D$5:D$48)=0,"",MIN(F30+G30,POINTS_CAP_B)) -> 22 | J30: 25 | K30: 0.022997685 | L30: =IF(COUNT(J$5:J$48)=0,"",IF(ISNUMBER(J30),POINTS_CAP_B-J30,0)) -> 10 | M30: =IF(COUNT(J$5:J$48)=0,"", IFERROR(CHOOSE($B30,HDCP_V_B1,HDCP_V_B2,HDCP_V_B3,HDCP_V_B4),0)) -> 15 | N30: =IF(COUNT(J$5:J$48)=0,"",MIN(L30+M30,POINTS_CAP_B)) -> 25 | P30: 27 | Q30: 0.02005787 | R30: =IF(COUNT(P$5:P$48)=0,"",IF(ISNUMBER(P30),POINTS_CAP_B-P30,0)) -> 8 | S30: =IF(COUNT(P$5:P$48)=0,"", IFERROR(CHOOSE($B30,HDCP_V_B1,HDCP_V_B2,HDCP_V_B3,HDCP_V_B4),0)) -> 15 | T30: =IF(COUNT(P$5:P$48)=0,"",MIN(R30+S30,POINTS_CAP_B)) -> 23 | X30: =IF(COUNT(V$5:V$48)=0,"",IF(ISNUMBER(V30),POINTS_CAP_B-V30,0)) -> 0 | Y30: =IF(COUNT(V$5:V$48)=0,"", IFERROR(CHOOSE($B30,HDCP_V_B1,HDCP_V_B2,HDCP_V_B3,HDCP_V_B4),0)) -> 15 | Z30: =IF(COUNT(V$5:V$48)=0,"",MIN(X30+Y30,POINTS_CAP_B)) -> 15 | AB30: 23 | AC30: 0.043761574 | AD30: =IF(COUNT(AB$5:AB$48)=0,"",IF(ISNUMBER(AB30),POINTS_CAP_B-AB30,0)) -> 12 | AE30: =IF(COUNT(AB$5:AB$48)=0,"", IFERROR(CHOOSE($B30,HDCP_V_B1,HDCP_V_B2,HDCP_V_B3,HDCP_V_B4),0)) -> 15 | AF30: =IF(COUNT(AB$5:AB$48)=0,"",MIN(AD30+AE30,POINTS_CAP_B)) -> 27 | AJ30: =IF(COUNT(AH$5:AH$48)=0,"",IF(ISNUMBER(AH30),POINTS_CAP_B-AH30,0)) -> 0 | AK30: =IF(COUNT(AH$5:AH$48)=0,"", IFERROR(CHOOSE($B30,HDCP_V_B1,HDCP_V_B2,HDCP_V_B3,HDCP_V_B4),0)) -> 15 | AL30: =IF(COUNT(AH$5:AH$48)=0,"",MIN(AJ30+AK30,POINTS_CAP_B)) -> 15 | AN30: =SUM(F30,L30,R30,X30,AD30,AJ30) -> 37 | AO30: =SUM(H30,N30,T30,Z30,AF30,AL30) -> 127
A31: Andy Whiteside | B31: 4 | D31: 26 | E31: 0.012546296 | F31: =IF(COUNT(D$5:D$48)=0,"",IF(ISNUMBER(D31),POINTS_CAP_B-D31,0)) -> 9 | G31: =IF(COUNT(D$5:D$48)=0,"", IFERROR(CHOOSE($B31,HDCP_V_B1,HDCP_V_B2,HDCP_V_B3,HDCP_V_B4),0)) -> 15 | H31: =IF(COUNT(D$5:D$48)=0,"",MIN(F31+G31,POINTS_CAP_B)) -> 24 | L31: =IF(COUNT(J$5:J$48)=0,"",IF(ISNUMBER(J31),POINTS_CAP_B-J31,0)) -> 0 | M31: =IF(COUNT(J$5:J$48)=0,"", IFERROR(CHOOSE($B31,HDCP_V_B1,HDCP_V_B2,HDCP_V_B3,HDCP_V_B4),0)) -> 15 | N31: =IF(COUNT(J$5:J$48)=0,"",MIN(L31+M31,POINTS_CAP_B)) -> 15 | R31: =IF(COUNT(P$5:P$48)=0,"",IF(ISNUMBER(P31),POINTS_CAP_B-P31,0)) -> 0 | S31: =IF(COUNT(P$5:P$48)=0,"", IFERROR(CHOOSE($B31,HDCP_V_B1,HDCP_V_B2,HDCP_V_B3,HDCP_V_B4),0)) -> 15 | T31: =IF(COUNT(P$5:P$48)=0,"",MIN(R31+S31,POINTS_CAP_B)) -> 15 | X31: =IF(COUNT(V$5:V$48)=0,"",IF(ISNUMBER(V31),POINTS_CAP_B-V31,0)) -> 0 | Y31: =IF(COUNT(V$5:V$48)=0,"", IFERROR(CHOOSE($B31,HDCP_V_B1,HDCP_V_B2,HDCP_V_B3,HDCP_V_B4),0)) -> 15 | Z31: =IF(COUNT(V$5:V$48)=0,"",MIN(X31+Y31,POINTS_CAP_B)) -> 15 | AD31: =IF(COUNT(AB$5:AB$48)=0,"",IF(ISNUMBER(AB31),POINTS_CAP_B-AB31,0)) -> 0 | AE31: =IF(COUNT(AB$5:AB$48)=0,"", IFERROR(CHOOSE($B31,HDCP_V_B1,HDCP_V_B2,HDCP_V_B3,HDCP_V_B4),0)) -> 15 | AF31: =IF(COUNT(AB$5:AB$48)=0,"",MIN(AD31+AE31,POINTS_CAP_B)) -> 15 | AJ31: =IF(COUNT(AH$5:AH$48)=0,"",IF(ISNUMBER(AH31),POINTS_CAP_B-AH31,0)) -> 0 | AK31: =IF(COUNT(AH$5:AH$48)=0,"", IFERROR(CHOOSE($B31,HDCP_V_B1,HDCP_V_B2,HDCP_V_B3,HDCP_V_B4),0)) -> 15 | AL31: =IF(COUNT(AH$5:AH$48)=0,"",MIN(AJ31+AK31,POINTS_CAP_B)) -> 15 | AN31: =SUM(F31,L31,R31,X31,AD31,AJ31) -> 9 | AO31: =SUM(H31,N31,T31,Z31,AF31,AL31) -> 99
A32: Olly Wright | B32: 3 | D32: 12 | E32: 0.011805556 | F32: =IF(COUNT(D$5:D$48)=0,"",IF(ISNUMBER(D32),POINTS_CAP_B-D32,0)) -> 23 | G32: =IF(COUNT(D$5:D$48)=0,"", IFERROR(CHOOSE($B32,HDCP_V_B1,HDCP_V_B2,HDCP_V_B3,HDCP_V_B4),0)) -> 10 | H32: =IF(COUNT(D$5:D$48)=0,"",MIN(F32+G32,POINTS_CAP_B)) -> 33 | L32: =IF(COUNT(J$5:J$48)=0,"",IF(ISNUMBER(J32),POINTS_CAP_B-J32,0)) -> 0 | M32: =IF(COUNT(J$5:J$48)=0,"", IFERROR(CHOOSE($B32,HDCP_V_B1,HDCP_V_B2,HDCP_V_B3,HDCP_V_B4),0)) -> 10 | N32: =IF(COUNT(J$5:J$48)=0,"",MIN(L32+M32,POINTS_CAP_B)) -> 10 | P32: 24 | Q32: 0.018958333 | R32: =IF(COUNT(P$5:P$48)=0,"",IF(ISNUMBER(P32),POINTS_CAP_B-P32,0)) -> 11 | S32: =IF(COUNT(P$5:P$48)=0,"", IFERROR(CHOOSE($B32,HDCP_V_B1,HDCP_V_B2,HDCP_V_B3,HDCP_V_B4),0)) -> 10 | T32: =IF(COUNT(P$5:P$48)=0,"",MIN(R32+S32,POINTS_CAP_B)) -> 21 | X32: =IF(COUNT(V$5:V$48)=0,"",IF(ISNUMBER(V32),POINTS_CAP_B-V32,0)) -> 0 | Y32: =IF(COUNT(V$5:V$48)=0,"", IFERROR(CHOOSE($B32,HDCP_V_B1,HDCP_V_B2,HDCP_V_B3,HDCP_V_B4),0)) -> 10 | Z32: =IF(COUNT(V$5:V$48)=0,"",MIN(X32+Y32,POINTS_CAP_B)) -> 10 | AD32: =IF(COUNT(AB$5:AB$48)=0,"",IF(ISNUMBER(AB32),POINTS_CAP_B-AB32,0)) -> 0 | AE32: =IF(COUNT(AB$5:AB$48)=0,"", IFERROR(CHOOSE($B32,HDCP_V_B1,HDCP_V_B2,HDCP_V_B3,HDCP_V_B4),0)) -> 10 | AF32: =IF(COUNT(AB$5:AB$48)=0,"",MIN(AD32+AE32,POINTS_CAP_B)) -> 10 | AJ32: =IF(COUNT(AH$5:AH$48)=0,"",IF(ISNUMBER(AH32),POINTS_CAP_B-AH32,0)) -> 0 | AK32: =IF(COUNT(AH$5:AH$48)=0,"", IFERROR(CHOOSE($B32,HDCP_V_B1,HDCP_V_B2,HDCP_V_B3,HDCP_V_B4),0)) -> 10 | AL32: =IF(COUNT(AH$5:AH$48)=0,"",MIN(AJ32+AK32,POINTS_CAP_B)) -> 10 | AN32: =SUM(F32,L32,R32,X32,AD32,AJ32) -> 34 | AO32: =SUM(H32,N32,T32,Z32,AF32,AL32) -> 94
A33: Grant Campbell | B33: 4 | F33: =IF(COUNT(D$5:D$48)=0,"",IF(ISNUMBER(D33),POINTS_CAP_B-D33,0)) -> 0 | G33: =IF(COUNT(D$5:D$48)=0,"", IFERROR(CHOOSE($B33,HDCP_V_B1,HDCP_V_B2,HDCP_V_B3,HDCP_V_B4),0)) -> 15 | H33: =IF(COUNT(D$5:D$48)=0,"",MIN(F33+G33,POINTS_CAP_B)) -> 15 | L33: =IF(COUNT(J$5:J$48)=0,"",IF(ISNUMBER(J33),POINTS_CAP_B-J33,0)) -> 0 | M33: =IF(COUNT(J$5:J$48)=0,"", IFERROR(CHOOSE($B33,HDCP_V_B1,HDCP_V_B2,HDCP_V_B3,HDCP_V_B4),0)) -> 15 | N33: =IF(COUNT(J$5:J$48)=0,"",MIN(L33+M33,POINTS_CAP_B)) -> 15 | R33: =IF(COUNT(P$5:P$48)=0,"",IF(ISNUMBER(P33),POINTS_CAP_B-P33,0)) -> 0 | S33: =IF(COUNT(P$5:P$48)=0,"", IFERROR(CHOOSE($B33,HDCP_V_B1,HDCP_V_B2,HDCP_V_B3,HDCP_V_B4),0)) -> 15 | T33: =IF(COUNT(P$5:P$48)=0,"",MIN(R33+S33,POINTS_CAP_B)) -> 15 | X33: =IF(COUNT(V$5:V$48)=0,"",IF(ISNUMBER(V33),POINTS_CAP_B-V33,0)) -> 0 | Y33: =IF(COUNT(V$5:V$48)=0,"", IFERROR(CHOOSE($B33,HDCP_V_B1,HDCP_V_B2,HDCP_V_B3,HDCP_V_B4),0)) -> 15 | Z33: =IF(COUNT(V$5:V$48)=0,"",MIN(X33+Y33,POINTS_CAP_B)) -> 15 | AD33: =IF(COUNT(AB$5:AB$48)=0,"",IF(ISNUMBER(AB33),POINTS_CAP_B-AB33,0)) -> 0 | AE33: =IF(COUNT(AB$5:AB$48)=0,"", IFERROR(CHOOSE($B33,HDCP_V_B1,HDCP_V_B2,HDCP_V_B3,HDCP_V_B4),0)) -> 15 | AF33: =IF(COUNT(AB$5:AB$48)=0,"",MIN(AD33+AE33,POINTS_CAP_B)) -> 15 | AJ33: =IF(COUNT(AH$5:AH$48)=0,"",IF(ISNUMBER(AH33),POINTS_CAP_B-AH33,0)) -> 0 | AK33: =IF(COUNT(AH$5:AH$48)=0,"", IFERROR(CHOOSE($B33,HDCP_V_B1,HDCP_V_B2,HDCP_V_B3,HDCP_V_B4),0)) -> 15 | AL33: =IF(COUNT(AH$5:AH$48)=0,"",MIN(AJ33+AK33,POINTS_CAP_B)) -> 15 | AN33: =SUM(F33,L33,R33,X33,AD33,AJ33) -> 0 | AO33: =SUM(H33,N33,T33,Z33,AF33,AL33) -> 90
A34: Nick Davis | B34: 2 | D34: 24 | E34: 0.012384259 | F34: =IF(COUNT(D$5:D$48)=0,"",IF(ISNUMBER(D34),POINTS_CAP_B-D34,0)) -> 11 | G34: =IF(COUNT(D$5:D$48)=0,"", IFERROR(CHOOSE($B34,HDCP_V_B1,HDCP_V_B2,HDCP_V_B3,HDCP_V_B4),0)) -> 5 | H34: =IF(COUNT(D$5:D$48)=0,"",MIN(F34+G34,POINTS_CAP_B)) -> 16 | L34: =IF(COUNT(J$5:J$48)=0,"",IF(ISNUMBER(J34),POINTS_CAP_B-J34,0)) -> 0 | M34: =IF(COUNT(J$5:J$48)=0,"", IFERROR(CHOOSE($B34,HDCP_V_B1,HDCP_V_B2,HDCP_V_B3,HDCP_V_B4),0)) -> 5 | N34: =IF(COUNT(J$5:J$48)=0,"",MIN(L34+M34,POINTS_CAP_B)) -> 5 | P34: 20 | Q34: 0.018634259 | R34: =IF(COUNT(P$5:P$48)=0,"",IF(ISNUMBER(P34),POINTS_CAP_B-P34,0)) -> 15 | S34: =IF(COUNT(P$5:P$48)=0,"", IFERROR(CHOOSE($B34,HDCP_V_B1,HDCP_V_B2,HDCP_V_B3,HDCP_V_B4),0)) -> 5 | T34: =IF(COUNT(P$5:P$48)=0,"",MIN(R34+S34,POINTS_CAP_B)) -> 20 | V34: 20 | W34: 0.041805556 | X34: =IF(COUNT(V$5:V$48)=0,"",IF(ISNUMBER(V34),POINTS_CAP_B-V34,0)) -> 15 | Y34: =IF(COUNT(V$5:V$48)=0,"", IFERROR(CHOOSE($B34,HDCP_V_B1,HDCP_V_B2,HDCP_V_B3,HDCP_V_B4),0)) -> 5 | Z34: =IF(COUNT(V$5:V$48)=0,"",MIN(X34+Y34,POINTS_CAP_B)) -> 20 | AD34: =IF(COUNT(AB$5:AB$48)=0,"",IF(ISNUMBER(AB34),POINTS_CAP_B-AB34,0)) -> 0 | AE34: =IF(COUNT(AB$5:AB$48)=0,"", IFERROR(CHOOSE($B34,HDCP_V_B1,HDCP_V_B2,HDCP_V_B3,HDCP_V_B4),0)) -> 5 | AF34: =IF(COUNT(AB$5:AB$48)=0,"",MIN(AD34+AE34,POINTS_CAP_B)) -> 5 | AJ34: =IF(COUNT(AH$5:AH$48)=0,"",IF(ISNUMBER(AH34),POINTS_CAP_B-AH34,0)) -> 0 | AK34: =IF(COUNT(AH$5:AH$48)=0,"", IFERROR(CHOOSE($B34,HDCP_V_B1,HDCP_V_B2,HDCP_V_B3,HDCP_V_B4),0)) -> 5 | AL34: =IF(COUNT(AH$5:AH$48)=0,"",MIN(AJ34+AK34,POINTS_CAP_B)) -> 5 | AN34: =SUM(F34,L34,R34,X34,AD34,AJ34) -> 41 | AO34: =SUM(H34,N34,T34,Z34,AF34,AL34) -> 71

Sheet Handicaps
B2: B1 | C2: 0
B3: B2 | C3: 5
B4: B2 | C4: 10
B5: B4 | C5: 15
B7: Cap (A) | C7: 35

Sheet Results - A
A1: Overall | E1: Stage 1 | M1: Stage 2 | U1: Stage 3 | AC1: Stage 4 | AK1: Stage 5 | AS1: Stage 6
A2: Position | B2: Name | C2: Total Points | E2: Rank | F2: Name | G2: Pos. | H2: Time | I2: Base Pts. | J2: Handicap | K2: Points | M2: Rank | N2: Name | O2: Pos. | P2: Time | Q2: Base Pts. | R2: Handicap | S2: Points | U2: Rank | V2: Name | W2: Pos. | X2: Time | Y2: Base Pts. | Z2: Handicap | AA2: Points | AC2: Rank | AD2: Name | AE2: Pos. | AF2: Time | AG2: Base Pts. | AH2: Handicap | AI2: Points | AK2: Rank | AL2: Name | AM2: Pos. | AN2: Time | AO2: Base Pts. | AP2: Handicap | AQ2: Points | AS2: Rank | AT2: Name | AU2: Pos. | AV2: Time | AW2: Base Pts. | AX2: Handicap | AY2: Points
A4: {=_xlfn.LET(_xlpm.pts,INDEX(_xlfn.ANCHORARRAY($B$4),0,2),1+COUNTIF(_xlpm.pts,">"&INDEX(_xlfn.ANCHORARRAY($B$4),ROW()-ROW($A$4)+1,2)))} -> 1 | B4: {=_xlfn.LET( _xlpm.names,'Stage Data - A'!$A$5:$A$48, _xlpm.total,'Stage Data - A'!$AO$5:$AO$48, _xlpm.data,_xlfn._xlws.FILTER(CHOOSE({1,2},_xlpm.names,_xlpm.total),_xlpm.names<>""), _xlfn.SORTBY(_xlpm.data,INDEX(_xlpm.data,,2),-1,INDEX(_xlpm.data,,1),1) )} -> Raif Oz | C4: 209 | E4: {=_xlfn.LET(_xlpm.pts,INDEX(_xlfn.ANCHORARRAY($F$4),0,6),1+COUNTIF(_xlpm.pts,">"&INDEX(_xlfn.ANCHORARRAY($F$4),ROW()-ROW($E$4)+1,6)))} -> 1 | F4: {=_xlfn.LET( _xlpm.names,'Stage Data - A'!$A$5:$A$48, _xlpm.stpos,'Stage Data - A'!D$5:D$48, _xlpm.time,'Stage Data - A'!E$5:E$48, _xlpm.base,'Stage Data - A'!F$5:F$48, _xlpm.hdcp,'Stage Data - A'!G$5:G$48, _xlpm.adj,'Stage Data - A'!H$5:H$48, _xlpm.data,_xlfn._xlws.FILTER(CHOOSE({1,2,3,4,5,6},_xlpm.names,_xlpm.stpos,_xlpm.time,_xlpm.base,_xlpm.hdcp,_xlpm.adj), _xlpm.adj<>""), _xlfn.SORTBY(_xlpm.data, INDEX(_xlpm.data,,6), -1, INDEX(_xlpm.data,,1), 1) )} -> Alice Lethbridge | G4: 1 | H4: 0.011539352 | I4: 34 | J4: 5 | K4: 35 | M4: {=_xlfn.LET(_xlpm.pts,INDEX(_xlfn.ANCHORARRAY($N$4),0,6),1+COUNTIF(_xlpm.pts,">"&INDEX(_xlfn.ANCHORARRAY($N$4),ROW()-ROW($M$4)+1,6)))} -> 1 | N4: {=_xlfn.LET( _xlpm.names,'Stage Data - A'!$A$5:$A$48, _xlpm.stpos,'Stage Data - A'!J$5:J$48, _xlpm.time,'Stage Data - A'!K$5:K$48, _xlpm.base,'Stage Data - A'!L$5:L$48, _xlpm.hdcp,'Stage Data - A'!M$5:M$48, _xlpm.adj,'Stage Data - A'!N$5:N$48, _xlpm.data,_xlfn._xlws.FILTER(CHOOSE({1,2,3,4,5,6},_xlpm.names,_xlpm.stpos,_xlpm.time,_xlpm.base,_xlpm.hdcp,_xlpm.adj), _xlpm.adj<>""), _xlfn.SORTBY(_xlpm.data, INDEX(_xlpm.data,,6), -1, INDEX(_xlpm.data,,1), 1) )} -> Alice Lethbridge | O4: 5 | P4: 0.021053241 | Q4: 30 | R4: 5 | S4: 35 | U4: {=_xlfn.LET(_xlpm.pts,INDEX(_xlfn.ANCHORARRAY($V$4),0,6),1+COUNTIF(_xlpm.pts,">"&INDEX(_xlfn.ANCHORARRAY($V$4),ROW()-ROW($U$4)+1,6)))} -> 1 | V4: {=_xlfn.LET( _xlpm.names,'Stage Data - A'!$A$5:$A$50, _xlpm.stpos,'Stage Data - A'!P$5:P$50, _xlpm.time,'Stage Data - A'!Q$5:Q$50, _xlpm.base,'Stage Data - A'!R$5:R$50, _xlpm.hdcp,'Stage Data - A'!S$5:S$50, _xlpm.adj,'Stage Data - A'!T$5:T$50, _xlpm.data,_xlfn._xlws.FILTER(CHOOSE({1,2,3,4,5,6},_xlpm.names,_xlpm.stpos,_xlpm.time,_xlpm.base,_xlpm.hdcp,_xlpm.adj), _xlpm.adj<>""), _xlfn.SORTBY(_xlpm.data, INDEX(_xlpm.data,,6), -1, INDEX(_xlpm.data,,1), 1) )} -> Alice Lethbridge | W4: 4 | X4: 0.017418981 | Y4: 31 | Z4: 5 | AA4: 35 | AC4: {=_xlfn.LET(_xlpm.pts,INDEX(_xlfn.ANCHORARRAY($AD$4),0,6),1+COUNTIF(_xlpm.pts,">"&INDEX(_xlfn.ANCHORARRAY($AD$4),ROW()-ROW($AC$4)+1,6)))} -> 1 | AD4: {=_xlfn.LET( _xlpm.names,'Stage Data - A'!$A$5:$A$50, _xlpm.stpos,'Stage Data - A'!V$5:V$50, _xlpm.time,'Stage Data - A'!W$5:W$50, _xlpm.base,'Stage Data - A'!X$5:X$50, _xlpm.hdcp,'Stage Data - A'!Y$5:Y$50, _xlpm.adj,'Stage Data - A'!Z$5:Z$50, _xlpm.data,_xlfn._xlws.FILTER(CHOOSE({1,2,3,4,5,6},_xlpm.names,_xlpm.stpos,_xlpm.time,_xlpm.base,_xlpm.hdcp,_xlpm.adj), _xlpm.adj<>""), _xlfn.SORTBY(_xlpm.data, INDEX(_xlpm.data,,6), -1, INDEX(_xlpm.data,,1), 1) )} -> Raif Oz | AE4: 5 | AF4: 0.034699074 | AG4: 30 | AH4: 5 | AI4: 35 | AK4: {=_xlfn.LET(_xlpm.pts,INDEX(_xlfn.ANCHORARRAY($AL$4),0,6),1+COUNTIF(_xlpm.pts,">"&INDEX(_xlfn.ANCHORARRAY($AL$4),ROW()-ROW($AK$4)+1,6)))} -> 1 | AL4: {=_xlfn.LET( _xlpm.names,'Stage Data - A'!$A$5:$A$50, _xlpm.stpos,'Stage Data - A'!AB$5:AB$50, _xlpm.time,'Stage Data - A'!AC$5:AC$50, _xlpm.base,'Stage Data - A'!AD$5:AD$50, _xlpm.hdcp,'Stage Data - A'!AE$5:AE$50, _xlpm.adj,'Stage Data - A'!AF$5:AF$50, _xlpm.data,_xlfn._xlws.FILTER(CHOOSE({1,2,3,4,5,6},_xlpm.names,_xlpm.stpos,_xlpm.time,_xlpm.base,_xlpm.hdcp,_xlpm.adj), _xlpm.adj<>""), _xlfn.SORTBY(_xlpm.data, INDEX(_xlpm.data,,6), -1, INDEX(_xlpm.data,,1), 1) )} -> Eamon Mason | AM4: 15 | AN4: 0.037858796 | AO4: 20 | AP4: 15 | AQ4: 35 | AS4: {=_xlfn.LET(_xlpm.pts,INDEX(_xlfn.ANCHORARRAY($AT$4),0,6),1+COUNTIF(_xlpm.pts,">"&INDEX(_xlfn.ANCHORARRAY($AT$4),ROW()-ROW($AU$4)+1,6)))} -> 1 | AT4: {=_xlfn.LET( _xlpm.names,'Stage Data - A'!$A$5:$A$50, _xlpm.stpos,'Stage Data - A'!AH$5:AH$50, _xlpm.time,'Stage Data - A'!AI$5:AI$50, _xlpm.base,'Stage Data - A'!AJ$5:AJ$50, _xlpm.hdcp,'Stage Data - A'!AK$5:AK$50, _xlpm.adj,'Stage Data - A'!AL$5:AL$50, _xlpm.data,_xlfn._xlws.FILTER(CHOOSE({1,2,3,4,5,6},_xlpm.names,_xlpm.stpos,_xlpm.time,_xlpm.base,_xlpm.hdcp,_xlpm.adj), _xlpm.adj<>""), _xlfn.SORTBY(_xlpm.data, INDEX(_xlpm.data,,6), -1, INDEX(_xlpm.data,,1), 1) )} -> Bill McClatchie | AU4: 7 | AV4: 0.02556713 | AW4: 28 | AX4: 10 | AY4: 35
A5: {=_xlfn.LET(_xlpm.pts,INDEX(_xlfn.ANCHORARRAY($B$4),0,2),1+COUNTIF(_xlpm.pts,">"&INDEX(_xlfn.ANCHORARRAY($B$4),ROW()-ROW($A$4)+1,2)))} -> 2 | B5: Eamon Mason | C5: 203 | E5: {=_xlfn.LET(_xlpm.pts,INDEX(_xlfn.ANCHORARRAY($F$4),0,6),1+COUNTIF(_xlpm.pts,">"&INDEX(_xlfn.ANCHORARRAY($F$4),ROW()-ROW($E$4)+1,6)))} -> 1 | F5: Bill McClatchie | G5: 10 | H5: 0.011759259 | I5: 25 | J5: 10 | K5: 35 | M5: {=_xlfn.LET(_xlpm.pts,INDEX(_xlfn.ANCHORARRAY($N$4),0,6),1+COUNTIF(_xlpm.pts,">"&INDEX(_xlfn.ANCHORARRAY($N$4),ROW()-ROW($M$4)+1,6)))} -> 1 | N5: Bill McClatchie | O5: 10 | P5: 0.021342593 | Q5: 25 | R5: 10 | S5: 35 | U5: {=_xlfn.LET(_xlpm.pts,INDEX(_xlfn.ANCHORARRAY($V$4),0,6),1+COUNTIF(_xlpm.pts,">"&INDEX(_xlfn.ANCHORARRAY($V$4),ROW()-ROW($U$4)+1,6)))} -> 1 | V5: Bill McClatchie | W5: 9 | X5: 0.017604167 | Y5: 26 | Z5: 10 | AA5: 35 | AC5: {=_xlfn.LET(_xlpm.pts,INDEX(_xlfn.ANCHORARRAY($AD$4),0,6),1+COUNTIF(_xlpm.pts,">"&INDEX(_xlfn.ANCHORARRAY($AD$4),ROW()-ROW($AC$4)+1,6)))} -> 2 | AD5: Alice Lethbridge | AE5: 6 | AF5: 0.035821759 | AG5: 29 | AH5: 5 | AI5: 34 | AK5: {=_xlfn.LET(_xlpm.pts,INDEX(_xlfn.ANCHORARRAY($AL$4),0,6),1+COUNTIF(_xlpm.pts,">"&INDEX(_xlfn.ANCHORARRAY($AL$4),ROW()-ROW($AK$4)+1,6)))} -> 1 | AL5: Raif Oz | AM5: 4 | AN5: 0.035335648 | AO5: 31 | AP5: 5 | AQ5: 35 | AS5: {=_xlfn.LET(_xlpm.pts,INDEX(_xlfn.ANCHORARRAY($AT$4),0,6),1+COUNTIF(_xlpm.pts,">"&INDEX(_xlfn.ANCHORARRAY($AT$4),ROW()-ROW($AU$4)+1,6)))} -> 1 | AT5: Eamon Mason | AU5: 15 | AV5: 0.026388889 | AW5: 20 | AX5: 15 | AY5: 35
A6: {=_xlfn.LET(_xlpm.pts,INDEX(_xlfn.ANCHORARRAY($B$4),0,2),1+COUNTIF(_xlpm.pts,">"&INDEX(_xlfn.ANCHORARRAY($B$4),ROW()-ROW($A$4)+1,2)))} -> 3 | B6: Tobi Rosenkranz | C6: 202 | E6: {=_xlfn.LET(_xlpm.pts,INDEX(_xlfn.ANCHORARRAY($F$4),0,6),1+COUNTIF(_xlpm.pts,">"&INDEX(_xlfn.ANCHORARRAY($F$4),ROW()-ROW($E$4)+1,6)))} -> 1 | F6: Henrik Persson | G6: 2 | H6: 0.0115625 | I6: 33 | J6: 5 | K6: 35 | M6: {=_xlfn.LET(_xlpm.pts,INDEX(_xlfn.ANCHORARRAY($N$4),0,6),1+COUNTIF(_xlpm.pts,">"&INDEX(_xlfn.ANCHORARRAY($N$4),ROW()-ROW($M$4)+1,6)))} -> 1 | N6: Eamon Mason | O6: 12 | P6: 0.021516204 | Q6: 23 | R6: 15 | S6: 35 | U6: {=_xlfn.LET(_xlpm.pts,INDEX(_xlfn.ANCHORARRAY($V$4),0,6),1+COUNTIF(_xlpm.pts,">"&INDEX(_xlfn.ANCHORARRAY($V$4),ROW()-ROW($U$4)+1,6)))} -> 1 | V6: Eamon Mason | W6: 15 | X6: 0.01818287 | Y6: 20 | Z6: 15 | AA6: 35 | AC6: {=_xlfn.LET(_xlpm.pts,INDEX(_xlfn.ANCHORARRAY($AD$4),0,6),1+COUNTIF(_xlpm.pts,">"&INDEX(_xlfn.ANCHORARRAY($AD$4),ROW()-ROW($AC$4)+1,6)))} -> 2 | AD6: Judah Rand | AE6: 1 | AF6: 0.031782407 | AG6: 34 | AH6: 0 | AI6: 34 | AK6: {=_xlfn.LET(_xlpm.pts,INDEX(_xlfn.ANCHORARRAY($AL$4),0,6),1+COUNTIF(_xlpm.pts,">"&INDEX(_xlfn.ANCHORARRAY($AL$4),ROW()-ROW($AK$4)+1,6)))} -> 1 | AL6: Tobi Rosenkranz | AM6: 5 | AN6: 0.035381944 | AO6: 30 | AP6: 5 | AQ6: 35 | AS6: {=_xlfn.LET(_xlpm.pts,INDEX(_xlfn.ANCHORARRAY($AT$4),0,6),1+COUNTIF(_xlpm.pts,">"&INDEX(_xlfn.ANCHORARRAY($AT$4),ROW()-ROW($AU$4)+1,6)))} -> 1 | AT6: Raif Oz | AU6: 3 | AV6: 0.02494213 | AW6: 32 | AX6: 5 | AY6: 35
A7: {=_xlfn.LET(_xlpm.pts,INDEX(_xlfn.ANCHORARRAY($B$4),0,2),1+COUNTIF(_xlpm.pts,">"&INDEX(_xlfn.ANCHORARRAY($B$4),ROW()-ROW($A$4)+1,2)))} -> 4 | B7: Bill McClatchie | C7: 200 | E7: {=_xlfn.LET(_xlpm.pts,INDEX(_xlfn.ANCHORARRAY($F$4),0,6),1+COUNTIF(_xlpm.pts,">"&INDEX(_xlfn.ANCHORARRAY($F$4),ROW()-ROW($E$4)+1,6)))} -> 1 | F7: Raif Oz | G7: 4 | H7: 0.011597222 | I7: 31 | J7: 5 | K7: 35 | M7: {=_xlfn.LET(_xlpm.pts,INDEX(_xlfn.ANCHORARRAY($N$4),0,6),1+COUNTIF(_xlpm.pts,">"&INDEX(_xlfn.ANCHORARRAY($N$4),ROW()-ROW($M$4)+1,6)))} -> 1 | N7: Neal Beauchamp | O7: 4 | P7: 0.021018519 | Q7: 31 | R7: 5 | S7: 35 | U7: {=_xlfn.LET(_xlpm.pts,INDEX(_xlfn.ANCHORARRAY($V$4),0,6),1+COUNTIF(_xlpm.pts,">"&INDEX(_xlfn.ANCHORARRAY($V$4),ROW()-ROW($U$4)+1,6)))} -> 1 | V7: Henrik Persson | W7: 3 | X7: 0.017407407 | Y7: 32 | Z7: 5 | AA7: 35 | AC7: {=_xlfn.LET(_xlpm.pts,INDEX(_xlfn.ANCHORARRAY($AD$4),0,6),1+COUNTIF(_xlpm.pts,">"&INDEX(_xlfn.ANCHORARRAY($AD$4),ROW()-ROW($AC$4)+1,6)))} -> 4 | AD7: Chris Jenkins | AE7: 7 | AF7: 0.036076389 | AG7: 28 | AH7: 5 | AI7: 33 | AK7: {=_xlfn.LET(_xlpm.pts,INDEX(_xlfn.ANCHORARRAY($AL$4),0,6),1+COUNTIF(_xlpm.pts,">"&INDEX(_xlfn.ANCHORARRAY($AL$4),ROW()-ROW($AK$4)+1,6)))} -> 4 | AL7: Chris Jenkins | AM7: 6 | AN7: 0.035439815 | AO7: 29 | AP7: 5 | AQ7: 34 | AS7: {=_xlfn.LET(_xlpm.pts,INDEX(_xlfn.ANCHORARRAY($AT$4),0,6),1+COUNTIF(_xlpm.pts,">"&INDEX(_xlfn.ANCHORARRAY($AT$4),ROW()-ROW($AU$4)+1,6)))} -> 1 | AT7: Tobi Rosenkranz | AU7: 5 | AV7: 0.025555556 | AW7: 30 | AX7: 5 | AY7: 35
A8: {=_xlfn.LET(_xlpm.pts,INDEX(_xlfn.ANCHORARRAY($B$4),0,2),1+COUNTIF(_xlpm.pts,">"&INDEX(_xlfn.ANCHORARRAY($B$4),ROW()-ROW($A$4)+1,2)))} -> 5 | B8: Judah Rand | C8: 199 | E8: {=_xlfn.LET(_xlpm.pts,INDEX(_xlfn.ANCHORARRAY($F$4),0,6),1+COUNTIF(_xlpm.pts,">"&INDEX(_xlfn.ANCHORARRAY($F$4),ROW()-ROW($E$4)+1,6)))} -> 5 | F8: Neal Beauchamp | G8: 7 | H8: 0.01162037 | I8: 28 | J8: 5 | K8: 33 | M8: {=_xlfn.LET(_xlpm.pts,INDEX(_xlfn.ANCHORARRAY($N$4),0,6),1+COUNTIF(_xlpm.pts,">"&INDEX(_xlfn.ANCHORARRAY($N$4),ROW()-ROW($M$4)+1,6)))} -> 1 | N8: Richard Turner | O8: 15 | P8: 0.021770833 | Q8: 20 | R8: 15 | S8: 35 | U8: {=_xlfn.LET(_xlpm.pts,INDEX(_xlfn.ANCHORARRAY($V$4),0,6),1+COUNTIF(_xlpm.pts,">"&INDEX(_xlfn.ANCHORARRAY($V$4),ROW()-ROW($U$4)+1,6)))} -> 1 | V8: Raif Oz | W8: 4 | X8: 0.017418981 | Y8: 31 | Z8: 5 | AA8: 35 | AC8: {=_xlfn.LET(_xlpm.pts,INDEX(_xlfn.ANCHORARRAY($AD$4),0,6),1+COUNTIF(_xlpm.pts,">"&INDEX(_xlfn.ANCHORARRAY($AD$4),ROW()-ROW($AC$4)+1,6)))} -> 4 | AD8: Conor Walsh | AE8: 2 | AF8: 0.032662037 | AG8: 33 | AH8: 0 | AI8: 33 | AK8: {=_xlfn.LET(_xlpm.pts,INDEX(_xlfn.ANCHORARRAY($AL$4),0,6),1+COUNTIF(_xlpm.pts,">"&INDEX(_xlfn.ANCHORARRAY($AL$4),ROW()-ROW($AK$4)+1,6)))} -> 4 | AL8: Denis Whelan | AM8: 11 | AN8: 0.037256944 | AO8: 24 | AP8: 10 | AQ8: 34 | AS8: {=_xlfn.LET(_xlpm.pts,INDEX(_xlfn.ANCHORARRAY($AT$4),0,6),1+COUNTIF(_xlpm.pts,">"&INDEX(_xlfn.ANCHORARRAY($AT$4),ROW()-ROW($AU$4)+1,6)))} -> 5 | AT8: David Wong | AU8: 11 | AV8: 0.025925926 | AW8: 24 | AX8: 10 | AY8: 34
A9: {=_xlfn.LET(_xlpm.pts,INDEX(_xlfn.ANCHORARRAY($B$4),0,2),1+COUNTIF(_xlpm.pts,">"&INDEX(_xlfn.ANCHORARRAY($B$4),ROW()-ROW($A$4)+1,2)))} -> 6 | B9: Henrik Persson | C9: 198 | E9: {=_xlfn.LET(_xlpm.pts,INDEX(_xlfn.ANCHORARRAY($F$4),0,6),1+COUNTIF(_xlpm.pts,">"&INDEX(_xlfn.ANCHORARRAY($F$4),ROW()-ROW($E$4)+1,6)))} -> 5 | F9: Olly Wright | G9: 12 | H9: 0.011805556 | I9: 23 | J9: 10 | K9: 33 | M9: {=_xlfn.LET(_xlpm.pts,INDEX(_xlfn.ANCHORARRAY($N$4),0,6),1+COUNTIF(_xlpm.pts,">"&INDEX(_xlfn.ANCHORARRAY($N$4),ROW()-ROW($M$4)+1,6)))} -> 1 | N9: Tobi Rosenkranz | O9: 3 | P9: 0.020868056 | Q9: 32 | R9: 5 | S9: 35 | U9: {=_xlfn.LET(_xlpm.pts,INDEX(_xlfn.ANCHORARRAY($V$4),0,6),1+COUNTIF(_xlpm.pts,">"&INDEX(_xlfn.ANCHORARRAY($V$4),ROW()-ROW($U$4)+1,6)))} -> 1 | V9: Tobi Rosenkranz | W9: 4 | X9: 0.017418981 | Y9: 31 | Z9: 5 | AA9: 35 | AC9: {=_xlfn.LET(_xlpm.pts,INDEX(_xlfn.ANCHORARRAY($AD$4),0,6),1+COUNTIF(_xlpm.pts,">"&INDEX(_xlfn.ANCHORARRAY($AD$4),ROW()-ROW($AC$4)+1,6)))} -> 6 | AD9: David Willis | AE9: 13 | AF9: 0.037372685 | AG9: 22 | AH9: 10 | AI9: 32 | AK9: {=_xlfn.LET(_xlpm.pts,INDEX(_xlfn.ANCHORARRAY($AL$4),0,6),1+COUNTIF(_xlpm.pts,">"&INDEX(_xlfn.ANCHORARRAY($AL$4),ROW()-ROW($AK$4)+1,6)))} -> 4 | AL9: Judah Rand | AM9: 1 | AN9: 0.034155093 | AO9: 34 | AP9: 0 | AQ9: 34 | AS9: {=_xlfn.LET(_xlpm.pts,INDEX(_xlfn.ANCHORARRAY($AT$4),0,6),1+COUNTIF(_xlpm.pts,">"&INDEX(_xlfn.ANCHORARRAY($AT$4),ROW()-ROW($AU$4)+1,6)))} -> 5 | AT9: Tom Kennett | AU9: 1 | AV9: 0.0246875 | AW9: 34 | AX9: 0 | AY9: 34
