Workbook
Name CAP_A: Handicaps!$A$7
Name CAP_B: Handicaps!$D$7
Name HDCP_GRP_A1: Handicaps!$A$2
Name HDCP_GRP_A2: Handicaps!$A$3
Name HDCP_GRP_A3: Handicaps!$A$4
Name HDCP_GRP_A4: Handicaps!$A$5
Name HDCP_GRP_B1: Handicaps!$D$2
Name HDCP_GRP_B2: Handicaps!$D$3
Name HDCP_GRP_B3: Handicaps!$D$4
Name HDCP_GRP_B4: Handicaps!$D$5
Name HDCP_V_A1: Handicaps!$B$2
Name HDCP_V_A2: Handicaps!$B$3
Name HDCP_V_A3: Handicaps!$B$4
Name HDCP_V_A4: Handicaps!$B$5
Name HDCP_V_B1: Handicaps!$E$2
Name HDCP_V_B2: Handicaps!$E$3
Name HDCP_V_B3: Handicaps!$E$4
Name HDCP_V_B4: Handicaps!$E$5
Name POINTS_CAP_A: Handicaps!$B$7
Name POINTS_CAP_B: Handicaps!$E$7
Name POINTS_CAP_W: 'Stage Data - W'!$AX$2

Sheet Stage Data - A
B1: Handicap Group | D1: Stage 1 | J1: Stage 2 | P1: Stage 3a | V1: Stage 3b | AB1: Stage 4 | AH1: Stage 5 | AN1: Stage 6 | AT1: Base Points | AU1: Adjusted Points
D2: Position | E2: Time | F2: Points | J2: Position | K2: Time | L2: Points | P2: Position | Q2: Time | R2: Points | V2: Position | W2: Time | X2: Points | AB2: Position | AC2: Time | AD2: Points | AH2: Position | AI2: Time | AJ2: Points | AN2: Position | AO2: Time | AP2: Points
A3: Name | F3: Base | G3: Handicap | H3: Adjusted | L3: Base | M3: Handicap | N3: Adjusted | R3: Base | S3: Handicap | T3: Adjusted | X3: Base | Y3: Handicap | Z3: Adjusted | AD3: Base | AE3: Handicap | AF3: Adjusted | AJ3: Base | AK3: Handicap | AL3: Adjusted | AP3: Base | AQ3: Handicap | AR3: Adjusted
A5: Tom Kennett | B5: 1 | D5: 4 | E5: 0.023726852 | F5: =IF(COUNT(D$5:D$48)=0,"",IF(ISNUMBER(D5),1+POINTS_CAP_A-D5,0)) -> 27 | G5: {=IF(COUNT(D$5:D$48)=0,"", IFERROR(CHOOSE($B5,HDCP_V_A1,HDCP_V_A2,HDCP_V_A3,HDCP_V_A4),0))} -> 0 | H5: =IF(COUNT(D$5:D$48)=0,"",MIN(F5+G5,POINTS_CAP_A)) -> 27 | J5: 2 | K5: 0.019965278 | L5: =IF(COUNT(J$5:J$48)=0,"",IF(ISNUMBER(J5),1+POINTS_CAP_A-J5,0)) -> 29 | M5: {=IF(COUNT(J$5:J$48)=0,"", IFERROR(CHOOSE($B5,HDCP_V_A1,HDCP_V_A2,HDCP_V_A3,HDCP_V_A4),0))} -> 0 | N5: =IF(COUNT(J$5:J$48)=0,"",MIN(L5+M5,POINTS_CAP_A)) -> 29 | P5: 4 | Q5: 0.03037037 | R5: =IF(COUNT(P$5:P$48)=0,"",IF(ISNUMBER(P5),1+POINTS_CAP_A-P5,0)) -> 27 | S5: {=IF(COUNT(P$5:P$48)=0,"", IFERROR(CHOOSE($B5,HDCP_V_A1,HDCP_V_A2,HDCP_V_A3,HDCP_V_A4),0))} -> 0 | T5: =IF(COUNT(P$5:P$48)=0,"",MIN(R5+S5,POINTS_CAP_A)) -> 27 | V5: 3 | W5: 0.020821759 | X5: =IF(COUNT(V$5:V$48)=0,"",IF(ISNUMBER(V5),1+POINTS_CAP_A-V5,0)) -> 28 | Y5: {=IF(COUNT(V$5:V$48)=0,"", IFERROR(CHOOSE($B5,HDCP_V_A1,HDCP_V_A2,HDCP_V_A3,HDCP_V_A4),0))} -> 0 | Z5: =IF(COUNT(V$5:V$48)=0,"",MIN(X5+Y5,POINTS_CAP_A)) -> 28 | AB5: 1 | AC5: 0.041215278 | AD5: =IF(COUNT(AB$5:AB$48)=0,"",IF(ISNUMBER(AB5),1+POINTS_CAP_A-AB5,0)) -> 30 | AE5: {=IF(COUNT(AB$5:AB$48)=0,"", IFERROR(CHOOSE($B5,HDCP_V_A1,HDCP_V_A2,HDCP_V_A3,HDCP_V_A4),0))} -> 0 | AF5: =IF(COUNT(AB$5:AB$48)=0,"",MIN(AD5+AE5,POINTS_CAP_A)) -> 30 | AJ5: =IF(COUNT(AH$5:AH$48)=0,"",IF(ISNUMBER(AH5),1+POINTS_CAP_A-AH5,0)) | AK5: {=IF(COUNT(AH$5:AH$48)=0,"", IFERROR(CHOOSE($B5,HDCP_V_A1,HDCP_V_A2,HDCP_V_A3,HDCP_V_A4),0))} | AL5: =IF(COUNT(AH$5:AH$48)=0,"",MIN(AJ5+AK5,POINTS_CAP_A)) | AP5: =IF(COUNT(AN$5:AN$48)=0,"",IF(ISNUMBER(AN5),1+POINTS_CAP_A-AN5,0)) | AQ5: {=IF(COUNT(AN$5:AN$48)=0,"", IFERROR(CHOOSE($B5,HDCP_V_A1,HDCP_V_A2,HDCP_V_A3,HDCP_V_A4),0))} | AR5: =IF(COUNT(AN$5:AN$48)=0,"",MIN(AP5+AQ5,POINTS_CAP_A)) | AT5: =IF(F5="","",SUM(F5,L5,R5,X5,AD5,AJ5,AP5)) -> 141 | AU5: =IF(H5="","",SUM(H5,N5,T5,Z5,AF5,AL5,AR5)) -> 141
A6: Raif Oz | B6: 1 | D6: 5 | E6: 0.023726852 | F6: =IF(COUNT(D$5:D$48)=0,"",IF(ISNUMBER(D6),1+POINTS_CAP_A-D6,0)) -> 26 | G6: {=IF(COUNT(D$5:D$48)=0,"", IFERROR(CHOOSE($B6,HDCP_V_A1,HDCP_V_A2,HDCP_V_A3,HDCP_V_A4),0))} -> 0 | H6: =IF(COUNT(D$5:D$48)=0,"",MIN(F6+G6,POINTS_CAP_A)) -> 26 | J6: 1 | K6: 0.019965278 | L6: =IF(COUNT(J$5:J$48)=0,"",IF(ISNUMBER(J6),1+POINTS_CAP_A-J6,0)) -> 30 | M6: {=IF(COUNT(J$5:J$48)=0,"", IFERROR(CHOOSE($B6,HDCP_V_A1,HDCP_V_A2,HDCP_V_A3,HDCP_V_A4),0))} -> 0 | N6: =IF(COUNT(J$5:J$48)=0,"",MIN(L6+M6,POINTS_CAP_A)) -> 30 | P6: 3 | Q6: 0.030173611 | R6: =IF(COUNT(P$5:P$48)=0,"",IF(ISNUMBER(P6),1+POINTS_CAP_A-P6,0)) -> 28 | S6: {=IF(COUNT(P$5:P$48)=0,"", IFERROR(CHOOSE($B6,HDCP_V_A1,HDCP_V_A2,HDCP_V_A3,HDCP_V_A4),0))} -> 0 | T6: =IF(COUNT(P$5:P$48)=0,"",MIN(R6+S6,POINTS_CAP_A)) -> 28 | V6: 11 | W6: 0.021666667 | X6: =IF(COUNT(V$5:V$48)=0,"",IF(ISNUMBER(V6),1+POINTS_CAP_A-V6,0)) -> 20 | Y6: {=IF(COUNT(V$5:V$48)=0,"", IFERROR(CHOOSE($B6,HDCP_V_A1,HDCP_V_A2,HDCP_V_A3,HDCP_V_A4),0))} -> 0 | Z6: =IF(COUNT(V$5:V$48)=0,"",MIN(X6+Y6,POINTS_CAP_A)) -> 20 | AB6: 6 | AC6: 0.042615741 | AD6: =IF(COUNT(AB$5:AB$48)=0,"",IF(ISNUMBER(AB6),1+POINTS_CAP_A-AB6,0)) -> 25 | AE6: {=IF(COUNT(AB$5:AB$48)=0,"", IFERROR(CHOOSE($B6,HDCP_V_A1,HDCP_V_A2,HDCP_V_A3,HDCP_V_A4),0))} -> 0 | AF6: =IF(COUNT(AB$5:AB$48)=0,"",MIN(AD6+AE6,POINTS_CAP_A)) -> 25 | AJ6: =IF(COUNT(AH$5:AH$48)=0,"",IF(ISNUMBER(AH6),1+POINTS_CAP_A-AH6,0)) | AK6: {=IF(COUNT(AH$5:AH$48)=0,"", IFERROR(CHOOSE($B6,HDCP_V_A1,HDCP_V_A2,HDCP_V_A3,HDCP_V_A4),0))} | AL6: =IF(COUNT(AH$5:AH$48)=0,"",MIN(AJ6+AK6,POINTS_CAP_A)) | AP6: =IF(COUNT(AN$5:AN$48)=0,"",IF(ISNUMBER(AN6),1+POINTS_CAP_A-AN6,0)) | AQ6: {=IF(COUNT(AN$5:AN$48)=0,"", IFERROR(CHOOSE($B6,HDCP_V_A1,HDCP_V_A2,HDCP_V_A3,HDCP_V_A4),0))} | AR6: =IF(COUNT(AN$5:AN$48)=0,"",MIN(AP6+AQ6,POINTS_CAP_A)) | AT6: =IF(F6="","",SUM(F6,L6,R6,X6,AD6,AJ6,AP6)) -> 129 | AU6: =IF(H6="","",SUM(H6,N6,T6,Z6,AF6,AL6,AR6)) -> 129
A7: Seb Ashton | B7: 1 | D7: 2 | E7: 0.023726852 | F7: =IF(COUNT(D$5:D$48)=0,"",IF(ISNUMBER(D7),1+POINTS_CAP_A-D7,0)) -> 29 | G7: {=IF(COUNT(D$5:D$48)=0,"", IFERROR(CHOOSE($B7,HDCP_V_A1,HDCP_V_A2,HDCP_V_A3,HDCP_V_A4),0))} -> 0 | H7: =IF(COUNT(D$5:D$48)=0,"",MIN(F7+G7,POINTS_CAP_A)) -> 29 | J7: 4 | K7: 0.019976852 | L7: =IF(COUNT(J$5:J$48)=0,"",IF(ISNUMBER(J7),1+POINTS_CAP_A-J7,0)) -> 27 | M7: {=IF(COUNT(J$5:J$48)=0,"", IFERROR(CHOOSE($B7,HDCP_V_A1,HDCP_V_A2,HDCP_V_A3,HDCP_V_A4),0))} -> 0 | N7: =IF(COUNT(J$5:J$48)=0,"",MIN(L7+M7,POINTS_CAP_A)) -> 27 | P7: 2 | Q7: 0.029606481 | R7: =IF(COUNT(P$5:P$48)=0,"",IF(ISNUMBER(P7),1+POINTS_CAP_A-P7,0)) -> 29 | S7: {=IF(COUNT(P$5:P$48)=0,"", IFERROR(CHOOSE($B7,HDCP_V_A1,HDCP_V_A2,HDCP_V_A3,HDCP_V_A4),0))} -> 0 | T7: =IF(COUNT(P$5:P$48)=0,"",MIN(R7+S7,POINTS_CAP_A)) -> 29 | V7: 5 | W7: 0.02125 | X7: =IF(COUNT(V$5:V$48)=0,"",IF(ISNUMBER(V7),1+POINTS_CAP_A-V7,0)) -> 26 | Y7: {=IF(COUNT(V$5:V$48)=0,"", IFERROR(CHOOSE($B7,HDCP_V_A1,HDCP_V_A2,HDCP_V_A3,HDCP_V_A4),0))} -> 0 | Z7: =IF(COUNT(V$5:V$48)=0,"",MIN(X7+Y7,POINTS_CAP_A)) -> 26 | AB7: 4 | AC7: 0.041921296 | AD7: =IF(COUNT(AB$5:AB$48)=0,"",IF(ISNUMBER(AB7),1+POINTS_CAP_A-AB7,0)) -> 27 | AE7: {=IF(COUNT(AB$5:AB$48)=0,"", IFERROR(CHOOSE($B7,HDCP_V_A1,HDCP_V_A2,HDCP_V_A3,HDCP_V_A4),0))} -> 0 | AF7: =IF(COUNT(AB$5:AB$48)=0,"",MIN(AD7+AE7,POINTS_CAP_A)) -> 27 | AJ7: =IF(COUNT(AH$5:AH$48)=0,"",IF(ISNUMBER(AH7),1+POINTS_CAP_A-AH7,0)) | AK7: {=IF(COUNT(AH$5:AH$48)=0,"", IFERROR(CHOOSE($B7,HDCP_V_A1,HDCP_V_A2,HDCP_V_A3,HDCP_V_A4),0))} | AL7: =IF(COUNT(AH$5:AH$48)=0,"",MIN(AJ7+AK7,POINTS_CAP_A)) | AP7: =IF(COUNT(AN$5:AN$48)=0,"",IF(ISNUMBER(AN7),1+POINTS_CAP_A-AN7,0)) | AQ7: {=IF(COUNT(AN$5:AN$48)=0,"", IFERROR(CHOOSE($B7,HDCP_V_A1,HDCP_V_A2,HDCP_V_A3,HDCP_V_A4),0))} | AR7: =IF(COUNT(AN$5:AN$48)=0,"",MIN(AP7+AQ7,POINTS_CAP_A)) | AT7: =IF(F7="","",SUM(F7,L7,R7,X7,AD7,AJ7,AP7)) -> 138 | AU7: =IF(H7="","",SUM(H7,N7,T7,Z7,AF7,AL7,AR7)) -> 138
A8: Conor Walsh | B8: 1 | D8: 10 | E8: 0.024282407 | F8: =IF(COUNT(D$5:D$48)=0,"",IF(ISNUMBER(D8),1+POINTS_CAP_A-D8,0)) -> 21 | G8: {=IF(COUNT(D$5:D$48)=0,"", IFERROR(CHOOSE($B8,HDCP_V_A1,HDCP_V_A2,HDCP_V_A3,HDCP_V_A4),0))} -> 0 | H8: =IF(COUNT(D$5:D$48)=0,"",MIN(F8+G8,POINTS_CAP_A)) -> 21 | J8: 27 | K8: 0.024537037 | L8: =IF(COUNT(J$5:J$48)=0,"",IF(ISNUMBER(J8),1+POINTS_CAP_A-J8,0)) -> 4 | M8: {=IF(COUNT(J$5:J$48)=0,"", IFERROR(CHOOSE($B8,HDCP_V_A1,HDCP_V_A2,HDCP_V_A3,HDCP_V_A4),0))} -> 0 | N8: =IF(COUNT(J$5:J$48)=0,"",MIN(L8+M8,POINTS_CAP_A)) -> 4 | P8: 10 | Q8: 0.031921296 | R8: =IF(COUNT(P$5:P$48)=0,"",IF(ISNUMBER(P8),1+POINTS_CAP_A-P8,0)) -> 21 | S8: {=IF(COUNT(P$5:P$48)=0,"", IFERROR(CHOOSE($B8,HDCP_V_A1,HDCP_V_A2,HDCP_V_A3,HDCP_V_A4),0))} -> 0 | T8: =IF(COUNT(P$5:P$48)=0,"",MIN(R8+S8,POINTS_CAP_A)) -> 21 | V8: 13 | W8: 0.021863426 | X8: =IF(COUNT(V$5:V$48)=0,"",IF(ISNUMBER(V8),1+POINTS_CAP_A-V8,0)) -> 18 | Y8: {=IF(COUNT(V$5:V$48)=0,"", IFERROR(CHOOSE($B8,HDCP_V_A1,HDCP_V_A2,HDCP_V_A3,HDCP_V_A4),0))} -> 0 | Z8: =IF(COUNT(V$5:V$48)=0,"",MIN(X8+Y8,POINTS_CAP_A)) -> 18 | AB8: 7 | AC8: 0.043240741 | AD8: =IF(COUNT(AB$5:AB$48)=0,"",IF(ISNUMBER(AB8),1+POINTS_CAP_A-AB8,0)) -> 24 | AE8: {=IF(COUNT(AB$5:AB$48)=0,"", IFERROR(CHOOSE($B8,HDCP_V_A1,HDCP_V_A2,HDCP_V_A3,HDCP_V_A4),0))} -> 0 | AF8: =IF(COUNT(AB$5:AB$48)=0,"",MIN(AD8+AE8,POINTS_CAP_A)) -> 24 | AJ8: =IF(COUNT(AH$5:AH$48)=0,"",IF(ISNUMBER(AH8),1+POINTS_CAP_A-AH8,0)) | AK8: {=IF(COUNT(AH$5:AH$48)=0,"", IFERROR(CHOOSE($B8,HDCP_V_A1,HDCP_V_A2,HDCP_V_A3,HDCP_V_A4),0))} | AL8: =IF(COUNT(AH$5:AH$48)=0,"",MIN(AJ8+AK8,POINTS_CAP_A)) | AP8: =IF(COUNT(AN$5:AN$48)=0,"",IF(ISNUMBER(AN8),1+POINTS_CAP_A-AN8,0)) | AQ8: {=IF(COUNT(AN$5:AN$48)=0,"", IFERROR(CHOOSE($B8,HDCP_V_A1,HDCP_V_A2,HDCP_V_A3,HDCP_V_A4),0))} | AR8: =IF(COUNT(AN$5:AN$48)=0,"",MIN(AP8+AQ8,POINTS_CAP_A)) | AT8: =IF(F8="","",SUM(F8,L8,R8,X8,AD8,AJ8,AP8)) -> 88 | AU8: =IF(H8="","",SUM(H8,N8,T8,Z8,AF8,AL8,AR8)) -> 88
A9: Judah Rand | B9: 1 | D9: 1 | E9: 0.023715278 | F9: =IF(COUNT(D$5:D$48)=0,"",IF(ISNUMBER(D9),1+POINTS_CAP_A-D9,0)) -> 30 | G9: {=IF(COUNT(D$5:D$48)=0,"", IFERROR(CHOOSE($B9,HDCP_V_A1,HDCP_V_A2,HDCP_V_A3,HDCP_V_A4),0))} -> 0 | H9: =IF(COUNT(D$5:D$48)=0,"",MIN(F9+G9,POINTS_CAP_A)) -> 30 | J9: 3 | K9: 0.019976852 | L9: =IF(COUNT(J$5:J$48)=0,"",IF(ISNUMBER(J9),1+POINTS_CAP_A-J9,0)) -> 28 | M9: {=IF(COUNT(J$5:J$48)=0,"", IFERROR(CHOOSE($B9,HDCP_V_A1,HDCP_V_A2,HDCP_V_A3,HDCP_V_A4),0))} -> 0 | N9: =IF(COUNT(J$5:J$48)=0,"",MIN(L9+M9,POINTS_CAP_A)) -> 28 | P9: 1 | Q9: 0.029606481 | R9: =IF(COUNT(P$5:P$48)=0,"",IF(ISNUMBER(P9),1+POINTS_CAP_A-P9,0)) -> 30 | S9: {=IF(COUNT(P$5:P$48)=0,"", IFERROR(CHOOSE($B9,HDCP_V_A1,HDCP_V_A2,HDCP_V_A3,HDCP_V_A4),0))} -> 0 | T9: =IF(COUNT(P$5:P$48)=0,"",MIN(R9+S9,POINTS_CAP_A)) -> 30 | V9: 1 | W9: 0.020729167 | X9: =IF(COUNT(V$5:V$48)=0,"",IF(ISNUMBER(V9),1+POINTS_CAP_A-V9,0)) -> 30 | Y9: {=IF(COUNT(V$5:V$48)=0,"", IFERROR(CHOOSE($B9,HDCP_V_A1,HDCP_V_A2,HDCP_V_A3,HDCP_V_A4),0))} -> 0 | Z9: =IF(COUNT(V$5:V$48)=0,"",MIN(X9+Y9,POINTS_CAP_A)) -> 30 | AB9: 2 | AC9: 0.041724537 | AD9: =IF(COUNT(AB$5:AB$48)=0,"",IF(ISNUMBER(AB9),1+POINTS_CAP_A-AB9,0)) -> 29 | AE9: {=IF(COUNT(AB$5:AB$48)=0,"", IFERROR(CHOOSE($B9,HDCP_V_A1,HDCP_V_A2,HDCP_V_A3,HDCP_V_A4),0))} -> 0 | AF9: =IF(COUNT(AB$5:AB$48)=0,"",MIN(AD9+AE9,POINTS_CAP_A)) -> 29 | AJ9: =IF(COUNT(AH$5:AH$48)=0,"",IF(ISNUMBER(AH9),1+POINTS_CAP_A-AH9,0)) | AK9: {=IF(COUNT(AH$5:AH$48)=0,"", IFERROR(CHOOSE($B9,HDCP_V_A1,HDCP_V_A2,HDCP_V_A3,HDCP_V_A4),0))} | AL9: =IF(COUNT(AH$5:AH$48)=0,"",MIN(AJ9+AK9,POINTS_CAP_A)) | AP9: =IF(COUNT(AN$5:AN$48)=0,"",IF(ISNUMBER(AN9),1+POINTS_CAP_A-AN9,0)) | AQ9: {=IF(COUNT(AN$5:AN$48)=0,"", IFERROR(CHOOSE($B9,HDCP_V_A1,HDCP_V_A2,HDCP_V_A3,HDCP_V_A4),0))} | AR9: =IF(COUNT(AN$5:AN$48)=0,"",MIN(AP9+AQ9,POINTS_CAP_A)) | AT9: =IF(F9="","",SUM(F9,L9,R9,X9,AD9,AJ9,AP9)) -> 147 | AU9: =IF(H9="","",SUM(H9,N9,T9,Z9,AF9,AL9,AR9)) -> 147
A10: Jonny Bodey | B10: 2 | D10: 13 | E10: 0.0246875 | F10: =IF(COUNT(D$5:D$48)=0,"",IF(ISNUMBER(D10),1+POINTS_CAP_A-D10,0)) -> 18 | G10: {=IF(COUNT(D$5:D$48)=0,"", IFERROR(CHOOSE($B10,HDCP_V_A1,HDCP_V_A2,HDCP_V_A3,HDCP_V_A4),0))} -> 6 | H10: =IF(COUNT(D$5:D$48)=0,"",MIN(F10+G10,POINTS_CAP_A)) -> 24 | J10: 12 | K10: 0.020335648 | L10: =IF(COUNT(J$5:J$48)=0,"",IF(ISNUMBER(J10),1+POINTS_CAP_A-J10,0)) -> 19 | M10: {=IF(COUNT(J$5:J$48)=0,"", IFERROR(CHOOSE($B10,HDCP_V_A1,HDCP_V_A2,HDCP_V_A3,HDCP_V_A4),0))} -> 6 | N10: =IF(COUNT(J$5:J$48)=0,"",MIN(L10+M10,POINTS_CAP_A)) -> 25 | P10: 11 | Q10: 0.032094907 | R10: =IF(COUNT(P$5:P$48)=0,"",IF(ISNUMBER(P10),1+POINTS_CAP_A-P10,0)) -> 20 | S10: {=IF(COUNT(P$5:P$48)=0,"", IFERROR(CHOOSE($B10,HDCP_V_A1,HDCP_V_A2,HDCP_V_A3,HDCP_V_A4),0))} -> 6 | T10: =IF(COUNT(P$5:P$48)=0,"",MIN(R10+S10,POINTS_CAP_A)) -> 26 | V10: 19 | W10: 0.0225 | X10: =IF(COUNT(V$5:V$48)=0,"",IF(ISNUMBER(V10),1+POINTS_CAP_A-V10,0)) -> 12 | Y10: {=IF(COUNT(V$5:V$48)=0,"", IFERROR(CHOOSE($B10,HDCP_V_A1,HDCP_V_A2,HDCP_V_A3,HDCP_V_A4),0))} -> 6 | Z10: =IF(COUNT(V$5:V$48)=0,"",MIN(X10+Y10,POINTS_CAP_A)) -> 18 | AB10: 10 | AC10: 0.044467593 | AD10: =IF(COUNT(AB$5:AB$48)=0,"",IF(ISNUMBER(AB10),1+POINTS_CAP_A-AB10,0)) -> 21 | AE10: {=IF(COUNT(AB$5:AB$48)=0,"", IFERROR(CHOOSE($B10,HDCP_V_A1,HDCP_V_A2,HDCP_V_A3,HDCP_V_A4),0))} -> 6 | AF10: =IF(COUNT(AB$5:AB$48)=0,"",MIN(AD10+AE10,POINTS_CAP_A)) -> 27 | AJ10: =IF(COUNT(AH$5:AH$48)=0,"",IF(ISNUMBER(AH10),1+POINTS_CAP_A-AH10,0)) | AK10: {=IF(COUNT(AH$5:AH$48)=0,"", IFERROR(CHOOSE($B10,HDCP_V_A1,HDCP_V_A2,HDCP_V_A3,HDCP_V_A4),0))} | AL10: =IF(COUNT(AH$5:AH$48)=0,"",MIN(AJ10+AK10,POINTS_CAP_A)) | AP10: =IF(COUNT(AN$5:AN$48)=0,"",IF(ISNUMBER(AN10),1+POINTS_CAP_A-AN10,0)) | AQ10: {=IF(COUNT(AN$5:AN$48)=0,"", IFERROR(CHOOSE($B10,HDCP_V_A1,HDCP_V_A2,HDCP_V_A3,HDCP_V_A4),0))} | AR10: =IF(COUNT(AN$5:AN$48)=0,"",MIN(AP10+AQ10,POINTS_CAP_A)) | AT10: =IF(F10="","",SUM(F10,L10,R10,X10,AD10,AJ10,AP10)) -> 90 | AU10: =IF(H10="","",SUM(H10,N10,T10,Z10,AF10,AL10,AR10)) -> 120
A11: Neal Beauchamp | B11: 2 | D11: 11 | E11: 0.02431713 | F11: =IF(COUNT(D$5:D$48)=0,"",IF(ISNUMBER(D11),1+POINTS_CAP_A-D11,0)) -> 20 | G11: {=IF(COUNT(D$5:D$48)=0,"", IFERROR(CHOOSE($B11,HDCP_V_A1,HDCP_V_A2,HDCP_V_A3,HDCP_V_A4),0))} -> 6 | H11: =IF(COUNT(D$5:D$48)=0,"",MIN(F11+G11,POINTS_CAP_A)) -> 26 | J11: 10 | K11: 0.020300926 | L11: =IF(COUNT(J$5:J$48)=0,"",IF(ISNUMBER(J11),1+POINTS_CAP_A-J11,0)) -> 21 | M11: {=IF(COUNT(J$5:J$48)=0,"", IFERROR(CHOOSE($B11,HDCP_V_A1,HDCP_V_A2,HDCP_V_A3,HDCP_V_A4),0))} -> 6 | N11: =IF(COUNT(J$5:J$48)=0,"",MIN(L11+M11,POINTS_CAP_A)) -> 27 | P11: 7 | Q11: 0.031203704 | R11: =IF(COUNT(P$5:P$48)=0,"",IF(ISNUMBER(P11),1+POINTS_CAP_A-P11,0)) -> 24 | S11: {=IF(COUNT(P$5:P$48)=0,"", IFERROR(CHOOSE($B11,HDCP_V_A1,HDCP_V_A2,HDCP_V_A3,HDCP_V_A4),0))} -> 6 | T11: =IF(COUNT(P$5:P$48)=0,"",MIN(R11+S11,POINTS_CAP_A)) -> 30 | V11: 8 | W11: 0.035358796 | X11: =IF(COUNT(V$5:V$48)=0,"",IF(ISNUMBER(V11),1+POINTS_CAP_A-V11,0)) -> 23 | Y11: {=IF(COUNT(V$5:V$48)=0,"", IFERROR(CHOOSE($B11,HDCP_V_A1,HDCP_V_A2,HDCP_V_A3,HDCP_V_A4),0))} -> 6 | Z11: =IF(COUNT(V$5:V$48)=0,"",MIN(X11+Y11,POINTS_CAP_A)) -> 29 | AB11: 11 | AC11: 0.04462963 | AD11: =IF(COUNT(AB$5:AB$48)=0,"",IF(ISNUMBER(AB11),1+POINTS_CAP_A-AB11,0)) -> 20 | AE11: {=IF(COUNT(AB$5:AB$48)=0,"", IFERROR(CHOOSE($B11,HDCP_V_A1,HDCP_V_A2,HDCP_V_A3,HDCP_V_A4),0))} -> 6 | AF11: =IF(COUNT(AB$5:AB$48)=0,"",MIN(AD11+AE11,POINTS_CAP_A)) -> 26 | AJ11: =IF(COUNT(AH$5:AH$48)=0,"",IF(ISNUMBER(AH11),1+POINTS_CAP_A-AH11,0)) | AK11: {=IF(COUNT(AH$5:AH$48)=0,"", IFERROR(CHOOSE($B11,HDCP_V_A1,HDCP_V_A2,HDCP_V_A3,HDCP_V_A4),0))} | AL11: =IF(COUNT(AH$5:AH$48)=0,"",MIN(AJ11+AK11,POINTS_CAP_A)) | AP11: =IF(COUNT(AN$5:AN$48)=0,"",IF(ISNUMBER(AN11),1+POINTS_CAP_A-AN11,0)) | AQ11: {=IF(COUNT(AN$5:AN$48)=0,"", IFERROR(CHOOSE($B11,HDCP_V_A1,HDCP_V_A2,HDCP_V_A3,HDCP_V_A4),0))} | AR11: =IF(COUNT(AN$5:AN$48)=0,"",MIN(AP11+AQ11,POINTS_CAP_A)) | AT11: =IF(F11="","",SUM(F11,L11,R11,X11,AD11,AJ11,AP11)) -> 108 | AU11: =IF(H11="","",SUM(H11,N11,T11,Z11,AF11,AL11,AR11)) -> 138
A12: Henrik Persson | B12: 2 | D12: 6 | E12: 0.023831019 | F12: =IF(COUNT(D$5:D$48)=0,"",IF(ISNUMBER(D12),1+POINTS_CAP_A-D12,0)) -> 25 | G12: {=IF(COUNT(D$5:D$48)=0,"", IFERROR(CHOOSE($B12,HDCP_V_A1,HDCP_V_A2,HDCP_V_A3,HDCP_V_A4),0))} -> 6 | H12: =IF(COUNT(D$5:D$48)=0,"",MIN(F12+G12,POINTS_CAP_A)) -> 30 | J12: 6 | K12: 0.020104167 | L12: =IF(COUNT(J$5:J$48)=0,"",IF(ISNUMBER(J12),1+POINTS_CAP_A-J12,0)) -> 25 | M12: {=IF(COUNT(J$5:J$48)=0,"", IFERROR(CHOOSE($B12,HDCP_V_A1,HDCP_V_A2,HDCP_V_A3,HDCP_V_A4),0))} -> 6 | N12: =IF(COUNT(J$5:J$48)=0,"",MIN(L12+M12,POINTS_CAP_A)) -> 30 | P12: 5 | Q12: 0.030636574 | R12: =IF(COUNT(P$5:P$48)=0,"",IF(ISNUMBER(P12),1+POINTS_CAP_A-P12,0)) -> 26 | S12: {=IF(COUNT(P$5:P$48)=0,"", IFERROR(CHOOSE($B12,HDCP_V_A1,HDCP_V_A2,HDCP_V_A3,HDCP_V_A4),0))} -> 6 | T12: =IF(COUNT(P$5:P$48)=0,"",MIN(R12+S12,POINTS_CAP_A)) -> 30 | V12: 6 | W12: 0.021284722 | X12: =IF(COUNT(V$5:V$48)=0,"",IF(ISNUMBER(V12),1+POINTS_CAP_A-V12,0)) -> 25 | Y12: {=IF(COUNT(V$5:V$48)=0,"", IFERROR(CHOOSE($B12,HDCP_V_A1,HDCP_V_A2,HDCP_V_A3,HDCP_V_A4),0))} -> 6 | Z12: =IF(COUNT(V$5:V$48)=0,"",MIN(X12+Y12,POINTS_CAP_A)) -> 30 | AB12: 5 | AC12: 0.042048611 | AD12: =IF(COUNT(AB$5:AB$48)=0,"",IF(ISNUMBER(AB12),1+POINTS_CAP_A-AB12,0)) -> 26 | AE12: {=IF(COUNT(AB$5:AB$48)=0,"", IFERROR(CHOOSE($B12,HDCP_V_A1,HDCP_V_A2,HDCP_V_A3,HDCP_V_A4),0))} -> 6 | AF12: =IF(COUNT(AB$5:AB$48)=0,"",MIN(AD12+AE12,POINTS_CAP_A)) -> 30 | AJ12: =IF(COUNT(AH$5:AH$48)=0,"",IF(ISNUMBER(AH12),1+POINTS_CAP_A-AH12,0)) | AK12: {=IF(COUNT(AH$5:AH$48)=0,"", IFERROR(CHOOSE($B12,HDCP_V_A1,HDCP_V_A2,HDCP_V_A3,HDCP_V_A4),0))} | AL12: =IF(COUNT(AH$5:AH$48)=0,"",MIN(AJ12+AK12,POINTS_CAP_A)) | AP12: =IF(COUNT(AN$5:AN$48)=0,"",IF(ISNUMBER(AN12),1+POINTS_CAP_A-AN12,0)) | AQ12: {=IF(COUNT(AN$5:AN$48)=0,"", IFERROR(CHOOSE($B12,HDCP_V_A1,HDCP_V_A2,HDCP_V_A3,HDCP_V_A4),0))} | AR12: =IF(COUNT(AN$5:AN$48)=0,"",MIN(AP12+AQ12,POINTS_CAP_A)) | AT12: =IF(F12="","",SUM(F12,L12,R12,X12,AD12,AJ12,AP12)) -> 127 | AU12: =IF(H12="","",SUM(H12,N12,T12,Z12,AF12,AL12,AR12)) -> 150
A13: Neil Grunshaw | B13: 2 | D13: 9 | E13: 0.024016204 | F13: =IF(COUNT(D$5:D$48)=0,"",IF(ISNUMBER(D13),1+POINTS_CAP_A-D13,0)) -> 22 | G13: {=IF(COUNT(D$5:D$48)=0,"", IFERROR(CHOOSE($B13,HDCP_V_A1,HDCP_V_A2,HDCP_V_A3,HDCP_V_A4),0))} -> 6 | H13: =IF(COUNT(D$5:D$48)=0,"",MIN(F13+G13,POINTS_CAP_A)) -> 28 | J13: 7 | K13: 0.020104167 | L13: =IF(COUNT(J$5:J$48)=0,"",IF(ISNUMBER(J13),1+POINTS_CAP_A-J13,0)) -> 24 | M13: {=IF(COUNT(J$5:J$48)=0,"", IFERROR(CHOOSE($B13,HDCP_V_A1,HDCP_V_A2,HDCP_V_A3,HDCP_V_A4),0))} -> 6 | N13: =IF(COUNT(J$5:J$48)=0,"",MIN(L13+M13,POINTS_CAP_A)) -> 30 | P13: 13 | Q13: 0.032349537 | R13: =IF(COUNT(P$5:P$48)=0,"",IF(ISNUMBER(P13),1+POINTS_CAP_A-P13,0)) -> 18 | S13: {=IF(COUNT(P$5:P$48)=0,"", IFERROR(CHOOSE($B13,HDCP_V_A1,HDCP_V_A2,HDCP_V_A3,HDCP_V_A4),0))} -> 6 | T13: =IF(COUNT(P$5:P$48)=0,"",MIN(R13+S13,POINTS_CAP_A)) -> 24 | V13: 4 | W13: 0.020914352 | X13: =IF(COUNT(V$5:V$48)=0,"",IF(ISNUMBER(V13),1+POINTS_CAP_A-V13,0)) -> 27 | Y13: {=IF(COUNT(V$5:V$48)=0,"", IFERROR(CHOOSE($B13,HDCP_V_A1,HDCP_V_A2,HDCP_V_A3,HDCP_V_A4),0))} -> 6 | Z13: =IF(COUNT(V$5:V$48)=0,"",MIN(X13+Y13,POINTS_CAP_A)) -> 30 | AB13: 8 | AC13: 0.043252315 | AD13: =IF(COUNT(AB$5:AB$48)=0,"",IF(ISNUMBER(AB13),1+POINTS_CAP_A-AB13,0)) -> 23 | AE13: {=IF(COUNT(AB$5:AB$48)=0,"", IFERROR(CHOOSE($B13,HDCP_V_A1,HDCP_V_A2,HDCP_V_A3,HDCP_V_A4),0))} -> 6 | AF13: =IF(COUNT(AB$5:AB$48)=0,"",MIN(AD13+AE13,POINTS_CAP_A)) -> 29 | AJ13: =IF(COUNT(AH$5:AH$48)=0,"",IF(ISNUMBER(AH13),1+POINTS_CAP_A-AH13,0)) | AK13: {=IF(COUNT(AH$5:AH$48)=0,"", IFERROR(CHOOSE($B13,HDCP_V_A1,HDCP_V_A2,HDCP_V_A3,HDCP_V_A4),0))} | AL13: =IF(COUNT(AH$5:AH$48)=0,"",MIN(AJ13+AK13,POINTS_CAP_A)) | AP13: =IF(COUNT(AN$5:AN$48)=0,"",IF(ISNUMBER(AN13),1+POINTS_CAP_A-AN13,0)) | AQ13: {=IF(COUNT(AN$5:AN$48)=0,"", IFERROR(CHOOSE($B13,HDCP_V_A1,HDCP_V_A2,HDCP_V_A3,HDCP_V_A4),0))} | AR13: =IF(COUNT(AN$5:AN$48)=0,"",MIN(AP13+AQ13,POINTS_CAP_A)) | AT13: =IF(F13="","",SUM(F13,L13,R13,X13,AD13,AJ13,AP13)) -> 114 | AU13: =IF(H13="","",SUM(H13,N13,T13,Z13,AF13,AL13,AR13)) -> 141
A14: Tom Herbert | B14: 2 | D14: 8 | E14: 0.023912037 | F14: =IF(COUNT(D$5:D$48)=0,"",IF(ISNUMBER(D14),1+POINTS_CAP_A-D14,0)) -> 23 | G14: {=IF(COUNT(D$5:D$48)=0,"", IFERROR(CHOOSE($B14,HDCP_V_A1,HDCP_V_A2,HDCP_V_A3,HDCP_V_A4),0))} -> 6 | H14: =IF(COUNT(D$5:D$48)=0,"",MIN(F14+G14,POINTS_CAP_A)) -> 29 | J14: 9 | K14: 0.020277778 | L14: =IF(COUNT(J$5:J$48)=0,"",IF(ISNUMBER(J14),1+POINTS_CAP_A-J14,0)) -> 22 | M14: {=IF(COUNT(J$5:J$48)=0,"", IFERROR(CHOOSE($B14,HDCP_V_A1,HDCP_V_A2,HDCP_V_A3,HDCP_V_A4),0))} -> 6 | N14: =IF(COUNT(J$5:J$48)=0,"",MIN(L14+M14,POINTS_CAP_A)) -> 28 | P14: 9 | Q14: 0.031863426 | R14: =IF(COUNT(P$5:P$48)=0,"",IF(ISNUMBER(P14),1+POINTS_CAP_A-P14,0)) -> 22 | S14: {=IF(COUNT(P$5:P$48)=0,"", IFERROR(CHOOSE($B14,HDCP_V_A1,HDCP_V_A2,HDCP_V_A3,HDCP_V_A4),0))} -> 6 | T14: =IF(COUNT(P$5:P$48)=0,"",MIN(R14+S14,POINTS_CAP_A)) -> 28 | V14: 7 | W14: 0.021435185 | X14: =IF(COUNT(V$5:V$48)=0,"",IF(ISNUMBER(V14),1+POINTS_CAP_A-V14,0)) -> 24 | Y14: {=IF(COUNT(V$5:V$48)=0,"", IFERROR(CHOOSE($B14,HDCP_V_A1,HDCP_V_A2,HDCP_V_A3,HDCP_V_A4),0))} -> 6 | Z14: =IF(COUNT(V$5:V$48)=0,"",MIN(X14+Y14,POINTS_CAP_A)) -> 30 | AB14: 9 | AC14: 0.044155093 | AD14: =IF(COUNT(AB$5:AB$48)=0,"",IF(ISNUMBER(AB14),1+POINTS_CAP_A-AB14,0)) -> 22 | AE14: {=IF(COUNT(AB$5:AB$48)=0,"", IFERROR(CHOOSE($B14,HDCP_V_A1,HDCP_V_A2,HDCP_V_A3,HDCP_V_A4),0))} -> 6 | AF14: =IF(COUNT(AB$5:AB$48)=0,"",MIN(AD14+AE14,POINTS_CAP_A)) -> 28 | AJ14: =IF(COUNT(AH$5:AH$48)=0,"",IF(ISNUMBER(AH14),1+POINTS_CAP_A-AH14,0)) | AK14: {=IF(COUNT(AH$5:AH$48)=0,"", IFERROR(CHOOSE($B14,HDCP_V_A1,HDCP_V_A2,HDCP_V_A3,HDCP_V_A4),0))} | AL14: =IF(COUNT(AH$5:AH$48)=0,"",MIN(AJ14+AK14,POINTS_CAP_A)) | AP14: =IF(COUNT(AN$5:AN$48)=0,"",IF(ISNUMBER(AN14),1+POINTS_CAP_A-AN14,0)) | AQ14: {=IF(COUNT(AN$5:AN$48)=0,"", IFERROR(CHOOSE($B14,HDCP_V_A1,HDCP_V_A2,HDCP_V_A3,HDCP_V_A4),0))} | AR14: =IF(COUNT(AN$5:AN$48)=0,"",MIN(AP14+AQ14,POINTS_CAP_A)) | AT14: =IF(F14="","",SUM(F14,L14,R14,X14,AD14,AJ14,AP14)) -> 113 | AU14: =IF(H14="","",SUM(H14,N14,T14,Z14,AF14,AL14,AR14)) -> 143
A15: Denis Whelan | B15: 2 | D15: 12 | E15: 0.02443287 | F15: =IF(COUNT(D$5:D$48)=0,"",IF(ISNUMBER(D15),1+POINTS_CAP_A-D15,0)) -> 19 | G15: {=IF(COUNT(D$5:D$48)=0,"", IFERROR(CHOOSE($B15,HDCP_V_A1,HDCP_V_A2,HDCP_V_A3,HDCP_V_A4),0))} -> 6 | H15: =IF(COUNT(D$5:D$48)=0,"",MIN(F15+G15,POINTS_CAP_A)) -> 25 | J15: 11 | K15: 0.020335648 | L15: =IF(COUNT(J$5:J$48)=0,"",IF(ISNUMBER(J15),1+POINTS_CAP_A-J15,0)) -> 20 | M15: {=IF(COUNT(J$5:J$48)=0,"", IFERROR(CHOOSE($B15,HDCP_V_A1,HDCP_V_A2,HDCP_V_A3,HDCP_V_A4),0))} -> 6 | N15: =IF(COUNT(J$5:J$48)=0,"",MIN(L15+M15,POINTS_CAP_A)) -> 26 | P15: 12 | Q15: 0.032106481 | R15: =IF(COUNT(P$5:P$48)=0,"",IF(ISNUMBER(P15),1+POINTS_CAP_A-P15,0)) -> 19 | S15: {=IF(COUNT(P$5:P$48)=0,"", IFERROR(CHOOSE($B15,HDCP_V_A1,HDCP_V_A2,HDCP_V_A3,HDCP_V_A4),0))} -> 6 | T15: =IF(COUNT(P$5:P$48)=0,"",MIN(R15+S15,POINTS_CAP_A)) -> 25 | V15: 9 | W15: 0.021597222 | X15: =IF(COUNT(V$5:V$48)=0,"",IF(ISNUMBER(V15),1+POINTS_CAP_A-V15,0)) -> 22 | Y15: {=IF(COUNT(V$5:V$48)=0,"", IFERROR(CHOOSE($B15,HDCP_V_A1,HDCP_V_A2,HDCP_V_A3,HDCP_V_A4),0))} -> 6 | Z15: =IF(COUNT(V$5:V$48)=0,"",MIN(X15+Y15,POINTS_CAP_A)) -> 28 | AB15: 13 | AC15: 0.045023148 | AD15: =IF(COUNT(AB$5:AB$48)=0,"",IF(ISNUMBER(AB15),1+POINTS_CAP_A-AB15,0)) -> 18 | AE15: {=IF(COUNT(AB$5:AB$48)=0,"", IFERROR(CHOOSE($B15,HDCP_V_A1,HDCP_V_A2,HDCP_V_A3,HDCP_V_A4),0))} -> 6 | AF15: =IF(COUNT(AB$5:AB$48)=0,"",MIN(AD15+AE15,POINTS_CAP_A)) -> 24 | AJ15: =IF(COUNT(AH$5:AH$48)=0,"",IF(ISNUMBER(AH15),1+POINTS_CAP_A-AH15,0)) | AK15: {=IF(COUNT(AH$5:AH$48)=0,"", IFERROR(CHOOSE($B15,HDCP_V_A1,HDCP_V_A2,HDCP_V_A3,HDCP_V_A4),0))} | AL15: =IF(COUNT(AH$5:AH$48)=0,"",MIN(AJ15+AK15,POINTS_CAP_A)) | AP15: =IF(COUNT(AN$5:AN$48)=0,"",IF(ISNUMBER(AN15),1+POINTS_CAP_A-AN15,0)) | AQ15: {=IF(COUNT(AN$5:AN$48)=0,"", IFERROR(CHOOSE($B15,HDCP_V_A1,HDCP_V_A2,HDCP_V_A3,HDCP_V_A4),0))} | AR15: =IF(COUNT(AN$5:AN$48)=0,"",MIN(AP15+AQ15,POINTS_CAP_A)) | AT15: =IF(F15="","",SUM(F15,L15,R15,X15,AD15,AJ15,AP15)) -> 98 | AU15: =IF(H15="","",SUM(H15,N15,T15,Z15,AF15,AL15,AR15)) -> 128
A16: Marcus Jones | B16: 2 | D16: 21 | E16: 0.025358796 | F16: =IF(COUNT(D$5:D$48)=0,"",IF(ISNUMBER(D16),1+POINTS_CAP_A-D16,0)) -> 10 | G16: {=IF(COUNT(D$5:D$48)=0,"", IFERROR(CHOOSE($B16,HDCP_V_A1,HDCP_V_A2,HDCP_V_A3,HDCP_V_A4),0))} -> 6 | H16: =IF(COUNT(D$5:D$48)=0,"",MIN(F16+G16,POINTS_CAP_A)) -> 16 | J16: 26 | K16: 0.024537037 | L16: =IF(COUNT(J$5:J$48)=0,"",IF(ISNUMBER(J16),1+POINTS_CAP_A-J16,0)) -> 5 | M16: {=IF(COUNT(J$5:J$48)=0,"", IFERROR(CHOOSE($B16,HDCP_V_A1,HDCP_V_A2,HDCP_V_A3,HDCP_V_A4),0))} -> 6 | N16: =IF(COUNT(J$5:J$48)=0,"",MIN(L16+M16,POINTS_CAP_A)) -> 11 | P16: 25 | Q16: 0.038819444 | R16: =IF(COUNT(P$5:P$48)=0,"",IF(ISNUMBER(P16),1+POINTS_CAP_A-P16,0)) -> 6 | S16: {=IF(COUNT(P$5:P$48)=0,"", IFERROR(CHOOSE($B16,HDCP_V_A1,HDCP_V_A2,HDCP_V_A3,HDCP_V_A4),0))} -> 6 | T16: =IF(COUNT(P$5:P$48)=0,"",MIN(R16+S16,POINTS_CAP_A)) -> 12 | V16: 27 | W16: 0.026655093 | X16: =IF(COUNT(V$5:V$48)=0,"",IF(ISNUMBER(V16),1+POINTS_CAP_A-V16,0)) -> 4 | Y16: {=IF(COUNT(V$5:V$48)=0,"", IFERROR(CHOOSE($B16,HDCP_V_A1,HDCP_V_A2,HDCP_V_A3,HDCP_V_A4),0))} -> 6 | Z16: =IF(COUNT(V$5:V$48)=0,"",MIN(X16+Y16,POINTS_CAP_A)) -> 10 | AB16: 24 | AC16: 0.049212963 | AD16: =IF(COUNT(AB$5:AB$48)=0,"",IF(ISNUMBER(AB16),1+POINTS_CAP_A-AB16,0)) -> 7 | AE16: {=IF(COUNT(AB$5:AB$48)=0,"", IFERROR(CHOOSE($B16,HDCP_V_A1,HDCP_V_A2,HDCP_V_A3,HDCP_V_A4),0))} -> 6 | AF16: =IF(COUNT(AB$5:AB$48)=0,"",MIN(AD16+AE16,POINTS_CAP_A)) -> 13 | AJ16: =IF(COUNT(AH$5:AH$48)=0,"",IF(ISNUMBER(AH16),1+POINTS_CAP_A-AH16,0)) | AK16: {=IF(COUNT(AH$5:AH$48)=0,"", IFERROR(CHOOSE($B16,HDCP_V_A1,HDCP_V_A2,HDCP_V_A3,HDCP_V_A4),0))} | AL16: =IF(COUNT(AH$5:AH$48)=0,"",MIN(AJ16+AK16,POINTS_CAP_A)) | AP16: =IF(COUNT(AN$5:AN$48)=0,"",IF(ISNUMBER(AN16),1+POINTS_CAP_A-AN16,0)) | AQ16: {=IF(COUNT(AN$5:AN$48)=0,"", IFERROR(CHOOSE($B16,HDCP_V_A1,HDCP_V_A2,HDCP_V_A3,HDCP_V_A4),0))} | AR16: =IF(COUNT(AN$5:AN$48)=0,"",MIN(AP16+AQ16,POINTS_CAP_A)) | AT16: =IF(F16="","",SUM(F16,L16,R16,X16,AD16,AJ16,AP16)) -> 32 | AU16: =IF(H16="","",SUM(H16,N16,T16,Z16,AF16,AL16,AR16)) -> 62
... A31: Richard Turner | B31: 2 | D31: 22 | E31: 0.025509259 | F31: =IF(COUNT(D$5:D$48)=0,"",IF(ISNUMBER(D31),1+POINTS_CAP_A-D31,0)) -> 9 | G31: {=IF(COUNT(D$5:D$48)=0,"", IFERROR(CHOOSE($B31,HDCP_V_A1,HDCP_V_A2,HDCP_V_A3,HDCP_V_A4),0))} -> 6 | H31: =IF(COUNT(D$5:D$48)=0,"",MIN(F31+G31,POINTS_CAP_A)) -> 15 | J31: 24 | K31: 0.022453704 | L31: =IF(COUNT(J$5:J$48)=0,"",IF(ISNUMBER(J31),1+POINTS_CAP_A-J31,0)) -> 7 | M31: {=IF(COUNT(J$5:J$48)=0,"", IFERROR(CHOOSE($B31,HDCP_V_A1,HDCP_V_A2,HDCP_V_A3,HDCP_V_A4),0))} -> 6 | N31: =IF(COUNT(J$5:J$48)=0,"",MIN(L31+M31,POINTS_CAP_A)) -> 13 | P31: 26 | Q31: 0.038819444 | R31: =IF(COUNT(P$5:P$48)=0,"",IF(ISNUMBER(P31),1+POINTS_CAP_A-P31,0)) -> 5 | S31: {=IF(COUNT(P$5:P$48)=0,"", IFERROR(CHOOSE($B31,HDCP_V_A1,HDCP_V_A2,HDCP_V_A3,HDCP_V_A4),0))} -> 6 | T31: =IF(COUNT(P$5:P$48)=0,"",MIN(R31+S31,POINTS_CAP_A)) -> 11 | V31: 26 | W31: 0.026655093 | X31: =IF(COUNT(V$5:V$48)=0,"",IF(ISNUMBER(V31),1+POINTS_CAP_A-V31,0)) -> 5 | Y31: {=IF(COUNT(V$5:V$48)=0,"", IFERROR(CHOOSE($B31,HDCP_V_A1,HDCP_V_A2,HDCP_V_A3,HDCP_V_A4),0))} -> 6 | Z31: =IF(COUNT(V$5:V$48)=0,"",MIN(X31+Y31,POINTS_CAP_A)) -> 11 | AB31: 26 | AC31: 0.049212963 | AD31: =IF(COUNT(AB$5:AB$48)=0,"",IF(ISNUMBER(AB31),1+POINTS_CAP_A-AB31,0)) -> 5 | AE31: {=IF(COUNT(AB$5:AB$48)=0,"", IFERROR(CHOOSE($B31,HDCP_V_A1,HDCP_V_A2,HDCP_V_A3,HDCP_V_A4),0))} -> 6 | AF31: =IF(COUNT(AB$5:AB$48)=0,"",MIN(AD31+AE31,POINTS_CAP_A)) -> 11 | AJ31: =IF(COUNT(AH$5:AH$48)=0,"",IF(ISNUMBER(AH31),1+POINTS_CAP_A-AH31,0)) | AK31: {=IF(COUNT(AH$5:AH$48)=0,"", IFERROR(CHOOSE($B31,HDCP_V_A1,HDCP_V_A2,HDCP_V_A3,HDCP_V_A4),0))} | AL31: =IF(COUNT(AH$5:AH$48)=0,"",MIN(AJ31+AK31,POINTS_CAP_A)) | AP31: =IF(COUNT(AN$5:AN$48)=0,"",IF(ISNUMBER(AN31),1+POINTS_CAP_A-AN31,0)) | AQ31: {=IF(COUNT(AN$5:AN$48)=0,"", IFERROR(CHOOSE($B31,HDCP_V_A1,HDCP_V_A2,HDCP_V_A3,HDCP_V_A4),0))} | AR31: =IF(COUNT(AN$5:AN$48)=0,"",MIN(AP31+AQ31,POINTS_CAP_A)) | AT31: =IF(F31="","",SUM(F31,L31,R31,X31,AD31,AJ31,AP31)) -> 31 | AU31: =IF(H31="","",SUM(H31,N31,T31,Z31,AF31,AL31,AR31)) -> 61
AT32: =IF(F32="","",SUM(F32,L32,R32,X32,AJ32,AP32)) | AU32: =IF(H32="","",SUM(H32,N32,T32,Z32,AL32,AR32))
AT33: =IF(F33="","",SUM(F33,L33,R33,X33,AJ33,AP33)) | AU33: =IF(H33="","",SUM(H33,N33,T33,Z33,AL33,AR33))
AT34: =IF(F34="","",SUM(F34,L34,R34,X34,AJ34,AP34)) | AU34: =IF(H34="","",SUM(H34,N34,T34,Z34,AL34,AR34))
AT35: =IF(F35="","",SUM(F35,L35,R35,X35,AJ35,AP35)) | AU35: =IF(H35="","",SUM(H35,N35,T35,Z35,AL35,AR35))
AT36: =IF(F36="","",SUM(F36,L36,R36,X36,AJ36,AP36)) | AU36: =IF(H36="","",SUM(H36,N36,T36,Z36,AL36,AR36))
AT37: =IF(F37="","",SUM(F37,L37,R37,X37,AJ37,AP37)) | AU37: =IF(H37="","",SUM(H37,N37,T37,Z37,AL37,AR37))
AT38: =IF(F38="","",SUM(F38,L38,R38,X38,AJ38,AP38)) | AU38: =IF(H38="","",SUM(H38,N38,T38,Z38,AL38,AR38))
AT39: =IF(F39="","",SUM(F39,L39,R39,X39,AJ39,AP39)) | AU39: =IF(H39="","",SUM(H39,N39,T39,Z39,AL39,AR39))
AT40: =IF(F40="","",SUM(F40,L40,R40,X40,AJ40,AP40)) | AU40: =IF(H40="","",SUM(H40,N40,T40,Z40,AL40,AR40))
AT41: =IF(F41="","",SUM(F41,L41,R41,X41,AJ41,AP41)) | AU41: =IF(H41="","",SUM(H41,N41,T41,Z41,AL41,AR41))
AT42: =IF(F42="","",SUM(F42,L42,R42,X42,AJ42,AP42)) | AU42: =IF(H42="","",SUM(H42,N42,T42,Z42,AL42,AR42))
AT43: =IF(F43="","",SUM(F43,L43,R43,X43,AJ43,AP43)) | AU43: =IF(H43="","",SUM(H43,N43,T43,Z43,AL43,AR43))
... AT55: =IF(F55="","",SUM(F55,L55,R55,X55,AJ55,AP55)) | AU55: =IF(H55="","",SUM(H55,N55,T55,Z55,AL55,AR55))

Sheet Stage Data - B
B1: Handicap Group | D1: Stage 1 | J1: Stage 2 | P1: Stage 3a | V1: Stage 3b | AB1: Stage 4 | AH1: Stage 5 | AN1: Stage 6 | AT1: Base Points | AU1: Adjusted Points
D2: Position | E2: Time | F2: Points | J2: Position | K2: Time | L2: Points | P2: Position | Q2: Time | R2: Points | V2: Position | W2: Time | X2: Points | AB2: Position | AC2: Time | AD2: Points | AH2: Position | AI2: Time | AJ2: Points | AN2: Position | AO2: Time | AP2: Points
A3: Name | F3: Base | G3: Handicap | H3: Adjusted | L3: Base | M3: Handicap | N3: Adjusted | R3: Base | S3: Handicap | T3: Adjusted | X3: Base | Y3: Handicap | Z3: Adjusted | AD3: Base | AE3: Handicap | AF3: Adjusted | AJ3: Base | AK3: Handicap | AL3: Adjusted | AP3: Base | AQ3: Handicap | AR3: Adjusted
A5: Adam Currie | B5: 1 | D5: 8 | E5: 0.026388889 | F5: =IF(COUNT(D$5:D$48)=0,"",IF(ISNUMBER(D5),1+POINTS_CAP_B-D5,0)) -> 33 | G5: =IF(COUNT(D$5:D$48)=0,"", IFERROR(CHOOSE($B5,HDCP_V_B1,HDCP_V_B2,HDCP_V_B3,HDCP_V_B4),0)) -> 0 | H5: =IF(COUNT(D$5:D$48)=0,"",MIN(F5+G5,POINTS_CAP_B)) -> 33 | J5: 20 | K5: 0.023368056 | L5: =IF(COUNT(J$5:J$48)=0,"",IF(ISNUMBER(J5),1+POINTS_CAP_B-J5,0)) -> 21 | M5: =IF(COUNT(J$5:J$48)=0,"", IFERROR(CHOOSE($B5,HDCP_V_B1,HDCP_V_B2,HDCP_V_B3,HDCP_V_B4),0)) -> 0 | N5: =IF(COUNT(J$5:J$48)=0,"",MIN(L5+M5,POINTS_CAP_B)) -> 21 | P5: 37 | Q5: 0.062476852 | R5: =IF(COUNT(P$5:P$48)=0,"",IF(ISNUMBER(P5),1+POINTS_CAP_B-P5,0)) -> 4 | S5: =IF(COUNT(P$5:P$48)=0,"", IFERROR(CHOOSE($B5,HDCP_V_B1,HDCP_V_B2,HDCP_V_B3,HDCP_V_B4),0)) -> 0 | T5: =IF(COUNT(P$5:P$48)=0,"",MIN(R5+S5,POINTS_CAP_B)) -> 4 | V5: 7 | W5: 0.023587963 | X5: =IF(COUNT(V$5:V$48)=0,"",IF(ISNUMBER(V5),1+POINTS_CAP_B-V5,0)) -> 34 | Y5: =IF(COUNT(V$5:V$48)=0,"", IFERROR(CHOOSE($B5,HDCP_V_B1,HDCP_V_B2,HDCP_V_B3,HDCP_V_B4),0)) -> 0 | Z5: =IF(COUNT(V$5:V$48)=0,"",MIN(X5+Y5,POINTS_CAP_B)) -> 34 | AB5: 36 | AC5: 0.080509259 | AD5: =IF(COUNT(AB$5:AB$48)=0,"",IF(ISNUMBER(AB5),1+POINTS_CAP_B-AB5,0)) -> 5 | AE5: =IF(COUNT(AB$5:AB$48)=0,"", IFERROR(CHOOSE($B5,HDCP_V_B1,HDCP_V_B2,HDCP_V_B3,HDCP_V_B4),0)) -> 0 | AF5: =IF(COUNT(AB$5:AB$48)=0,"",MIN(AD5+AE5,POINTS_CAP_B)) -> 5 | AJ5: =IF(COUNT(AH$5:AH$48)=0,"",IF(ISNUMBER(AH5),1+POINTS_CAP_B-AH5,0)) | AK5: =IF(COUNT(AH$5:AH$48)=0,"", IFERROR(CHOOSE($B5,HDCP_V_B1,HDCP_V_B2,HDCP_V_B3,HDCP_V_B4),0)) | AL5: =IF(COUNT(AH$5:AH$48)=0,"",MIN(AJ5+AK5,POINTS_CAP_B)) | AP5: =IF(COUNT(AN$5:AN$48)=0,"",IF(ISNUMBER(AN5),1+POINTS_CAP_B-AN5,0)) | AQ5: =IF(COUNT(AN$5:AN$48)=0,"", IFERROR(CHOOSE($B5,HDCP_V_B1,HDCP_V_B2,HDCP_V_B3,HDCP_V_B4),0)) | AR5: =IF(COUNT(AN$5:AN$48)=0,"",MIN(AP5+AQ5,POINTS_CAP_B)) | AT5: =IF(F5="","",SUM(F5,L5,R5,X5,AD5,AJ5,AP5)) -> 97 | AU5: =IF(H5="","",SUM(H5,N5,T5,Z5,AF5,AL5,AR5)) -> 97
A6: David Willis | B6: 1 | D6: 1 | E6: 0.025 | F6: =IF(COUNT(D$5:D$48)=0,"",IF(ISNUMBER(D6),1+POINTS_CAP_B-D6,0)) -> 40 | G6: =IF(COUNT(D$5:D$48)=0,"", IFERROR(CHOOSE($B6,HDCP_V_B1,HDCP_V_B2,HDCP_V_B3,HDCP_V_B4),0)) -> 0 | H6: =IF(COUNT(D$5:D$48)=0,"",MIN(F6+G6,POINTS_CAP_B)) -> 40 | J6: 2 | K6: 0.021099537 | L6: =IF(COUNT(J$5:J$48)=0,"",IF(ISNUMBER(J6),1+POINTS_CAP_B-J6,0)) -> 39 | M6: =IF(COUNT(J$5:J$48)=0,"", IFERROR(CHOOSE($B6,HDCP_V_B1,HDCP_V_B2,HDCP_V_B3,HDCP_V_B4),0)) -> 0 | N6: =IF(COUNT(J$5:J$48)=0,"",MIN(L6+M6,POINTS_CAP_B)) -> 39 | P6: 2 | Q6: 0.034108796 | R6: =IF(COUNT(P$5:P$48)=0,"",IF(ISNUMBER(P6),1+POINTS_CAP_B-P6,0)) -> 39 | S6: =IF(COUNT(P$5:P$48)=0,"", IFERROR(CHOOSE($B6,HDCP_V_B1,HDCP_V_B2,HDCP_V_B3,HDCP_V_B4),0)) -> 0 | T6: =IF(COUNT(P$5:P$48)=0,"",MIN(R6+S6,POINTS_CAP_B)) -> 39 | V6: 2 | W6: 0.021990741 | X6: =IF(COUNT(V$5:V$48)=0,"",IF(ISNUMBER(V6),1+POINTS_CAP_B-V6,0)) -> 39 | Y6: =IF(COUNT(V$5:V$48)=0,"", IFERROR(CHOOSE($B6,HDCP_V_B1,HDCP_V_B2,HDCP_V_B3,HDCP_V_B4),0)) -> 0 | Z6: =IF(COUNT(V$5:V$48)=0,"",MIN(X6+Y6,POINTS_CAP_B)) -> 39 | AB6: 2 | AC6: 0.046238426 | AD6: =IF(COUNT(AB$5:AB$48)=0,"",IF(ISNUMBER(AB6),1+POINTS_CAP_B-AB6,0)) -> 39 | AE6: =IF(COUNT(AB$5:AB$48)=0,"", IFERROR(CHOOSE($B6,HDCP_V_B1,HDCP_V_B2,HDCP_V_B3,HDCP_V_B4),0)) -> 0 | AF6: =IF(COUNT(AB$5:AB$48)=0,"",MIN(AD6+AE6,POINTS_CAP_B)) -> 39 | AJ6: =IF(COUNT(AH$5:AH$48)=0,"",IF(ISNUMBER(AH6),1+POINTS_CAP_B-AH6,0)) | AK6: =IF(COUNT(AH$5:AH$48)=0,"", IFERROR(CHOOSE($B6,HDCP_V_B1,HDCP_V_B2,HDCP_V_B3,HDCP_V_B4),0)) | AL6: =IF(COUNT(AH$5:AH$48)=0,"",MIN(AJ6+AK6,POINTS_CAP_B)) | AP6: =IF(COUNT(AN$5:AN$48)=0,"",IF(ISNUMBER(AN6),1+POINTS_CAP_B-AN6,0)) | AQ6: =IF(COUNT(AN$5:AN$48)=0,"", IFERROR(CHOOSE($B6,HDCP_V_B1,HDCP_V_B2,HDCP_V_B3,HDCP_V_B4),0)) | AR6: =IF(COUNT(AN$5:AN$48)=0,"",MIN(AP6+AQ6,POINTS_CAP_B)) | AT6: =IF(F6="","",SUM(F6,L6,R6,X6,AD6,AJ6,AP6)) -> 196 | AU6: =IF(H6="","",SUM(H6,N6,T6,Z6,AF6,AL6,AR6)) -> 196
A7: Paul Davey | B7: 1 | D7: 16 | E7: 0.026863426 | F7: =IF(COUNT(D$5:D$48)=0,"",IF(ISNUMBER(D7),1+POINTS_CAP_B-D7,0)) -> 25 | G7: =IF(COUNT(D$5:D$48)=0,"", IFERROR(CHOOSE($B7,HDCP_V_B1,HDCP_V_B2,HDCP_V_B3,HDCP_V_B4),0)) -> 0 | H7: =IF(COUNT(D$5:D$48)=0,"",MIN(F7+G7,POINTS_CAP_B)) -> 25 | J7: 12 | K7: 0.022511574 | L7: =IF(COUNT(J$5:J$48)=0,"",IF(ISNUMBER(J7),1+POINTS_CAP_B-J7,0)) -> 29 | M7: =IF(COUNT(J$5:J$48)=0,"", IFERROR(CHOOSE($B7,HDCP_V_B1,HDCP_V_B2,HDCP_V_B3,HDCP_V_B4),0)) -> 0 | N7: =IF(COUNT(J$5:J$48)=0,"",MIN(L7+M7,POINTS_CAP_B)) -> 29 | P7: 15 | Q7: 0.0375 | R7: =IF(COUNT(P$5:P$48)=0,"",IF(ISNUMBER(P7),1+POINTS_CAP_B-P7,0)) -> 26 | S7: =IF(COUNT(P$5:P$48)=0,"", IFERROR(CHOOSE($B7,HDCP_V_B1,HDCP_V_B2,HDCP_V_B3,HDCP_V_B4),0)) -> 0 | T7: =IF(COUNT(P$5:P$48)=0,"",MIN(R7+S7,POINTS_CAP_B)) -> 26 | V7: 5 | W7: 0.02287037 | X7: =IF(COUNT(V$5:V$48)=0,"",IF(ISNUMBER(V7),1+POINTS_CAP_B-V7,0)) -> 36 | Y7: =IF(COUNT(V$5:V$48)=0,"", IFERROR(CHOOSE($B7,HDCP_V_B1,HDCP_V_B2,HDCP_V_B3,HDCP_V_B4),0)) -> 0 | Z7: =IF(COUNT(V$5:V$48)=0,"",MIN(X7+Y7,POINTS_CAP_B)) -> 36 | AB7: 12 | AC7: 0.051018519 | AD7: =IF(COUNT(AB$5:AB$48)=0,"",IF(ISNUMBER(AB7),1+POINTS_CAP_B-AB7,0)) -> 29 | AE7: =IF(COUNT(AB$5:AB$48)=0,"", IFERROR(CHOOSE($B7,HDCP_V_B1,HDCP_V_B2,HDCP_V_B3,HDCP_V_B4),0)) -> 0 | AF7: =IF(COUNT(AB$5:AB$48)=0,"",MIN(AD7+AE7,POINTS_CAP_B)) -> 29 | AJ7: =IF(COUNT(AH$5:AH$48)=0,"",IF(ISNUMBER(AH7),1+POINTS_CAP_B-AH7,0)) | AK7: =IF(COUNT(AH$5:AH$48)=0,"", IFERROR(CHOOSE($B7,HDCP_V_B1,HDCP_V_B2,HDCP_V_B3,HDCP_V_B4),0)) | AL7: =IF(COUNT(AH$5:AH$48)=0,"",MIN(AJ7+AK7,POINTS_CAP_B)) | AP7: =IF(COUNT(AN$5:AN$48)=0,"",IF(ISNUMBER(AN7),1+POINTS_CAP_B-AN7,0)) | AQ7: =IF(COUNT(AN$5:AN$48)=0,"", IFERROR(CHOOSE($B7,HDCP_V_B1,HDCP_V_B2,HDCP_V_B3,HDCP_V_B4),0)) | AR7: =IF(COUNT(AN$5:AN$48)=0,"",MIN(AP7+AQ7,POINTS_CAP_B)) | AT7: =IF(F7="","",SUM(F7,L7,R7,X7,AD7,AJ7,AP7)) -> 145 | AU7: =IF(H7="","",SUM(H7,N7,T7,Z7,AF7,AL7,AR7)) -> 145
A8: Luke Benfield | B8: 1 | D8: 6 | E8: 0.026064815 | F8: =IF(COUNT(D$5:D$48)=0,"",IF(ISNUMBER(D8),1+POINTS_CAP_B-D8,0)) -> 35 | G8: =IF(COUNT(D$5:D$48)=0,"", IFERROR(CHOOSE($B8,HDCP_V_B1,HDCP_V_B2,HDCP_V_B3,HDCP_V_B4),0)) -> 0 | H8: =IF(COUNT(D$5:D$48)=0,"",MIN(F8+G8,POINTS_CAP_B)) -> 35 | J8: 6 | K8: 0.021759259 | L8: =IF(COUNT(J$5:J$48)=0,"",IF(ISNUMBER(J8),1+POINTS_CAP_B-J8,0)) -> 35 | M8: =IF(COUNT(J$5:J$48)=0,"", IFERROR(CHOOSE($B8,HDCP_V_B1,HDCP_V_B2,HDCP_V_B3,HDCP_V_B4),0)) -> 0 | N8: =IF(COUNT(J$5:J$48)=0,"",MIN(L8+M8,POINTS_CAP_B)) -> 35 | P8: 12 | Q8: 0.036770833 | R8: =IF(COUNT(P$5:P$48)=0,"",IF(ISNUMBER(P8),1+POINTS_CAP_B-P8,0)) -> 29 | S8: =IF(COUNT(P$5:P$48)=0,"", IFERROR(CHOOSE($B8,HDCP_V_B1,HDCP_V_B2,HDCP_V_B3,HDCP_V_B4),0)) -> 0 | T8: =IF(COUNT(P$5:P$48)=0,"",MIN(R8+S8,POINTS_CAP_B)) -> 29 | V8: 12 | W8: 0.024097222 | X8: =IF(COUNT(V$5:V$48)=0,"",IF(ISNUMBER(V8),1+POINTS_CAP_B-V8,0)) -> 29 | Y8: =IF(COUNT(V$5:V$48)=0,"", IFERROR(CHOOSE($B8,HDCP_V_B1,HDCP_V_B2,HDCP_V_B3,HDCP_V_B4),0)) -> 0 | Z8: =IF(COUNT(V$5:V$48)=0,"",MIN(X8+Y8,POINTS_CAP_B)) -> 29 | AB8: 10 | AC8: 01:12:!2 | AD8: =IF(COUNT(AB$5:AB$48)=0,"",IF(ISNUMBER(AB8),1+POINTS_CAP_B-AB8,0)) -> 31 | AE8: =IF(COUNT(AB$5:AB$48)=0,"", IFERROR(CHOOSE($B8,HDCP_V_B1,HDCP_V_B2,HDCP_V_B3,HDCP_V_B4),0)) -> 0 | AF8: =IF(COUNT(AB$5:AB$48)=0,"",MIN(AD8+AE8,POINTS_CAP_B)) -> 31 | AJ8: =IF(COUNT(AH$5:AH$48)=0,"",IF(ISNUMBER(AH8),1+POINTS_CAP_B-AH8,0)) | AK8: =IF(COUNT(AH$5:AH$48)=0,"", IFERROR(CHOOSE($B8,HDCP_V_B1,HDCP_V_B2,HDCP_V_B3,HDCP_V_B4),0)) | AL8: =IF(COUNT(AH$5:AH$48)=0,"",MIN(AJ8+AK8,POINTS_CAP_B)) | AP8: =IF(COUNT(AN$5:AN$48)=0,"",IF(ISNUMBER(AN8),1+POINTS_CAP_B-AN8,0)) | AQ8: =IF(COUNT(AN$5:AN$48)=0,"", IFERROR(CHOOSE($B8,HDCP_V_B1,HDCP_V_B2,HDCP_V_B3,HDCP_V_B4),0)) | AR8: =IF(COUNT(AN$5:AN$48)=0,"",MIN(AP8+AQ8,POINTS_CAP_B)) | AT8: =IF(F8="","",SUM(F8,L8,R8,X8,AD8,AJ8,AP8)) -> 159 | AU8: =IF(H8="","",SUM(H8,N8,T8,Z8,AF8,AL8,AR8)) -> 159
A9: David Goddard | B9: 1 | D9: 15 | E9: 0.026828704 | F9: =IF(COUNT(D$5:D$48)=0,"",IF(ISNUMBER(D9),1+POINTS_CAP_B-D9,0)) -> 26 | G9: =IF(COUNT(D$5:D$48)=0,"", IFERROR(CHOOSE($B9,HDCP_V_B1,HDCP_V_B2,HDCP_V_B3,HDCP_V_B4),0)) -> 0 | H9: =IF(COUNT(D$5:D$48)=0,"",MIN(F9+G9,POINTS_CAP_B)) -> 26 | J9: 8 | K9: 0.022268519 | L9: =IF(COUNT(J$5:J$48)=0,"",IF(ISNUMBER(J9),1+POINTS_CAP_B-J9,0)) -> 33 | M9: =IF(COUNT(J$5:J$48)=0,"", IFERROR(CHOOSE($B9,HDCP_V_B1,HDCP_V_B2,HDCP_V_B3,HDCP_V_B4),0)) -> 0 | N9: =IF(COUNT(J$5:J$48)=0,"",MIN(L9+M9,POINTS_CAP_B)) -> 33 | P9: 14 | Q9: 0.037465278 | R9: =IF(COUNT(P$5:P$48)=0,"",IF(ISNUMBER(P9),1+POINTS_CAP_B-P9,0)) -> 27 | S9: =IF(COUNT(P$5:P$48)=0,"", IFERROR(CHOOSE($B9,HDCP_V_B1,HDCP_V_B2,HDCP_V_B3,HDCP_V_B4),0)) -> 0 | T9: =IF(COUNT(P$5:P$48)=0,"",MIN(R9+S9,POINTS_CAP_B)) -> 27 | V9: 8 | W9: 0.023622685 | X9: =IF(COUNT(V$5:V$48)=0,"",IF(ISNUMBER(V9),1+POINTS_CAP_B-V9,0)) -> 33 | Y9: =IF(COUNT(V$5:V$48)=0,"", IFERROR(CHOOSE($B9,HDCP_V_B1,HDCP_V_B2,HDCP_V_B3,HDCP_V_B4),0)) -> 0 | Z9: =IF(COUNT(V$5:V$48)=0,"",MIN(X9+Y9,POINTS_CAP_B)) -> 33 | AB9: 20 | AC9: 0.054386574 | AD9: =IF(COUNT(AB$5:AB$48)=0,"",IF(ISNUMBER(AB9),1+POINTS_CAP_B-AB9,0)) -> 21 | AE9: =IF(COUNT(AB$5:AB$48)=0,"", IFERROR(CHOOSE($B9,HDCP_V_B1,HDCP_V_B2,HDCP_V_B3,HDCP_V_B4),0)) -> 0 | AF9: =IF(COUNT(AB$5:AB$48)=0,"",MIN(AD9+AE9,POINTS_CAP_B)) -> 21 | AJ9: =IF(COUNT(AH$5:AH$48)=0,"",IF(ISNUMBER(AH9),1+POINTS_CAP_B-AH9,0)) | AK9: =IF(COUNT(AH$5:AH$48)=0,"", IFERROR(CHOOSE($B9,HDCP_V_B1,HDCP_V_B2,HDCP_V_B3,HDCP_V_B4),0)) | AL9: =IF(COUNT(AH$5:AH$48)=0,"",MIN(AJ9+AK9,POINTS_CAP_B)) | AP9: =IF(COUNT(AN$5:AN$48)=0,"",IF(ISNUMBER(AN9),1+POINTS_CAP_B-AN9,0)) | AQ9: =IF(COUNT(AN$5:AN$48)=0,"", IFERROR(CHOOSE($B9,HDCP_V_B1,HDCP_V_B2,HDCP_V_B3,HDCP_V_B4),0)) | AR9: =IF(COUNT(AN$5:AN$48)=0,"",MIN(AP9+AQ9,POINTS_CAP_B)) | AT9: =IF(F9="","",SUM(F9,L9,R9,X9,AD9,AJ9,AP9)) -> 140 | AU9: =IF(H9="","",SUM(H9,N9,T9,Z9,AF9,AL9,AR9)) -> 140
A10: Rich Southcott | B10: 1 | D10: 2 | E10: 0.025104167 | F10: =IF(COUNT(D$5:D$48)=0,"",IF(ISNUMBER(D10),1+POINTS_CAP_B-D10,0)) -> 39 | G10: =IF(COUNT(D$5:D$48)=0,"", IFERROR(CHOOSE($B10,HDCP_V_B1,HDCP_V_B2,HDCP_V_B3,HDCP_V_B4),0)) -> 0 | H10: =IF(COUNT(D$5:D$48)=0,"",MIN(F10+G10,POINTS_CAP_B)) -> 39 | J10: 1 | K10: 0.021006944 | L10: =IF(COUNT(J$5:J$48)=0,"",IF(ISNUMBER(J10),1+POINTS_CAP_B-J10,0)) -> 40 | M10: =IF(COUNT(J$5:J$48)=0,"", IFERROR(CHOOSE($B10,HDCP_V_B1,HDCP_V_B2,HDCP_V_B3,HDCP_V_B4),0)) -> 0 | N10: =IF(COUNT(J$5:J$48)=0,"",MIN(L10+M10,POINTS_CAP_B)) -> 40 | P10: 1 | Q10: 0.033321759 | R10: =IF(COUNT(P$5:P$48)=0,"",IF(ISNUMBER(P10),1+POINTS_CAP_B-P10,0)) -> 40 | S10: =IF(COUNT(P$5:P$48)=0,"", IFERROR(CHOOSE($B10,HDCP_V_B1,HDCP_V_B2,HDCP_V_B3,HDCP_V_B4),0)) -> 0 | T10: =IF(COUNT(P$5:P$48)=0,"",MIN(R10+S10,POINTS_CAP_B)) -> 40 | V10: 1 | W10: 0.021724537 | X10: =IF(COUNT(V$5:V$48)=0,"",IF(ISNUMBER(V10),1+POINTS_CAP_B-V10,0)) -> 40 | Y10: =IF(COUNT(V$5:V$48)=0,"", IFERROR(CHOOSE($B10,HDCP_V_B1,HDCP_V_B2,HDCP_V_B3,HDCP_V_B4),0)) -> 0 | Z10: =IF(COUNT(V$5:V$48)=0,"",MIN(X10+Y10,POINTS_CAP_B)) -> 40 | AB10: 1 | AC10: 0.045231481 | AD10: =IF(COUNT(AB$5:AB$48)=0,"",IF(ISNUMBER(AB10),1+POINTS_CAP_B-AB10,0)) -> 40 | AE10: =IF(COUNT(AB$5:AB$48)=0,"", IFERROR(CHOOSE($B10,HDCP_V_B1,HDCP_V_B2,HDCP_V_B3,HDCP_V_B4),0)) -> 0 | AF10: =IF(COUNT(AB$5:AB$48)=0,"",MIN(AD10+AE10,POINTS_CAP_B)) -> 40 | AJ10: =IF(COUNT(AH$5:AH$48)=0,"",IF(ISNUMBER(AH10),1+POINTS_CAP_B-AH10,0)) | AK10: =IF(COUNT(AH$5:AH$48)=0,"", IFERROR(CHOOSE($B10,HDCP_V_B1,HDCP_V_B2,HDCP_V_B3,HDCP_V_B4),0)) | AL10: =IF(COUNT(AH$5:AH$48)=0,"",MIN(AJ10+AK10,POINTS_CAP_B)) | AP10: =IF(COUNT(AN$5:AN$48)=0,"",IF(ISNUMBER(AN10),1+POINTS_CAP_B-AN10,0)) | AQ10: =IF(COUNT(AN$5:AN$48)=0,"", IFERROR(CHOOSE($B10,HDCP_V_B1,HDCP_V_B2,HDCP_V_B3,HDCP_V_B4),0)) | AR10: =IF(COUNT(AN$5:AN$48)=0,"",MIN(AP10+AQ10,POINTS_CAP_B)) | AT10: =IF(F10="","",SUM(F10,L10,R10,X10,AD10,AJ10,AP10)) -> 199 | AU10: =IF(H10="","",SUM(H10,N10,T10,Z10,AF10,AL10,AR10)) -> 199
A11: Joe Barrett | B11: 1 | D11: 7 | E11: 0.02625 | F11: =IF(COUNT(D$5:D$48)=0,"",IF(ISNUMBER(D11),1+POINTS_CAP_B-D11,0)) -> 34 | G11: =IF(COUNT(D$5:D$48)=0,"", IFERROR(CHOOSE($B11,HDCP_V_B1,HDCP_V_B2,HDCP_V_B3,HDCP_V_B4),0)) -> 0 | H11: =IF(COUNT(D$5:D$48)=0,"",MIN(F11+G11,POINTS_CAP_B)) -> 34 | J11: 10 | K11: 0.022314815 | L11: =IF(COUNT(J$5:J$48)=0,"",IF(ISNUMBER(J11),1+POINTS_CAP_B-J11,0)) -> 31 | M11: =IF(COUNT(J$5:J$48)=0,"", IFERROR(CHOOSE($B11,HDCP_V_B1,HDCP_V_B2,HDCP_V_B3,HDCP_V_B4),0)) -> 0 | N11: =IF(COUNT(J$5:J$48)=0,"",MIN(L11+M11,POINTS_CAP_B)) -> 31 | P11: 9 | Q11: 0.035983796 | R11: =IF(COUNT(P$5:P$48)=0,"",IF(ISNUMBER(P11),1+POINTS_CAP_B-P11,0)) -> 32 | S11: =IF(COUNT(P$5:P$48)=0,"", IFERROR(CHOOSE($B11,HDCP_V_B1,HDCP_V_B2,HDCP_V_B3,HDCP_V_B4),0)) -> 0 | T11: =IF(COUNT(P$5:P$48)=0,"",MIN(R11+S11,POINTS_CAP_B)) -> 32 | V11: 10 | W11: 0.023969907 | X11: =IF(COUNT(V$5:V$48)=0,"",IF(ISNUMBER(V11),1+POINTS_CAP_B-V11,0)) -> 31 | Y11: =IF(COUNT(V$5:V$48)=0,"", IFERROR(CHOOSE($B11,HDCP_V_B1,HDCP_V_B2,HDCP_V_B3,HDCP_V_B4),0)) -> 0 | Z11: =IF(COUNT(V$5:V$48)=0,"",MIN(X11+Y11,POINTS_CAP_B)) -> 31 | AB11: 5 | AC11: 0.049085648 | AD11: =IF(COUNT(AB$5:AB$48)=0,"",IF(ISNUMBER(AB11),1+POINTS_CAP_B-AB11,0)) -> 36 | AE11: =IF(COUNT(AB$5:AB$48)=0,"", IFERROR(CHOOSE($B11,HDCP_V_B1,HDCP_V_B2,HDCP_V_B3,HDCP_V_B4),0)) -> 0 | AF11: =IF(COUNT(AB$5:AB$48)=0,"",MIN(AD11+AE11,POINTS_CAP_B)) -> 36 | AJ11: =IF(COUNT(AH$5:AH$48)=0,"",IF(ISNUMBER(AH11),1+POINTS_CAP_B-AH11,0)) | AK11: =IF(COUNT(AH$5:AH$48)=0,"", IFERROR(CHOOSE($B11,HDCP_V_B1,HDCP_V_B2,HDCP_V_B3,HDCP_V_B4),0)) | AL11: =IF(COUNT(AH$5:AH$48)=0,"",MIN(AJ11+AK11,POINTS_CAP_B)) | AP11: =IF(COUNT(AN$5:AN$48)=0,"",IF(ISNUMBER(AN11),1+POINTS_CAP_B-AN11,0)) | AQ11: =IF(COUNT(AN$5:AN$48)=0,"", IFERROR(CHOOSE($B11,HDCP_V_B1,HDCP_V_B2,HDCP_V_B3,HDCP_V_B4),0)) | AR11: =IF(COUNT(AN$5:AN$48)=0,"",MIN(AP11+AQ11,POINTS_CAP_B)) | AT11: =IF(F11="","",SUM(F11,L11,R11,X11,AD11,AJ11,AP11)) -> 164 | AU11: =IF(H11="","",SUM(H11,N11,T11,Z11,AF11,AL11,AR11)) -> 164
A12: Sean Haywood | B12: 1 | D12: 5 | E12: 0.025393519 | F12: =IF(COUNT(D$5:D$48)=0,"",IF(ISNUMBER(D12),1+POINTS_CAP_B-D12,0)) -> 36 | G12: =IF(COUNT(D$5:D$48)=0,"", IFERROR(CHOOSE($B12,HDCP_V_B1,HDCP_V_B2,HDCP_V_B3,HDCP_V_B4),0)) -> 0 | H12: =IF(COUNT(D$5:D$48)=0,"",MIN(F12+G12,POINTS_CAP_B)) -> 36 | J12: 4 | K12: 0.021377315 | L12: =IF(COUNT(J$5:J$48)=0,"",IF(ISNUMBER(J12),1+POINTS_CAP_B-J12,0)) -> 37 | M12: =IF(COUNT(J$5:J$48)=0,"", IFERROR(CHOOSE($B12,HDCP_V_B1,HDCP_V_B2,HDCP_V_B3,HDCP_V_B4),0)) -> 0 | N12: =IF(COUNT(J$5:J$48)=0,"",MIN(L12+M12,POINTS_CAP_B)) -> 37 | P12: 4 | Q12: 0.035069444 | R12: =IF(COUNT(P$5:P$48)=0,"",IF(ISNUMBER(P12),1+POINTS_CAP_B-P12,0)) -> 37 | S12: =IF(COUNT(P$5:P$48)=0,"", IFERROR(CHOOSE($B12,HDCP_V_B1,HDCP_V_B2,HDCP_V_B3,HDCP_V_B4),0)) -> 0 | T12: =IF(COUNT(P$5:P$48)=0,"",MIN(R12+S12,POINTS_CAP_B)) -> 37 | V12: 4 | W12: 0.02287037 | X12: =IF(COUNT(V$5:V$48)=0,"",IF(ISNUMBER(V12),1+POINTS_CAP_B-V12,0)) -> 37 | Y12: =IF(COUNT(V$5:V$48)=0,"", IFERROR(CHOOSE($B12,HDCP_V_B1,HDCP_V_B2,HDCP_V_B3,HDCP_V_B4),0)) -> 0 | Z12: =IF(COUNT(V$5:V$48)=0,"",MIN(X12+Y12,POINTS_CAP_B)) -> 37 | AB12: 3 | AC12: 0.047256944 | AD12: =IF(COUNT(AB$5:AB$48)=0,"",IF(ISNUMBER(AB12),1+POINTS_CAP_B-AB12,0)) -> 38 | AE12: =IF(COUNT(AB$5:AB$48)=0,"", IFERROR(CHOOSE($B12,HDCP_V_B1,HDCP_V_B2,HDCP_V_B3,HDCP_V_B4),0)) -> 0 | AF12: =IF(COUNT(AB$5:AB$48)=0,"",MIN(AD12+AE12,POINTS_CAP_B)) -> 38 | AJ12: =IF(COUNT(AH$5:AH$48)=0,"",IF(ISNUMBER(AH12),1+POINTS_CAP_B-AH12,0)) | AK12: =IF(COUNT(AH$5:AH$48)=0,"", IFERROR(CHOOSE($B12,HDCP_V_B1,HDCP_V_B2,HDCP_V_B3,HDCP_V_B4),0)) | AL12: =IF(COUNT(AH$5:AH$48)=0,"",MIN(AJ12+AK12,POINTS_CAP_B)) | AP12: =IF(COUNT(AN$5:AN$48)=0,"",IF(ISNUMBER(AN12),1+POINTS_CAP_B-AN12,0)) | AQ12: =IF(COUNT(AN$5:AN$48)=0,"", IFERROR(CHOOSE($B12,HDCP_V_B1,HDCP_V_B2,HDCP_V_B3,HDCP_V_B4),0)) | AR12: =IF(COUNT(AN$5:AN$48)=0,"",MIN(AP12+AQ12,POINTS_CAP_B)) | AT12: =IF(F12="","",SUM(F12,L12,R12,X12,AD12,AJ12,AP12)) -> 185 | AU12: =IF(H12="","",SUM(H12,N12,T12,Z12,AF12,AL12,AR12)) -> 185
A13: Gareth Edwards | B13: 2 | D13: 17 | E13: 0.026863426 | F13: =IF(COUNT(D$5:D$48)=0,"",IF(ISNUMBER(D13),1+POINTS_CAP_B-D13,0)) -> 24 | G13: =IF(COUNT(D$5:D$48)=0,"", IFERROR(CHOOSE($B13,HDCP_V_B1,HDCP_V_B2,HDCP_V_B3,HDCP_V_B4),0)) -> 8 | H13: =IF(COUNT(D$5:D$48)=0,"",MIN(F13+G13,POINTS_CAP_B)) -> 32 | J13: 21 | K13: 0.023715278 | L13: =IF(COUNT(J$5:J$48)=0,"",IF(ISNUMBER(J13),1+POINTS_CAP_B-J13,0)) -> 20 | M13: =IF(COUNT(J$5:J$48)=0,"", IFERROR(CHOOSE($B13,HDCP_V_B1,HDCP_V_B2,HDCP_V_B3,HDCP_V_B4),0)) -> 8 | N13: =IF(COUNT(J$5:J$48)=0,"",MIN(L13+M13,POINTS_CAP_B)) -> 28 | P13: 20 | Q13: 0.038310185 | R13: =IF(COUNT(P$5:P$48)=0,"",IF(ISNUMBER(P13),1+POINTS_CAP_B-P13,0)) -> 21 | S13: =IF(COUNT(P$5:P$48)=0,"", IFERROR(CHOOSE($B13,HDCP_V_B1,HDCP_V_B2,HDCP_V_B3,HDCP_V_B4),0)) -> 8 | T13: =IF(COUNT(P$5:P$48)=0,"",MIN(R13+S13,POINTS_CAP_B)) -> 29 | V13: 19 | W13: 0.024803241 | X13: =IF(COUNT(V$5:V$48)=0,"",IF(ISNUMBER(V13),1+POINTS_CAP_B-V13,0)) -> 22 | Y13: =IF(COUNT(V$5:V$48)=0,"", IFERROR(CHOOSE($B13,HDCP_V_B1,HDCP_V_B2,HDCP_V_B3,HDCP_V_B4),0)) -> 8 | Z13: =IF(COUNT(V$5:V$48)=0,"",MIN(X13+Y13,POINTS_CAP_B)) -> 30 | AB13: 27 | AC13: 0.059502315 | AD13: =IF(COUNT(AB$5:AB$48)=0,"",IF(ISNUMBER(AB13),1+POINTS_CAP_B-AB13,0)) -> 14 | AE13: =IF(COUNT(AB$5:AB$48)=0,"", IFERROR(CHOOSE($B13,HDCP_V_B1,HDCP_V_B2,HDCP_V_B3,HDCP_V_B4),0)) -> 8 | AF13: =IF(COUNT(AB$5:AB$48)=0,"",MIN(AD13+AE13,POINTS_CAP_B)) -> 22 | AJ13: =IF(COUNT(AH$5:AH$48)=0,"",IF(ISNUMBER(AH13),1+POINTS_CAP_B-AH13,0)) | AK13: =IF(COUNT(AH$5:AH$48)=0,"", IFERROR(CHOOSE($B13,HDCP_V_B1,HDCP_V_B2,HDCP_V_B3,HDCP_V_B4),0)) | AL13: =IF(COUNT(AH$5:AH$48)=0,"",MIN(AJ13+AK13,POINTS_CAP_B)) | AP13: =IF(COUNT(AN$5:AN$48)=0,"",IF(ISNUMBER(AN13),1+POINTS_CAP_B-AN13,0)) | AQ13: =IF(COUNT(AN$5:AN$48)=0,"", IFERROR(CHOOSE($B13,HDCP_V_B1,HDCP_V_B2,HDCP_V_B3,HDCP_V_B4),0)) | AR13: =IF(COUNT(AN$5:AN$48)=0,"",MIN(AP13+AQ13,POINTS_CAP_B)) | AT13: =IF(F13="","",SUM(F13,L13,R13,X13,AD13,AJ13,AP13)) -> 101 | AU13: =IF(H13="","",SUM(H13,N13,T13,Z13,AF13,AL13,AR13)) -> 141
A14: Alex Wilson-Jones | B14: 2 | D14: 12 | E14: 0.026770833 | F14: =IF(COUNT(D$5:D$48)=0,"",IF(ISNUMBER(D14),1+POINTS_CAP_B-D14,0)) -> 29 | G14: =IF(COUNT(D$5:D$48)=0,"", IFERROR(CHOOSE($B14,HDCP_V_B1,HDCP_V_B2,HDCP_V_B3,HDCP_V_B4),0)) -> 8 | H14: =IF(COUNT(D$5:D$48)=0,"",MIN(F14+G14,POINTS_CAP_B)) -> 37 | J14: 16 | K14: 0.022766204 | L14: =IF(COUNT(J$5:J$48)=0,"",IF(ISNUMBER(J14),1+POINTS_CAP_B-J14,0)) -> 25 | M14: =IF(COUNT(J$5:J$48)=0,"", IFERROR(CHOOSE($B14,HDCP_V_B1,HDCP_V_B2,HDCP_V_B3,HDCP_V_B4),0)) -> 8 | N14: =IF(COUNT(J$5:J$48)=0,"",MIN(L14+M14,POINTS_CAP_B)) -> 33 | P14: 19 | Q14: 0.037951389 | R14: =IF(COUNT(P$5:P$48)=0,"",IF(ISNUMBER(P14),1+POINTS_CAP_B-P14,0)) -> 22 | S14: =IF(COUNT(P$5:P$48)=0,"", IFERROR(CHOOSE($B14,HDCP_V_B1,HDCP_V_B2,HDCP_V_B3,HDCP_V_B4),0)) -> 8 | T14: =IF(COUNT(P$5:P$48)=0,"",MIN(R14+S14,POINTS_CAP_B)) -> 30 | V14: 15 | W14: 0.024328704 | X14: =IF(COUNT(V$5:V$48)=0,"",IF(ISNUMBER(V14),1+POINTS_CAP_B-V14,0)) -> 26 | Y14: =IF(COUNT(V$5:V$48)=0,"", IFERROR(CHOOSE($B14,HDCP_V_B1,HDCP_V_B2,HDCP_V_B3,HDCP_V_B4),0)) -> 8 | Z14: =IF(COUNT(V$5:V$48)=0,"",MIN(X14+Y14,POINTS_CAP_B)) -> 34 | AB14: 17 | AC14: 0.053680556 | AD14: =IF(COUNT(AB$5:AB$48)=0,"",IF(ISNUMBER(AB14),1+POINTS_CAP_B-AB14,0)) -> 24 | AE14: =IF(COUNT(AB$5:AB$48)=0,"", IFERROR(CHOOSE($B14,HDCP_V_B1,HDCP_V_B2,HDCP_V_B3,HDCP_V_B4),0)) -> 8 | AF14: =IF(COUNT(AB$5:AB$48)=0,"",MIN(AD14+AE14,POINTS_CAP_B)) -> 32 | AJ14: =IF(COUNT(AH$5:AH$48)=0,"",IF(ISNUMBER(AH14),1+POINTS_CAP_B-AH14,0)) | AK14: =IF(COUNT(AH$5:AH$48)=0,"", IFERROR(CHOOSE($B14,HDCP_V_B1,HDCP_V_B2,HDCP_V_B3,HDCP_V_B4),0)) | AL14: =IF(COUNT(AH$5:AH$48)=0,"",MIN(AJ14+AK14,POINTS_CAP_B)) | AP14: =IF(COUNT(AN$5:AN$48)=0,"",IF(ISNUMBER(AN14),1+POINTS_CAP_B-AN14,0)) | AQ14: =IF(COUNT(AN$5:AN$48)=0,"", IFERROR(CHOOSE($B14,HDCP_V_B1,HDCP_V_B2,HDCP_V_B3,HDCP_V_B4),0)) | AR14: =IF(COUNT(AN$5:AN$48)=0,"",MIN(AP14+AQ14,POINTS_CAP_B)) | AT14: =IF(F14="","",SUM(F14,L14,R14,X14,AD14,AJ14,AP14)) -> 126 | AU14: =IF(H14="","",SUM(H14,N14,T14,Z14,AF14,AL14,AR14)) -> 166
A15: Justin Goold | B15: 2 | D15: 14 | E15: 0.026828704 | F15: =IF(COUNT(D$5:D$48)=0,"",IF(ISNUMBER(D15),1+POINTS_CAP_B-D15,0)) -> 27 | G15: =IF(COUNT(D$5:D$48)=0,"", IFERROR(CHOOSE($B15,HDCP_V_B1,HDCP_V_B2,HDCP_V_B3,HDCP_V_B4),0)) -> 8 | H15: =IF(COUNT(D$5:D$48)=0,"",MIN(F15+G15,POINTS_CAP_B)) -> 35 | J15: 14 | K15: 0.022592593 | L15: =IF(COUNT(J$5:J$48)=0,"",IF(ISNUMBER(J15),1+POINTS_CAP_B-J15,0)) -> 27 | M15: =IF(COUNT(J$5:J$48)=0,"", IFERROR(CHOOSE($B15,HDCP_V_B1,HDCP_V_B2,HDCP_V_B3,HDCP_V_B4),0)) -> 8 | N15: =IF(COUNT(J$5:J$48)=0,"",MIN(L15+M15,POINTS_CAP_B)) -> 35 | P15: 16 | Q15: 0.03755787 | R15: =IF(COUNT(P$5:P$48)=0,"",IF(ISNUMBER(P15),1+POINTS_CAP_B-P15,0)) -> 25 | S15: =IF(COUNT(P$5:P$48)=0,"", IFERROR(CHOOSE($B15,HDCP_V_B1,HDCP_V_B2,HDCP_V_B3,HDCP_V_B4),0)) -> 8 | T15: =IF(COUNT(P$5:P$48)=0,"",MIN(R15+S15,POINTS_CAP_B)) -> 33 | V15: 24 | W15: 0.026030093 | X15: =IF(COUNT(V$5:V$48)=0,"",IF(ISNUMBER(V15),1+POINTS_CAP_B-V15,0)) -> 17 | Y15: =IF(COUNT(V$5:V$48)=0,"", IFERROR(CHOOSE($B15,HDCP_V_B1,HDCP_V_B2,HDCP_V_B3,HDCP_V_B4),0)) -> 8 | Z15: =IF(COUNT(V$5:V$48)=0,"",MIN(X15+Y15,POINTS_CAP_B)) -> 25 | AB15: 37 | AC15: 0.080509259 | AD15: =IF(COUNT(AB$5:AB$48)=0,"",IF(ISNUMBER(AB15),1+POINTS_CAP_B-AB15,0)) -> 4 | AE15: =IF(COUNT(AB$5:AB$48)=0,"", IFERROR(CHOOSE($B15,HDCP_V_B1,HDCP_V_B2,HDCP_V_B3,HDCP_V_B4),0)) -> 8 | AF15: =IF(COUNT(AB$5:AB$48)=0,"",MIN(AD15+AE15,POINTS_CAP_B)) -> 12 | AJ15: =IF(COUNT(AH$5:AH$48)=0,"",IF(ISNUMBER(AH15),1+POINTS_CAP_B-AH15,0)) | AK15: =IF(COUNT(AH$5:AH$48)=0,"", IFERROR(CHOOSE($B15,HDCP_V_B1,HDCP_V_B2,HDCP_V_B3,HDCP_V_B4),0)) | AL15: =IF(COUNT(AH$5:AH$48)=0,"",MIN(AJ15+AK15,POINTS_CAP_B)) | AP15: =IF(COUNT(AN$5:AN$48)=0,"",IF(ISNUMBER(AN15),1+POINTS_CAP_B-AN15,0)) | AQ15: =IF(COUNT(AN$5:AN$48)=0,"", IFERROR(CHOOSE($B15,HDCP_V_B1,HDCP_V_B2,HDCP_V_B3,HDCP_V_B4),0)) | AR15: =IF(COUNT(AN$5:AN$48)=0,"",MIN(AP15+AQ15,POINTS_CAP_B)) | AT15: =IF(F15="","",SUM(F15,L15,R15,X15,AD15,AJ15,AP15)) -> 100 | AU15: =IF(H15="","",SUM(H15,N15,T15,Z15,AF15,AL15,AR15)) -> 140
A16: Rob Cherry | B16: 2 | D16: 30 | E16: 0.03037037 | F16: =IF(COUNT(D$5:D$48)=0,"",IF(ISNUMBER(D16),1+POINTS_CAP_B-D16,0)) -> 11 | G16: =IF(COUNT(D$5:D$48)=0,"", IFERROR(CHOOSE($B16,HDCP_V_B1,HDCP_V_B2,HDCP_V_B3,HDCP_V_B4),0)) -> 8 | H16: =IF(COUNT(D$5:D$48)=0,"",MIN(F16+G16,POINTS_CAP_B)) -> 19 | J16: 28 | K16: 0.025289352 | L16: =IF(COUNT(J$5:J$48)=0,"",IF(ISNUMBER(J16),1+POINTS_CAP_B-J16,0)) -> 13 | M16: =IF(COUNT(J$5:J$48)=0,"", IFERROR(CHOOSE($B16,HDCP_V_B1,HDCP_V_B2,HDCP_V_B3,HDCP_V_B4),0)) -> 8 | N16: =IF(COUNT(J$5:J$48)=0,"",MIN(L16+M16,POINTS_CAP_B)) -> 21 | P16: 23 | Q16: 0.039108796 | R16: =IF(COUNT(P$5:P$48)=0,"",IF(ISNUMBER(P16),1+POINTS_CAP_B-P16,0)) -> 18 | S16: =IF(COUNT(P$5:P$48)=0,"", IFERROR(CHOOSE($B16,HDCP_V_B1,HDCP_V_B2,HDCP_V_B3,HDCP_V_B4),0)) -> 8 | T16: =IF(COUNT(P$5:P$48)=0,"",MIN(R16+S16,POINTS_CAP_B)) -> 26 | V16: 31 | W16: 0.02693287 | X16: =IF(COUNT(V$5:V$48)=0,"",IF(ISNUMBER(V16),1+POINTS_CAP_B-V16,0)) -> 10 | Y16: =IF(COUNT(V$5:V$48)=0,"", IFERROR(CHOOSE($B16,HDCP_V_B1,HDCP_V_B2,HDCP_V_B3,HDCP_V_B4),0)) -> 8 | Z16: =IF(COUNT(V$5:V$48)=0,"",MIN(X16+Y16,POINTS_CAP_B)) -> 18 | AB16: 21 | AC16: 0.055 | AD16: =IF(COUNT(AB$5:AB$48)=0,"",IF(ISNUMBER(AB16),1+POINTS_CAP_B-AB16,0)) -> 20 | AE16: =IF(COUNT(AB$5:AB$48)=0,"", IFERROR(CHOOSE($B16,HDCP_V_B1,HDCP_V_B2,HDCP_V_B3,HDCP_V_B4),0)) -> 8 | AF16: =IF(COUNT(AB$5:AB$48)=0,"",MIN(AD16+AE16,POINTS_CAP_B)) -> 28 | AJ16: =IF(COUNT(AH$5:AH$48)=0,"",IF(ISNUMBER(AH16),1+POINTS_CAP_B-AH16,0)) | AK16: =IF(COUNT(AH$5:AH$48)=0,"", IFERROR(CHOOSE($B16,HDCP_V_B1,HDCP_V_B2,HDCP_V_B3,HDCP_V_B4),0)) | AL16: =IF(COUNT(AH$5:AH$48)=0,"",MIN(AJ16+AK16,POINTS_CAP_B)) | AP16: =IF(COUNT(AN$5:AN$48)=0,"",IF(ISNUMBER(AN16),1+POINTS_CAP_B-AN16,0)) | AQ16: =IF(COUNT(AN$5:AN$48)=0,"", IFERROR(CHOOSE($B16,HDCP_V_B1,HDCP_V_B2,HDCP_V_B3,HDCP_V_B4),0)) | AR16: =IF(COUNT(AN$5:AN$48)=0,"",MIN(AP16+AQ16,POINTS_CAP_B)) | AT16: =IF(F16="","",SUM(F16,L16,R16,X16,AD16,AJ16,AP16)) -> 72 | AU16: =IF(H16="","",SUM(H16,N16,T16,Z16,AF16,AL16,AR16)) -> 112
A17: Chris Croft | B17: 2 | D17: 25 | E17: 0.028854167 | F17: =IF(COUNT(D$5:D$48)=0,"",IF(ISNUMBER(D17),1+POINTS_CAP_B-D17,0)) -> 16 | G17: =IF(COUNT(D$5:D$48)=0,"", IFERROR(CHOOSE($B17,HDCP_V_B1,HDCP_V_B2,HDCP_V_B3,HDCP_V_B4),0)) -> 8 | H17: =IF(COUNT(D$5:D$48)=0,"",MIN(F17+G17,POINTS_CAP_B)) -> 24 | J17: 26 | K17: 0.025023148 | L17: =IF(COUNT(J$5:J$48)=0,"",IF(ISNUMBER(J17),1+POINTS_CAP_B-J17,0)) -> 15 | M17: =IF(COUNT(J$5:J$48)=0,"", IFERROR(CHOOSE($B17,HDCP_V_B1,HDCP_V_B2,HDCP_V_B3,HDCP_V_B4),0)) -> 8 | N17: =IF(COUNT(J$5:J$48)=0,"",MIN(L17+M17,POINTS_CAP_B)) -> 23 | P17: 28 | Q17: 0.041180556 | R17: =IF(COUNT(P$5:P$48)=0,"",IF(ISNUMBER(P17),1+POINTS_CAP_B-P17,0)) -> 13 | S17: =IF(COUNT(P$5:P$48)=0,"", IFERROR(CHOOSE($B17,HDCP_V_B1,HDCP_V_B2,HDCP_V_B3,HDCP_V_B4),0)) -> 8 | T17: =IF(COUNT(P$5:P$48)=0,"",MIN(R17+S17,POINTS_CAP_B)) -> 21 | V17: 27 | W17: 0.026377315 | X17: =IF(COUNT(V$5:V$48)=0,"",IF(ISNUMBER(V17),1+POINTS_CAP_B-V17,0)) -> 14 | Y17: =IF(COUNT(V$5:V$48)=0,"", IFERROR(CHOOSE($B17,HDCP_V_B1,HDCP_V_B2,HDCP_V_B3,HDCP_V_B4),0)) -> 8 | Z17: =IF(COUNT(V$5:V$48)=0,"",MIN(X17+Y17,POINTS_CAP_B)) -> 22 | AB17: 26 | AC17: 0.057847222 | AD17: =IF(COUNT(AB$5:AB$48)=0,"",IF(ISNUMBER(AB17),1+POINTS_CAP_B-AB17,0)) -> 15 | AE17: =IF(COUNT(AB$5:AB$48)=0,"", IFERROR(CHOOSE($B17,HDCP_V_B1,HDCP_V_B2,HDCP_V_B3,HDCP_V_B4),0)) -> 8 | AF17: =IF(COUNT(AB$5:AB$48)=0,"",MIN(AD17+AE17,POINTS_CAP_B)) -> 23 | AJ17: =IF(COUNT(AH$5:AH$48)=0,"",IF(ISNUMBER(AH17),1+POINTS_CAP_B-AH17,0)) | AK17: =IF(COUNT(AH$5:AH$48)=0,"", IFERROR(CHOOSE($B17,HDCP_V_B1,HDCP_V_B2,HDCP_V_B3,HDCP_V_B4),0)) | AL17: =IF(COUNT(AH$5:AH$48)=0,"",MIN(AJ17+AK17,POINTS_CAP_B)) | AP17: =IF(COUNT(AN$5:AN$48)=0,"",IF(ISNUMBER(AN17),1+POINTS_CAP_B-AN17,0)) | AQ17: =IF(COUNT(AN$5:AN$48)=0,"", IFERROR(CHOOSE($B17,HDCP_V_B1,HDCP_V_B2,HDCP_V_B3,HDCP_V_B4),0)) | AR17: =IF(COUNT(AN$5:AN$48)=0,"",MIN(AP17+AQ17,POINTS_CAP_B)) | AT17: =IF(F17="","",SUM(F17,L17,R17,X17,AD17,AJ17,AP17)) -> 73 | AU17: =IF(H17="","",SUM(H17,N17,T17,Z17,AF17,AL17,AR17)) -> 113
A18: Simon White | B18: 2 | D18: 19 | E18: 0.0275 | F18: =IF(COUNT(D$5:D$48)=0,"",IF(ISNUMBER(D18),1+POINTS_CAP_B-D18,0)) -> 22 | G18: =IF(COUNT(D$5:D$48)=0,"", IFERROR(CHOOSE($B18,HDCP_V_B1,HDCP_V_B2,HDCP_V_B3,HDCP_V_B4),0)) -> 8 | H18: =IF(COUNT(D$5:D$48)=0,"",MIN(F18+G18,POINTS_CAP_B)) -> 30 | J18: 17 | K18: 0.022824074 | L18: =IF(COUNT(J$5:J$48)=0,"",IF(ISNUMBER(J18),1+POINTS_CAP_B-J18,0)) -> 24 | M18: =IF(COUNT(J$5:J$48)=0,"", IFERROR(CHOOSE($B18,HDCP_V_B1,HDCP_V_B2,HDCP_V_B3,HDCP_V_B4),0)) -> 8 | N18: =IF(COUNT(J$5:J$48)=0,"",MIN(L18+M18,POINTS_CAP_B)) -> 32 | P18: 18 | Q18: 0.037766204 | R18: =IF(COUNT(P$5:P$48)=0,"",IF(ISNUMBER(P18),1+POINTS_CAP_B-P18,0)) -> 23 | S18: =IF(COUNT(P$5:P$48)=0,"", IFERROR(CHOOSE($B18,HDCP_V_B1,HDCP_V_B2,HDCP_V_B3,HDCP_V_B4),0)) -> 8 | T18: =IF(COUNT(P$5:P$48)=0,"",MIN(R18+S18,POINTS_CAP_B)) -> 31 | V18: 21 | W18: 0.025289352 | X18: =IF(COUNT(V$5:V$48)=0,"",IF(ISNUMBER(V18),1+POINTS_CAP_B-V18,0)) -> 20 | Y18: =IF(COUNT(V$5:V$48)=0,"", IFERROR(CHOOSE($B18,HDCP_V_B1,HDCP_V_B2,HDCP_V_B3,HDCP_V_B4),0)) -> 8 | Z18: =IF(COUNT(V$5:V$48)=0,"",MIN(X18+Y18,POINTS_CAP_B)) -> 28 | AB18: 14 | AC18: 01:!5:06 | AD18: =IF(COUNT(AB$5:AB$48)=0,"",IF(ISNUMBER(AB18),1+POINTS_CAP_B-AB18,0)) -> 27 | AE18: =IF(COUNT(AB$5:AB$48)=0,"", IFERROR(CHOOSE($B18,HDCP_V_B1,HDCP_V_B2,HDCP_V_B3,HDCP_V_B4),0)) -> 8 | AF18: =IF(COUNT(AB$5:AB$48)=0,"",MIN(AD18+AE18,POINTS_CAP_B)) -> 35 | AJ18: =IF(COUNT(AH$5:AH$48)=0,"",IF(ISNUMBER(AH18),1+POINTS_CAP_B-AH18,0)) | AK18: =IF(COUNT(AH$5:AH$48)=0,"", IFERROR(CHOOSE($B18,HDCP_V_B1,HDCP_V_B2,HDCP_V_B3,HDCP_V_B4),0)) | AL18: =IF(COUNT(AH$5:AH$48)=0,"",MIN(AJ18+AK18,POINTS_CAP_B)) | AP18: =IF(COUNT(AN$5:AN$48)=0,"",IF(ISNUMBER(AN18),1+POINTS_CAP_B-AN18,0)) | AQ18: =IF(COUNT(AN$5:AN$48)=0,"", IFERROR(CHOOSE($B18,HDCP_V_B1,HDCP_V_B2,HDCP_V_B3,HDCP_V_B4),0)) | AR18: =IF(COUNT(AN$5:AN$48)=0,"",MIN(AP18+AQ18,POINTS_CAP_B)) | AT18: =IF(F18="","",SUM(F18,L18,R18,X18,AD18,AJ18,AP18)) -> 116 | AU18: =IF(H18="","",SUM(H18,N18,T18,Z18,AF18,AL18,AR18)) -> 156
A19: David Griffiths | B19: 2 | D19: 11 | E19: 0.026712963 | F19: =IF(COUNT(D$5:D$48)=0,"",IF(ISNUMBER(D19),1+POINTS_CAP_B-D19,0)) -> 30 | G19: =IF(COUNT(D$5:D$48)=0,"", IFERROR(CHOOSE($B19,HDCP_V_B1,HDCP_V_B2,HDCP_V_B3,HDCP_V_B4),0)) -> 8 | H19: =IF(COUNT(D$5:D$48)=0,"",MIN(F19+G19,POINTS_CAP_B)) -> 38 | J19: 11 | K19: 0.0225 | L19: =IF(COUNT(J$5:J$48)=0,"",IF(ISNUMBER(J19),1+POINTS_CAP_B-J19,0)) -> 30 | M19: =IF(COUNT(J$5:J$48)=0,"", IFERROR(CHOOSE($B19,HDCP_V_B1,HDCP_V_B2,HDCP_V_B3,HDCP_V_B4),0)) -> 8 | N19: =IF(COUNT(J$5:J$48)=0,"",MIN(L19+M19,POINTS_CAP_B)) -> 38 | P19: 25 | Q19: 0.039849537 | R19: =IF(COUNT(P$5:P$48)=0,"",IF(ISNUMBER(P19),1+POINTS_CAP_B-P19,0)) -> 16 | S19: =IF(COUNT(P$5:P$48)=0,"", IFERROR(CHOOSE($B19,HDCP_V_B1,HDCP_V_B2,HDCP_V_B3,HDCP_V_B4),0)) -> 8 | T19: =IF(COUNT(P$5:P$48)=0,"",MIN(R19+S19,POINTS_CAP_B)) -> 24 | V19: 11 | W19: 0.024039352 | X19: =IF(COUNT(V$5:V$48)=0,"",IF(ISNUMBER(V19),1+POINTS_CAP_B-V19,0)) -> 30 | Y19: =IF(COUNT(V$5:V$48)=0,"", IFERROR(CHOOSE($B19,HDCP_V_B1,HDCP_V_B2,HDCP_V_B3,HDCP_V_B4),0)) -> 8 | Z19: =IF(COUNT(V$5:V$48)=0,"",MIN(X19+Y19,POINTS_CAP_B)) -> 38 | AB19: 19 | AC19: 0.054340278 | AD19: =IF(COUNT(AB$5:AB$48)=0,"",IF(ISNUMBER(AB19),1+POINTS_CAP_B-AB19,0)) -> 22 | AE19: =IF(COUNT(AB$5:AB$48)=0,"", IFERROR(CHOOSE($B19,HDCP_V_B1,HDCP_V_B2,HDCP_V_B3,HDCP_V_B4),0)) -> 8 | AF19: =IF(COUNT(AB$5:AB$48)=0,"",MIN(AD19+AE19,POINTS_CAP_B)) -> 30 | AJ19: =IF(COUNT(AH$5:AH$48)=0,"",IF(ISNUMBER(AH19),1+POINTS_CAP_B-AH19,0)) | AK19: =IF(COUNT(AH$5:AH$48)=0,"", IFERROR(CHOOSE($B19,HDCP_V_B1,HDCP_V_B2,HDCP_V_B3,HDCP_V_B4),0)) | AL19: =IF(COUNT(AH$5:AH$48)=0,"",MIN(AJ19+AK19,POINTS_CAP_B)) | AP19: =IF(COUNT(AN$5:AN$48)=0,"",IF(ISNUMBER(AN19),1+POINTS_CAP_B-AN19,0)) | AQ19: =IF(COUNT(AN$5:AN$48)=0,"", IFERROR(CHOOSE($B19,HDCP_V_B1,HDCP_V_B2,HDCP_V_B3,HDCP_V_B4),0)) | AR19: =IF(COUNT(AN$5:AN$48)=0,"",MIN(AP19+AQ19,POINTS_CAP_B)) | AT19: =IF(F19="","",SUM(F19,L19,R19,X19,AD19,AJ19,AP19)) -> 128 | AU19: =IF(H19="","",SUM(H19,N19,T19,Z19,AF19,AL19,AR19)) -> 168
