Workbook
Name CAP_A: Handicaps!$A$7
Name CAP_B: Handicaps!$D$7
Name HDCP_GRP_A1: Handicaps!$A$2
Name HDCP_GRP_A2: Handicaps!$A$3
Name HDCP_GRP_A3: Handicaps!$A$4
Name HDCP_GRP_A4: Handicaps!$A$5
Name HDCP_GRP_B1: Handicaps!$D$2
Name HDCP_GRP_B2: Handicaps!$D$3
Name HDCP_GRP_B3: Handicaps!$D$4
Name HDCP_GRP_B4: Handicaps!$D$5
Name HDCP_V_B1: Handicaps!$E$2
Name HDCP_V_B2: Handicaps!$E$3
Name HDCP_V_B3: Handicaps!$E$4
Name HDCP_V_B4: Handicaps!$E$5
Name POINTS_CAP_A: Handicaps!$B$7
Name POINTS_CAP_B: Handicaps!$E$7

Sheet Stage Data - A
B1: Handicap Group | D1: Stage 1 | J1: Stage 2 | P1: Stage 3 | V1: Stage 4 | AB1: Stage 5 | AH1: Stage 6 | AN1: Base Points | AO1: Adjusted Points
D2: Position | E2: Time | F2: Points | J2: Position | K2: Time | L2: Points | P2: Position | Q2: Time | R2: Points | V2: Position | W2: Time | X2: Points | AB2: Position | AC2: Time | AD2: Points | AH2: Position | AI2: Time | AJ2: Points
A3: Name | F3: Base | G3: Handicap | H3: Adjusted | L3: Base | M3: Handicap | N3: Adjusted | R3: Base | S3: Handicap | T3: Adjusted | X3: Base | Y3: Handicap | Z3: Adjusted | AD3: Base | AE3: Handicap | AF3: Adjusted | AJ3: Base | AK3: Handicap | AL3: Adjusted
A5: A Person | B5: 1 | F5: =IF(COUNT(D$5:D$48)=0,"",IF(ISNUMBER(D5),POINTS_CAP_A-D5,0)) | G5: =IF(COUNT(D$5:D$48)=0,"", IFERROR(CHOOSE($B5,HDCP_V_B1,HDCP_V_B2,HDCP_V_B3,HDCP_V_B4),0)) | H5: =IF(COUNT(D$5:D$48)=0,"",MIN(F5+G5,POINTS_CAP_A)) | L5: =IF(COUNT(J$5:J$48)=0,"",IF(ISNUMBER(J5),POINTS_CAP_A-J5,0)) | M5: =IF(COUNT(J$5:J$48)=0,"", IFERROR(CHOOSE($B5,HDCP_V_B1,HDCP_V_B2,HDCP_V_B3,HDCP_V_B4),0)) | N5: =IF(COUNT(J$5:J$48)=0,"",MIN(L5+M5,POINTS_CAP_A)) | R5: =IF(COUNT(P$5:P$48)=0,"",IF(ISNUMBER(P5),POINTS_CAP_A-P5,0)) | S5: =IF(COUNT(P$5:P$48)=0,"", IFERROR(CHOOSE($B5,HDCP_V_B1,HDCP_V_B2,HDCP_V_B3,HDCP_V_B4),0)) | T5: =IF(COUNT(P$5:P$48)=0,"",MIN(R5+S5,POINTS_CAP_A)) | X5: =IF(COUNT(V$5:V$48)=0,"",IF(ISNUMBER(V5),POINTS_CAP_A-V5,0)) | Y5: =IF(COUNT(V$5:V$48)=0,"", IFERROR(CHOOSE($B5,HDCP_V_B1,HDCP_V_B2,HDCP_V_B3,HDCP_V_B4),0)) | Z5: =IF(COUNT(V$5:V$48)=0,"",MIN(X5+Y5,POINTS_CAP_A)) | AD5: =IF(COUNT(AB$5:AB$48)=0,"",IF(ISNUMBER(AB5),POINTS_CAP_A-AB5,0)) | AE5: =IF(COUNT(AB$5:AB$48)=0,"", IFERROR(CHOOSE($B5,HDCP_V_B1,HDCP_V_B2,HDCP_V_B3,HDCP_V_B4),0)) | AF5: =IF(COUNT(AB$5:AB$48)=0,"",MIN(AD5+AE5,POINTS_CAP_A)) | AJ5: =IF(COUNT(AH$5:AH$48)=0,"",IF(ISNUMBER(AH5),POINTS_CAP_A-AH5,0)) | AK5: =IF(COUNT(AH$5:AH$48)=0,"", IFERROR(CHOOSE($B5,HDCP_V_B1,HDCP_V_B2,HDCP_V_B3,HDCP_V_B4),0)) | AL5: =IF(COUNT(AH$5:AH$48)=0,"",MIN(AJ5+AK5,POINTS_CAP_A)) | AN5: =IF(F5="","",SUM(F5,L5,R5,X5,AD5,AJ5)) | AO5: =IF(H5="","",SUM(H5,N5,T5,Z5,AF5,AL5))
F6: =IF(COUNT(D$5:D$48)=0,"",IF(ISNUMBER(D6),POINTS_CAP_A-D6,0)) | G6: =IF(COUNT(D$5:D$48)=0,"", IFERROR(CHOOSE($B6,HDCP_V_B1,HDCP_V_B2,HDCP_V_B3,HDCP_V_B4),0)) | H6: =IF(COUNT(D$5:D$48)=0,"",MIN(F6+G6,POINTS_CAP_A)) | L6: =IF(COUNT(J$5:J$48)=0,"",IF(ISNUMBER(J6),POINTS_CAP_A-J6,0)) | M6: =IF(COUNT(J$5:J$48)=0,"", IFERROR(CHOOSE($B6,HDCP_V_B1,HDCP_V_B2,HDCP_V_B3,HDCP_V_B4),0)) | N6: =IF(COUNT(J$5:J$48)=0,"",MIN(L6+M6,POINTS_CAP_A)) | R6: =IF(COUNT(P$5:P$48)=0,"",IF(ISNUMBER(P6),POINTS_CAP_A-P6,0)) | S6: =IF(COUNT(P$5:P$48)=0,"", IFERROR(CHOOSE($B6,HDCP_V_B1,HDCP_V_B2,HDCP_V_B3,HDCP_V_B4),0)) | T6: =IF(COUNT(P$5:P$48)=0,"",MIN(R6+S6,POINTS_CAP_A)) | X6: =IF(COUNT(V$5:V$48)=0,"",IF(ISNUMBER(V6),POINTS_CAP_A-V6,0)) | Y6: =IF(COUNT(V$5:V$48)=0,"", IFERROR(CHOOSE($B6,HDCP_V_B1,HDCP_V_B2,HDCP_V_B3,HDCP_V_B4),0)) | Z6: =IF(COUNT(V$5:V$48)=0,"",MIN(X6+Y6,POINTS_CAP_A)) | AD6: =IF(COUNT(AB$5:AB$48)=0,"",IF(ISNUMBER(AB6),POINTS_CAP_A-AB6,0)) | AE6: =IF(COUNT(AB$5:AB$48)=0,"", IFERROR(CHOOSE($B6,HDCP_V_B1,HDCP_V_B2,HDCP_V_B3,HDCP_V_B4),0)) | AF6: =IF(COUNT(AB$5:AB$48)=0,"",MIN(AD6+AE6,POINTS_CAP_A)) | AJ6: =IF(COUNT(AH$5:AH$48)=0,"",IF(ISNUMBER(AH6),POINTS_CAP_A-AH6,0)) | AK6: =IF(COUNT(AH$5:AH$48)=0,"", IFERROR(CHOOSE($B6,HDCP_V_B1,HDCP_V_B2,HDCP_V_B3,HDCP_V_B4),0)) | AL6: =IF(COUNT(AH$5:AH$48)=0,"",MIN(AJ6+AK6,POINTS_CAP_A)) | AN6: =IF(F6="","",SUM(F6,L6,R6,X6,AD6,AJ6)) | AO6: =IF(H6="","",SUM(H6,N6,T6,Z6,AF6,AL6))
F7: =IF(COUNT(D$5:D$48)=0,"",IF(ISNUMBER(D7),POINTS_CAP_A-D7,0)) | G7: =IF(COUNT(D$5:D$48)=0,"", IFERROR(CHOOSE($B7,HDCP_V_B1,HDCP_V_B2,HDCP_V_B3,HDCP_V_B4),0)) | H7: =IF(COUNT(D$5:D$48)=0,"",MIN(F7+G7,POINTS_CAP_A)) | L7: =IF(COUNT(J$5:J$48)=0,"",IF(ISNUMBER(J7),POINTS_CAP_A-J7,0)) | M7: =IF(COUNT(J$5:J$48)=0,"", IFERROR(CHOOSE($B7,HDCP_V_B1,HDCP_V_B2,HDCP_V_B3,HDCP_V_B4),0)) | N7: =IF(COUNT(J$5:J$48)=0,"",MIN(L7+M7,POINTS_CAP_A)) | R7: =IF(COUNT(P$5:P$48)=0,"",IF(ISNUMBER(P7),POINTS_CAP_A-P7,0)) | S7: =IF(COUNT(P$5:P$48)=0,"", IFERROR(CHOOSE($B7,HDCP_V_B1,HDCP_V_B2,HDCP_V_B3,HDCP_V_B4),0)) | T7: =IF(COUNT(P$5:P$48)=0,"",MIN(R7+S7,POINTS_CAP_A)) | X7: =IF(COUNT(V$5:V$48)=0,"",IF(ISNUMBER(V7),POINTS_CAP_A-V7,0)) | Y7: =IF(COUNT(V$5:V$48)=0,"", IFERROR(CHOOSE($B7,HDCP_V_B1,HDCP_V_B2,HDCP_V_B3,HDCP_V_B4),0)) | Z7: =IF(COUNT(V$5:V$48)=0,"",MIN(X7+Y7,POINTS_CAP_A)) | AD7: =IF(COUNT(AB$5:AB$48)=0,"",IF(ISNUMBER(AB7),POINTS_CAP_A-AB7,0)) | AE7: =IF(COUNT(AB$5:AB$48)=0,"", IFERROR(CHOOSE($B7,HDCP_V_B1,HDCP_V_B2,HDCP_V_B3,HDCP_V_B4),0)) | AF7: =IF(COUNT(AB$5:AB$48)=0,"",MIN(AD7+AE7,POINTS_CAP_A)) | AJ7: =IF(COUNT(AH$5:AH$48)=0,"",IF(ISNUMBER(AH7),POINTS_CAP_A-AH7,0)) | AK7: =IF(COUNT(AH$5:AH$48)=0,"", IFERROR(CHOOSE($B7,HDCP_V_B1,HDCP_V_B2,HDCP_V_B3,HDCP_V_B4),0)) | AL7: =IF(COUNT(AH$5:AH$48)=0,"",MIN(AJ7+AK7,POINTS_CAP_A)) | AN7: =IF(F7="","",SUM(F7,L7,R7,X7,AD7,AJ7)) | AO7: =IF(H7="","",SUM(H7,N7,T7,Z7,AF7,AL7))
F8: =IF(COUNT(D$5:D$48)=0,"",IF(ISNUMBER(D8),POINTS_CAP_A-D8,0)) | G8: =IF(COUNT(D$5:D$48)=0,"", IFERROR(CHOOSE($B8,HDCP_V_B1,HDCP_V_B2,HDCP_V_B3,HDCP_V_B4),0)) | H8: =IF(COUNT(D$5:D$48)=0,"",MIN(F8+G8,POINTS_CAP_A)) | L8: =IF(COUNT(J$5:J$48)=0,"",IF(ISNUMBER(J8),POINTS_CAP_A-J8,0)) | M8: =IF(COUNT(J$5:J$48)=0,"", IFERROR(CHOOSE($B8,HDCP_V_B1,HDCP_V_B2,HDCP_V_B3,HDCP_V_B4),0)) | N8: =IF(COUNT(J$5:J$48)=0,"",MIN(L8+M8,POINTS_CAP_A)) | R8: =IF(COUNT(P$5:P$48)=0,"",IF(ISNUMBER(P8),POINTS_CAP_A-P8,0)) | S8: =IF(COUNT(P$5:P$48)=0,"", IFERROR(CHOOSE($B8,HDCP_V_B1,HDCP_V_B2,HDCP_V_B3,HDCP_V_B4),0)) | T8: =IF(COUNT(P$5:P$48)=0,"",MIN(R8+S8,POINTS_CAP_A)) | X8: =IF(COUNT(V$5:V$48)=0,"",IF(ISNUMBER(V8),POINTS_CAP_A-V8,0)) | Y8: =IF(COUNT(V$5:V$48)=0,"", IFERROR(CHOOSE($B8,HDCP_V_B1,HDCP_V_B2,HDCP_V_B3,HDCP_V_B4),0)) | Z8: =IF(COUNT(V$5:V$48)=0,"",MIN(X8+Y8,POINTS_CAP_A)) | AD8: =IF(COUNT(AB$5:AB$48)=0,"",IF(ISNUMBER(AB8),POINTS_CAP_A-AB8,0)) | AE8: =IF(COUNT(AB$5:AB$48)=0,"", IFERROR(CHOOSE($B8,HDCP_V_B1,HDCP_V_B2,HDCP_V_B3,HDCP_V_B4),0)) | AF8: =IF(COUNT(AB$5:AB$48)=0,"",MIN(AD8+AE8,POINTS_CAP_A)) | AJ8: =IF(COUNT(AH$5:AH$48)=0,"",IF(ISNUMBER(AH8),POINTS_CAP_A-AH8,0)) | AK8: =IF(COUNT(AH$5:AH$48)=0,"", IFERROR(CHOOSE($B8,HDCP_V_B1,HDCP_V_B2,HDCP_V_B3,HDCP_V_B4),0)) | AL8: =IF(COUNT(AH$5:AH$48)=0,"",MIN(AJ8+AK8,POINTS_CAP_A)) | AN8: =IF(F8="","",SUM(F8,L8,R8,X8,AD8,AJ8)) | AO8: =IF(H8="","",SUM(H8,N8,T8,Z8,AF8,AL8))
F9: =IF(COUNT(D$5:D$48)=0,"",IF(ISNUMBER(D9),POINTS_CAP_A-D9,0)) | G9: =IF(COUNT(D$5:D$48)=0,"", IFERROR(CHOOSE($B9,HDCP_V_B1,HDCP_V_B2,HDCP_V_B3,HDCP_V_B4),0)) | H9: =IF(COUNT(D$5:D$48)=0,"",MIN(F9+G9,POINTS_CAP_A)) | L9: =IF(COUNT(J$5:J$48)=0,"",IF(ISNUMBER(J9),POINTS_CAP_A-J9,0)) | M9: =IF(COUNT(J$5:J$48)=0,"", IFERROR(CHOOSE($B9,HDCP_V_B1,HDCP_V_B2,HDCP_V_B3,HDCP_V_B4),0)) | N9: =IF(COUNT(J$5:J$48)=0,"",MIN(L9+M9,POINTS_CAP_A)) | R9: =IF(COUNT(P$5:P$48)=0,"",IF(ISNUMBER(P9),POINTS_CAP_A-P9,0)) | S9: =IF(COUNT(P$5:P$48)=0,"", IFERROR(CHOOSE($B9,HDCP_V_B1,HDCP_V_B2,HDCP_V_B3,HDCP_V_B4),0)) | T9: =IF(COUNT(P$5:P$48)=0,"",MIN(R9+S9,POINTS_CAP_A)) | X9: =IF(COUNT(V$5:V$48)=0,"",IF(ISNUMBER(V9),POINTS_CAP_A-V9,0)) | Y9: =IF(COUNT(V$5:V$48)=0,"", IFERROR(CHOOSE($B9,HDCP_V_B1,HDCP_V_B2,HDCP_V_B3,HDCP_V_B4),0)) | Z9: =IF(COUNT(V$5:V$48)=0,"",MIN(X9+Y9,POINTS_CAP_A)) | AD9: =IF(COUNT(AB$5:AB$48)=0,"",IF(ISNUMBER(AB9),POINTS_CAP_A-AB9,0)) | AE9: =IF(COUNT(AB$5:AB$48)=0,"", IFERROR(CHOOSE($B9,HDCP_V_B1,HDCP_V_B2,HDCP_V_B3,HDCP_V_B4),0)) | AF9: =IF(COUNT(AB$5:AB$48)=0,"",MIN(AD9+AE9,POINTS_CAP_A)) | AJ9: =IF(COUNT(AH$5:AH$48)=0,"",IF(ISNUMBER(AH9),POINTS_CAP_A-AH9,0)) | AK9: =IF(COUNT(AH$5:AH$48)=0,"", IFERROR(CHOOSE($B9,HDCP_V_B1,HDCP_V_B2,HDCP_V_B3,HDCP_V_B4),0)) | AL9: =IF(COUNT(AH$5:AH$48)=0,"",MIN(AJ9+AK9,POINTS_CAP_A)) | AN9: =IF(F9="","",SUM(F9,L9,R9,X9,AD9,AJ9)) | AO9: =IF(H9="","",SUM(H9,N9,T9,Z9,AF9,AL9))
F10: =IF(COUNT(D$5:D$48)=0,"",IF(ISNUMBER(D10),POINTS_CAP_A-D10,0)) | G10: =IF(COUNT(D$5:D$48)=0,"", IFERROR(CHOOSE($B10,HDCP_V_B1,HDCP_V_B2,HDCP_V_B3,HDCP_V_B4),0)) | H10: =IF(COUNT(D$5:D$48)=0,"",MIN(F10+G10,POINTS_CAP_A)) | L10: =IF(COUNT(J$5:J$48)=0,"",IF(ISNUMBER(J10),POINTS_CAP_A-J10,0)) | M10: =IF(COUNT(J$5:J$48)=0,"", IFERROR(CHOOSE($B10,HDCP_V_B1,HDCP_V_B2,HDCP_V_B3,HDCP_V_B4),0)) | N10: =IF(COUNT(J$5:J$48)=0,"",MIN(L10+M10,POINTS_CAP_A)) | R10: =IF(COUNT(P$5:P$48)=0,"",IF(ISNUMBER(P10),POINTS_CAP_A-P10,0)) | S10: =IF(COUNT(P$5:P$48)=0,"", IFERROR(CHOOSE($B10,HDCP_V_B1,HDCP_V_B2,HDCP_V_B3,HDCP_V_B4),0)) | T10: =IF(COUNT(P$5:P$48)=0,"",MIN(R10+S10,POINTS_CAP_A)) | X10: =IF(COUNT(V$5:V$48)=0,"",IF(ISNUMBER(V10),POINTS_CAP_A-V10,0)) | Y10: =IF(COUNT(V$5:V$48)=0,"", IFERROR(CHOOSE($B10,HDCP_V_B1,HDCP_V_B2,HDCP_V_B3,HDCP_V_B4),0)) | Z10: =IF(COUNT(V$5:V$48)=0,"",MIN(X10+Y10,POINTS_CAP_A)) | AD10: =IF(COUNT(AB$5:AB$48)=0,"",IF(ISNUMBER(AB10),POINTS_CAP_A-AB10,0)) | AE10: =IF(COUNT(AB$5:AB$48)=0,"", IFERROR(CHOOSE($B10,HDCP_V_B1,HDCP_V_B2,HDCP_V_B3,HDCP_V_B4),0)) | AF10: =IF(COUNT(AB$5:AB$48)=0,"",MIN(AD10+AE10,POINTS_CAP_A)) | AJ10: =IF(COUNT(AH$5:AH$48)=0,"",IF(ISNUMBER(AH10),POINTS_CAP_A-AH10,0)) | AK10: =IF(COUNT(AH$5:AH$48)=0,"", IFERROR(CHOOSE($B10,HDCP_V_B1,HDCP_V_B2,HDCP_V_B3,HDCP_V_B4),0)) | AL10: =IF(COUNT(AH$5:AH$48)=0,"",MIN(AJ10+AK10,POINTS_CAP_A)) | AN10: =IF(F10="","",SUM(F10,L10,R10,X10,AD10,AJ10)) | AO10: =IF(H10="","",SUM(H10,N10,T10,Z10,AF10,AL10))
F11: =IF(COUNT(D$5:D$48)=0,"",IF(ISNUMBER(D11),POINTS_CAP_A-D11,0)) | G11: =IF(COUNT(D$5:D$48)=0,"", IFERROR(CHOOSE($B11,HDCP_V_B1,HDCP_V_B2,HDCP_V_B3,HDCP_V_B4),0)) | H11: =IF(COUNT(D$5:D$48)=0,"",MIN(F11+G11,POINTS_CAP_A)) | L11: =IF(COUNT(J$5:J$48)=0,"",IF(ISNUMBER(J11),POINTS_CAP_A-J11,0)) | M11: =IF(COUNT(J$5:J$48)=0,"", IFERROR(CHOOSE($B11,HDCP_V_B1,HDCP_V_B2,HDCP_V_B3,HDCP_V_B4),0)) | N11: =IF(COUNT(J$5:J$48)=0,"",MIN(L11+M11,POINTS_CAP_A)) | R11: =IF(COUNT(P$5:P$48)=0,"",IF(ISNUMBER(P11),POINTS_CAP_A-P11,0)) | S11: =IF(COUNT(P$5:P$48)=0,"", IFERROR(CHOOSE($B11,HDCP_V_B1,HDCP_V_B2,HDCP_V_B3,HDCP_V_B4),0)) | T11: =IF(COUNT(P$5:P$48)=0,"",MIN(R11+S11,POINTS_CAP_A)) | X11: =IF(COUNT(V$5:V$48)=0,"",IF(ISNUMBER(V11),POINTS_CAP_A-V11,0)) | Y11: =IF(COUNT(V$5:V$48)=0,"", IFERROR(CHOOSE($B11,HDCP_V_B1,HDCP_V_B2,HDCP_V_B3,HDCP_V_B4),0)) | Z11: =IF(COUNT(V$5:V$48)=0,"",MIN(X11+Y11,POINTS_CAP_A)) | AD11: =IF(COUNT(AB$5:AB$48)=0,"",IF(ISNUMBER(AB11),POINTS_CAP_A-AB11,0)) | AE11: =IF(COUNT(AB$5:AB$48)=0,"", IFERROR(CHOOSE($B11,HDCP_V_B1,HDCP_V_B2,HDCP_V_B3,HDCP_V_B4),0)) | AF11: =IF(COUNT(AB$5:AB$48)=0,"",MIN(AD11+AE11,POINTS_CAP_A)) | AJ11: =IF(COUNT(AH$5:AH$48)=0,"",IF(ISNUMBER(AH11),POINTS_CAP_A-AH11,0)) | AK11: =IF(COUNT(AH$5:AH$48)=0,"", IFERROR(CHOOSE($B11,HDCP_V_B1,HDCP_V_B2,HDCP_V_B3,HDCP_V_B4),0)) | AL11: =IF(COUNT(AH$5:AH$48)=0,"",MIN(AJ11+AK11,POINTS_CAP_A)) | AN11: =IF(F11="","",SUM(F11,L11,R11,X11,AD11,AJ11)) | AO11: =IF(H11="","",SUM(H11,N11,T11,Z11,AF11,AL11))
F12: =IF(COUNT(D$5:D$48)=0,"",IF(ISNUMBER(D12),POINTS_CAP_A-D12,0)) | G12: =IF(COUNT(D$5:D$48)=0,"", IFERROR(CHOOSE($B12,HDCP_V_B1,HDCP_V_B2,HDCP_V_B3,HDCP_V_B4),0)) | H12: =IF(COUNT(D$5:D$48)=0,"",MIN(F12+G12,POINTS_CAP_A)) | L12: =IF(COUNT(J$5:J$48)=0,"",IF(ISNUMBER(J12),POINTS_CAP_A-J12,0)) | M12: =IF(COUNT(J$5:J$48)=0,"", IFERROR(CHOOSE($B12,HDCP_V_B1,HDCP_V_B2,HDCP_V_B3,HDCP_V_B4),0)) | N12: =IF(COUNT(J$5:J$48)=0,"",MIN(L12+M12,POINTS_CAP_A)) | R12: =IF(COUNT(P$5:P$48)=0,"",IF(ISNUMBER(P12),POINTS_CAP_A-P12,0)) | S12: =IF(COUNT(P$5:P$48)=0,"", IFERROR(CHOOSE($B12,HDCP_V_B1,HDCP_V_B2,HDCP_V_B3,HDCP_V_B4),0)) | T12: =IF(COUNT(P$5:P$48)=0,"",MIN(R12+S12,POINTS_CAP_A)) | X12: =IF(COUNT(V$5:V$48)=0,"",IF(ISNUMBER(V12),POINTS_CAP_A-V12,0)) | Y12: =IF(COUNT(V$5:V$48)=0,"", IFERROR(CHOOSE($B12,HDCP_V_B1,HDCP_V_B2,HDCP_V_B3,HDCP_V_B4),0)) | Z12: =IF(COUNT(V$5:V$48)=0,"",MIN(X12+Y12,POINTS_CAP_A)) | AD12: =IF(COUNT(AB$5:AB$48)=0,"",IF(ISNUMBER(AB12),POINTS_CAP_A-AB12,0)) | AE12: =IF(COUNT(AB$5:AB$48)=0,"", IFERROR(CHOOSE($B12,HDCP_V_B1,HDCP_V_B2,HDCP_V_B3,HDCP_V_B4),0)) | AF12: =IF(COUNT(AB$5:AB$48)=0,"",MIN(AD12+AE12,POINTS_CAP_A)) | AJ12: =IF(COUNT(AH$5:AH$48)=0,"",IF(ISNUMBER(AH12),POINTS_CAP_A-AH12,0)) | AK12: =IF(COUNT(AH$5:AH$48)=0,"", IFERROR(CHOOSE($B12,HDCP_V_B1,HDCP_V_B2,HDCP_V_B3,HDCP_V_B4),0)) | AL12: =IF(COUNT(AH$5:AH$48)=0,"",MIN(AJ12+AK12,POINTS_CAP_A)) | AN12: =IF(F12="","",SUM(F12,L12,R12,X12,AD12,AJ12)) | AO12: =IF(H12="","",SUM(H12,N12,T12,Z12,AF12,AL12))
F13: =IF(COUNT(D$5:D$48)=0,"",IF(ISNUMBER(D13),POINTS_CAP_A-D13,0)) | G13: =IF(COUNT(D$5:D$48)=0,"", IFERROR(CHOOSE($B13,HDCP_V_B1,HDCP_V_B2,HDCP_V_B3,HDCP_V_B4),0)) | H13: =IF(COUNT(D$5:D$48)=0,"",MIN(F13+G13,POINTS_CAP_A)) | L13: =IF(COUNT(J$5:J$48)=0,"",IF(ISNUMBER(J13),POINTS_CAP_A-J13,0)) | M13: =IF(COUNT(J$5:J$48)=0,"", IFERROR(CHOOSE($B13,HDCP_V_B1,HDCP_V_B2,HDCP_V_B3,HDCP_V_B4),0)) | N13: =IF(COUNT(J$5:J$48)=0,"",MIN(L13+M13,POINTS_CAP_A)) | R13: =IF(COUNT(P$5:P$48)=0,"",IF(ISNUMBER(P13),POINTS_CAP_A-P13,0)) | S13: =IF(COUNT(P$5:P$48)=0,"", IFERROR(CHOOSE($B13,HDCP_V_B1,HDCP_V_B2,HDCP_V_B3,HDCP_V_B4),0)) | T13: =IF(COUNT(P$5:P$48)=0,"",MIN(R13+S13,POINTS_CAP_A)) | X13: =IF(COUNT(V$5:V$48)=0,"",IF(ISNUMBER(V13),POINTS_CAP_A-V13,0)) | Y13: =IF(COUNT(V$5:V$48)=0,"", IFERROR(CHOOSE($B13,HDCP_V_B1,HDCP_V_B2,HDCP_V_B3,HDCP_V_B4),0)) | Z13: =IF(COUNT(V$5:V$48)=0,"",MIN(X13+Y13,POINTS_CAP_A)) | AD13: =IF(COUNT(AB$5:AB$48)=0,"",IF(ISNUMBER(AB13),POINTS_CAP_A-AB13,0)) | AE13: =IF(COUNT(AB$5:AB$48)=0,"", IFERROR(CHOOSE($B13,HDCP_V_B1,HDCP_V_B2,HDCP_V_B3,HDCP_V_B4),0)) | AF13: =IF(COUNT(AB$5:AB$48)=0,"",MIN(AD13+AE13,POINTS_CAP_A)) | AJ13: =IF(COUNT(AH$5:AH$48)=0,"",IF(ISNUMBER(AH13),POINTS_CAP_A-AH13,0)) | AK13: =IF(COUNT(AH$5:AH$48)=0,"", IFERROR(CHOOSE($B13,HDCP_V_B1,HDCP_V_B2,HDCP_V_B3,HDCP_V_B4),0)) | AL13: =IF(COUNT(AH$5:AH$48)=0,"",MIN(AJ13+AK13,POINTS_CAP_A)) | AN13: =IF(F13="","",SUM(F13,L13,R13,X13,AD13,AJ13)) | AO13: =IF(H13="","",SUM(H13,N13,T13,Z13,AF13,AL13))
F14: =IF(COUNT(D$5:D$48)=0,"",IF(ISNUMBER(D14),POINTS_CAP_A-D14,0)) | G14: =IF(COUNT(D$5:D$48)=0,"", IFERROR(CHOOSE($B14,HDCP_V_B1,HDCP_V_B2,HDCP_V_B3,HDCP_V_B4),0)) | H14: =IF(COUNT(D$5:D$48)=0,"",MIN(F14+G14,POINTS_CAP_A)) | L14: =IF(COUNT(J$5:J$48)=0,"",IF(ISNUMBER(J14),POINTS_CAP_A-J14,0)) | M14: =IF(COUNT(J$5:J$48)=0,"", IFERROR(CHOOSE($B14,HDCP_V_B1,HDCP_V_B2,HDCP_V_B3,HDCP_V_B4),0)) | N14: =IF(COUNT(J$5:J$48)=0,"",MIN(L14+M14,POINTS_CAP_A)) | R14: =IF(COUNT(P$5:P$48)=0,"",IF(ISNUMBER(P14),POINTS_CAP_A-P14,0)) | S14: =IF(COUNT(P$5:P$48)=0,"", IFERROR(CHOOSE($B14,HDCP_V_B1,HDCP_V_B2,HDCP_V_B3,HDCP_V_B4),0)) | T14: =IF(COUNT(P$5:P$48)=0,"",MIN(R14+S14,POINTS_CAP_A)) | X14: =IF(COUNT(V$5:V$48)=0,"",IF(ISNUMBER(V14),POINTS_CAP_A-V14,0)) | Y14: =IF(COUNT(V$5:V$48)=0,"", IFERROR(CHOOSE($B14,HDCP_V_B1,HDCP_V_B2,HDCP_V_B3,HDCP_V_B4),0)) | Z14: =IF(COUNT(V$5:V$48)=0,"",MIN(X14+Y14,POINTS_CAP_A)) | AD14: =IF(COUNT(AB$5:AB$48)=0,"",IF(ISNUMBER(AB14),POINTS_CAP_A-AB14,0)) | AE14: =IF(COUNT(AB$5:AB$48)=0,"", IFERROR(CHOOSE($B14,HDCP_V_B1,HDCP_V_B2,HDCP_V_B3,HDCP_V_B4),0)) | AF14: =IF(COUNT(AB$5:AB$48)=0,"",MIN(AD14+AE14,POINTS_CAP_A)) | AJ14: =IF(COUNT(AH$5:AH$48)=0,"",IF(ISNUMBER(AH14),POINTS_CAP_A-AH14,0)) | AK14: =IF(COUNT(AH$5:AH$48)=0,"", IFERROR(CHOOSE($B14,HDCP_V_B1,HDCP_V_B2,HDCP_V_B3,HDCP_V_B4),0)) | AL14: =IF(COUNT(AH$5:AH$48)=0,"",MIN(AJ14+AK14,POINTS_CAP_A)) | AN14: =IF(F14="","",SUM(F14,L14,R14,X14,AD14,AJ14)) | AO14: =IF(H14="","",SUM(H14,N14,T14,Z14,AF14,AL14))
F15: =IF(COUNT(D$5:D$48)=0,"",IF(ISNUMBER(D15),POINTS_CAP_A-D15,0)) | G15: =IF(COUNT(D$5:D$48)=0,"", IFERROR(CHOOSE($B15,HDCP_V_B1,HDCP_V_B2,HDCP_V_B3,HDCP_V_B4),0)) | H15: =IF(COUNT(D$5:D$48)=0,"",MIN(F15+G15,POINTS_CAP_A)) | L15: =IF(COUNT(J$5:J$48)=0,"",IF(ISNUMBER(J15),POINTS_CAP_A-J15,0)) | M15: =IF(COUNT(J$5:J$48)=0,"", IFERROR(CHOOSE($B15,HDCP_V_B1,HDCP_V_B2,HDCP_V_B3,HDCP_V_B4),0)) | N15: =IF(COUNT(J$5:J$48)=0,"",MIN(L15+M15,POINTS_CAP_A)) | R15: =IF(COUNT(P$5:P$48)=0,"",IF(ISNUMBER(P15),POINTS_CAP_A-P15,0)) | S15: =IF(COUNT(P$5:P$48)=0,"", IFERROR(CHOOSE($B15,HDCP_V_B1,HDCP_V_B2,HDCP_V_B3,HDCP_V_B4),0)) | T15: =IF(COUNT(P$5:P$48)=0,"",MIN(R15+S15,POINTS_CAP_A)) | X15: =IF(COUNT(V$5:V$48)=0,"",IF(ISNUMBER(V15),POINTS_CAP_A-V15,0)) | Y15: =IF(COUNT(V$5:V$48)=0,"", IFERROR(CHOOSE($B15,HDCP_V_B1,HDCP_V_B2,HDCP_V_B3,HDCP_V_B4),0)) | Z15: =IF(COUNT(V$5:V$48)=0,"",MIN(X15+Y15,POINTS_CAP_A)) | AD15: =IF(COUNT(AB$5:AB$48)=0,"",IF(ISNUMBER(AB15),POINTS_CAP_A-AB15,0)) | AE15: =IF(COUNT(AB$5:AB$48)=0,"", IFERROR(CHOOSE($B15,HDCP_V_B1,HDCP_V_B2,HDCP_V_B3,HDCP_V_B4),0)) | AF15: =IF(COUNT(AB$5:AB$48)=0,"",MIN(AD15+AE15,POINTS_CAP_A)) | AJ15: =IF(COUNT(AH$5:AH$48)=0,"",IF(ISNUMBER(AH15),POINTS_CAP_A-AH15,0)) | AK15: =IF(COUNT(AH$5:AH$48)=0,"", IFERROR(CHOOSE($B15,HDCP_V_B1,HDCP_V_B2,HDCP_V_B3,HDCP_V_B4),0)) | AL15: =IF(COUNT(AH$5:AH$48)=0,"",MIN(AJ15+AK15,POINTS_CAP_A)) | AN15: =IF(F15="","",SUM(F15,L15,R15,X15,AD15,AJ15)) | AO15: =IF(H15="","",SUM(H15,N15,T15,Z15,AF15,AL15))
F16: =IF(COUNT(D$5:D$48)=0,"",IF(ISNUMBER(D16),POINTS_CAP_A-D16,0)) | G16: =IF(COUNT(D$5:D$48)=0,"", IFERROR(CHOOSE($B16,HDCP_V_B1,HDCP_V_B2,HDCP_V_B3,HDCP_V_B4),0)) | H16: =IF(COUNT(D$5:D$48)=0,"",MIN(F16+G16,POINTS_CAP_A)) | L16: =IF(COUNT(J$5:J$48)=0,"",IF(ISNUMBER(J16),POINTS_CAP_A-J16,0)) | M16: =IF(COUNT(J$5:J$48)=0,"", IFERROR(CHOOSE($B16,HDCP_V_B1,HDCP_V_B2,HDCP_V_B3,HDCP_V_B4),0)) | N16: =IF(COUNT(J$5:J$48)=0,"",MIN(L16+M16,POINTS_CAP_A)) | R16: =IF(COUNT(P$5:P$48)=0,"",IF(ISNUMBER(P16),POINTS_CAP_A-P16,0)) | S16: =IF(COUNT(P$5:P$48)=0,"", IFERROR(CHOOSE($B16,HDCP_V_B1,HDCP_V_B2,HDCP_V_B3,HDCP_V_B4),0)) | T16: =IF(COUNT(P$5:P$48)=0,"",MIN(R16+S16,POINTS_CAP_A)) | X16: =IF(COUNT(V$5:V$48)=0,"",IF(ISNUMBER(V16),POINTS_CAP_A-V16,0)) | Y16: =IF(COUNT(V$5:V$48)=0,"", IFERROR(CHOOSE($B16,HDCP_V_B1,HDCP_V_B2,HDCP_V_B3,HDCP_V_B4),0)) | Z16: =IF(COUNT(V$5:V$48)=0,"",MIN(X16+Y16,POINTS_CAP_A)) | AD16: =IF(COUNT(AB$5:AB$48)=0,"",IF(ISNUMBER(AB16),POINTS_CAP_A-AB16,0)) | AE16: =IF(COUNT(AB$5:AB$48)=0,"", IFERROR(CHOOSE($B16,HDCP_V_B1,HDCP_V_B2,HDCP_V_B3,HDCP_V_B4),0)) | AF16: =IF(COUNT(AB$5:AB$48)=0,"",MIN(AD16+AE16,POINTS_CAP_A)) | AJ16: =IF(COUNT(AH$5:AH$48)=0,"",IF(ISNUMBER(AH16),POINTS_CAP_A-AH16,0)) | AK16: =IF(COUNT(AH$5:AH$48)=0,"", IFERROR(CHOOSE($B16,HDCP_V_B1,HDCP_V_B2,HDCP_V_B3,HDCP_V_B4),0)) | AL16: =IF(COUNT(AH$5:AH$48)=0,"",MIN(AJ16+AK16,POINTS_CAP_A)) | AN16: =IF(F16="","",SUM(F16,L16,R16,X16,AD16,AJ16)) | AO16: =IF(H16="","",SUM(H16,N16,T16,Z16,AF16,AL16))
F17: =IF(COUNT(D$5:D$48)=0,"",IF(ISNUMBER(D17),POINTS_CAP_A-D17,0)) | G17: =IF(COUNT(D$5:D$48)=0,"", IFERROR(CHOOSE($B17,HDCP_V_B1,HDCP_V_B2,HDCP_V_B3,HDCP_V_B4),0)) | H17: =IF(COUNT(D$5:D$48)=0,"",MIN(F17+G17,POINTS_CAP_A)) | L17: =IF(COUNT(J$5:J$48)=0,"",IF(ISNUMBER(J17),POINTS_CAP_A-J17,0)) | M17: =IF(COUNT(J$5:J$48)=0,"", IFERROR(CHOOSE($B17,HDCP_V_B1,HDCP_V_B2,HDCP_V_B3,HDCP_V_B4),0)) | N17: =IF(COUNT(J$5:J$48)=0,"",MIN(L17+M17,POINTS_CAP_A)) | R17: =IF(COUNT(P$5:P$48)=0,"",IF(ISNUMBER(P17),POINTS_CAP_A-P17,0)) | S17: =IF(COUNT(P$5:P$48)=0,"", IFERROR(CHOOSE($B17,HDCP_V_B1,HDCP_V_B2,HDCP_V_B3,HDCP_V_B4),0)) | T17: =IF(COUNT(P$5:P$48)=0,"",MIN(R17+S17,POINTS_CAP_A)) | X17: =IF(COUNT(V$5:V$48)=0,"",IF(ISNUMBER(V17),POINTS_CAP_A-V17,0)) | Y17: =IF(COUNT(V$5:V$48)=0,"", IFERROR(CHOOSE($B17,HDCP_V_B1,HDCP_V_B2,HDCP_V_B3,HDCP_V_B4),0)) | Z17: =IF(COUNT(V$5:V$48)=0,"",MIN(X17+Y17,POINTS_CAP_A)) | AD17: =IF(COUNT(AB$5:AB$48)=0,"",IF(ISNUMBER(AB17),POINTS_CAP_A-AB17,0)) | AE17: =IF(COUNT(AB$5:AB$48)=0,"", IFERROR(CHOOSE($B17,HDCP_V_B1,HDCP_V_B2,HDCP_V_B3,HDCP_V_B4),0)) | AF17: =IF(COUNT(AB$5:AB$48)=0,"",MIN(AD17+AE17,POINTS_CAP_A)) | AJ17: =IF(COUNT(AH$5:AH$48)=0,"",IF(ISNUMBER(AH17),POINTS_CAP_A-AH17,0)) | AK17: =IF(COUNT(AH$5:AH$48)=0,"", IFERROR(CHOOSE($B17,HDCP_V_B1,HDCP_V_B2,HDCP_V_B3,HDCP_V_B4),0)) | AL17: =IF(COUNT(AH$5:AH$48)=0,"",MIN(AJ17+AK17,POINTS_CAP_A)) | AN17: =IF(F17="","",SUM(F17,L17,R17,X17,AD17,AJ17)) | AO17: =IF(H17="","",SUM(H17,N17,T17,Z17,AF17,AL17))
... F30: =IF(COUNT(D$5:D$48)=0,"",IF(ISNUMBER(D30),POINTS_CAP_A-D30,0)) | G30: =IF(COUNT(D$5:D$48)=0,"", IFERROR(CHOOSE($B30,HDCP_V_B1,HDCP_V_B2,HDCP_V_B3,HDCP_V_B4),0)) | H30: =IF(COUNT(D$5:D$48)=0,"",MIN(F30+G30,POINTS_CAP_A)) | L30: =IF(COUNT(J$5:J$48)=0,"",IF(ISNUMBER(J30),POINTS_CAP_A-J30,0)) | M30: =IF(COUNT(J$5:J$48)=0,"", IFERROR(CHOOSE($B30,HDCP_V_B1,HDCP_V_B2,HDCP_V_B3,HDCP_V_B4),0)) | N30: =IF(COUNT(J$5:J$48)=0,"",MIN(L30+M30,POINTS_CAP_A)) | R30: =IF(COUNT(P$5:P$48)=0,"",IF(ISNUMBER(P30),POINTS_CAP_A-P30,0)) | S30: =IF(COUNT(P$5:P$48)=0,"", IFERROR(CHOOSE($B30,HDCP_V_B1,HDCP_V_B2,HDCP_V_B3,HDCP_V_B4),0)) | T30: =IF(COUNT(P$5:P$48)=0,"",MIN(R30+S30,POINTS_CAP_A)) | X30: =IF(COUNT(V$5:V$48)=0,"",IF(ISNUMBER(V30),POINTS_CAP_A-V30,0)) | Y30: =IF(COUNT(V$5:V$48)=0,"", IFERROR(CHOOSE($B30,HDCP_V_B1,HDCP_V_B2,HDCP_V_B3,HDCP_V_B4),0)) | Z30: =IF(COUNT(V$5:V$48)=0,"",MIN(X30+Y30,POINTS_CAP_A)) | AD30: =IF(COUNT(AB$5:AB$48)=0,"",IF(ISNUMBER(AB30),POINTS_CAP_A-AB30,0)) | AE30: =IF(COUNT(AB$5:AB$48)=0,"", IFERROR(CHOOSE($B30,HDCP_V_B1,HDCP_V_B2,HDCP_V_B3,HDCP_V_B4),0)) | AF30: =IF(COUNT(AB$5:AB$48)=0,"",MIN(AD30+AE30,POINTS_CAP_A)) | AJ30: =IF(COUNT(AH$5:AH$48)=0,"",IF(ISNUMBER(AH30),POINTS_CAP_A-AH30,0)) | AK30: =IF(COUNT(AH$5:AH$48)=0,"", IFERROR(CHOOSE($B30,HDCP_V_B1,HDCP_V_B2,HDCP_V_B3,HDCP_V_B4),0)) | AL30: =IF(COUNT(AH$5:AH$48)=0,"",MIN(AJ30+AK30,POINTS_CAP_A)) | AN30: =IF(F30="","",SUM(F30,L30,R30,X30,AD30,AJ30)) | AO30: =IF(H30="","",SUM(H30,N30,T30,Z30,AF30,AL30))
AN31: =IF(F31="","",SUM(F31,L31,R31,X31,AD31,AJ31)) | AO31: =IF(H31="","",SUM(H31,N31,T31,Z31,AF31,AL31))
AN32: =IF(F32="","",SUM(F32,L32,R32,X32,AD32,AJ32)) | AO32: =IF(H32="","",SUM(H32,N32,T32,Z32,AF32,AL32))
AN33: =IF(F33="","",SUM(F33,L33,R33,X33,AD33,AJ33)) | AO33: =IF(H33="","",SUM(H33,N33,T33,Z33,AF33,AL33))
AN34: =IF(F34="","",SUM(F34,L34,R34,X34,AD34,AJ34)) | AO34: =IF(H34="","",SUM(H34,N34,T34,Z34,AF34,AL34))
AN35: =IF(F35="","",SUM(F35,L35,R35,X35,AD35,AJ35)) | AO35: =IF(H35="","",SUM(H35,N35,T35,Z35,AF35,AL35))
AN36: =IF(F36="","",SUM(F36,L36,R36,X36,AD36,AJ36)) | AO36: =IF(H36="","",SUM(H36,N36,T36,Z36,AF36,AL36))
AN37: =IF(F37="","",SUM(F37,L37,R37,X37,AD37,AJ37)) | AO37: =IF(H37="","",SUM(H37,N37,T37,Z37,AF37,AL37))
AN38: =IF(F38="","",SUM(F38,L38,R38,X38,AD38,AJ38)) | AO38: =IF(H38="","",SUM(H38,N38,T38,Z38,AF38,AL38))
AN39: =IF(F39="","",SUM(F39,L39,R39,X39,AD39,AJ39)) | AO39: =IF(H39="","",SUM(H39,N39,T39,Z39,AF39,AL39))
AN40: =IF(F40="","",SUM(F40,L40,R40,X40,AD40,AJ40)) | AO40: =IF(H40="","",SUM(H40,N40,T40,Z40,AF40,AL40))
AN41: =IF(F41="","",SUM(F41,L41,R41,X41,AD41,AJ41)) | AO41: =IF(H41="","",SUM(H41,N41,T41,Z41,AF41,AL41))
AN42: =IF(F42="","",SUM(F42,L42,R42,X42,AD42,AJ42)) | AO42: =IF(H42="","",SUM(H42,N42,T42,Z42,AF42,AL42))
... AN55: =IF(F55="","",SUM(F55,L55,R55,X55,AD55,AJ55)) | AO55: =IF(H55="","",SUM(H55,N55,T55,Z55,AF55,AL55))

Sheet Stage Data - B
B1: Handicap Group | D1: Stage 1 | J1: Stage 2 | P1: Stage 3 | V1: Stage 4 | AB1: Stage 5 | AH1: Stage 6 | AN1: Base Points | AO1: Adjusted Points
D2: Position | E2: Time | F2: Points | J2: Position | K2: Time | L2: Points | P2: Position | Q2: Time | R2: Points | V2: Position | W2: Time | X2: Points | AB2: Position | AC2: Time | AD2: Points | AH2: Position | AI2: Time | AJ2: Points
A3: Name | F3: Base | G3: Handicap | H3: Adjusted | L3: Base | M3: Handicap | N3: Adjusted | R3: Base | S3: Handicap | T3: Adjusted | X3: Base | Y3: Handicap | Z3: Adjusted | AD3: Base | AE3: Handicap | AF3: Adjusted | AJ3: Base | AK3: Handicap | AL3: Adjusted
A5: Some Guy | B5: 1 | F5: =IF(COUNT(D$5:D$48)=0,"",IF(ISNUMBER(D5),POINTS_CAP_B-D5,0)) | G5: =IF(COUNT(D$5:D$48)=0,"", IFERROR(CHOOSE($B5,HDCP_V_B1,HDCP_V_B2,HDCP_V_B3,HDCP_V_B4),0)) | H5: =IF(COUNT(D$5:D$48)=0,"",MIN(F5+G5,POINTS_CAP_B)) | L5: =IF(COUNT(J$5:J$48)=0,"",IF(ISNUMBER(J5),POINTS_CAP_B-J5,0)) | M5: =IF(COUNT(J$5:J$48)=0,"", IFERROR(CHOOSE($B5,HDCP_V_B1,HDCP_V_B2,HDCP_V_B3,HDCP_V_B4),0)) | N5: =IF(COUNT(J$5:J$48)=0,"",MIN(L5+M5,POINTS_CAP_B)) | R5: =IF(COUNT(P$5:P$48)=0,"",IF(ISNUMBER(P5),POINTS_CAP_B-P5,0)) | S5: =IF(COUNT(P$5:P$48)=0,"", IFERROR(CHOOSE($B5,HDCP_V_B1,HDCP_V_B2,HDCP_V_B3,HDCP_V_B4),0)) | T5: =IF(COUNT(P$5:P$48)=0,"",MIN(R5+S5,POINTS_CAP_B)) | X5: =IF(COUNT(V$5:V$48)=0,"",IF(ISNUMBER(V5),POINTS_CAP_B-V5,0)) | Y5: =IF(COUNT(V$5:V$48)=0,"", IFERROR(CHOOSE($B5,HDCP_V_B1,HDCP_V_B2,HDCP_V_B3,HDCP_V_B4),0)) | Z5: =IF(COUNT(V$5:V$48)=0,"",MIN(X5+Y5,POINTS_CAP_B)) | AD5: =IF(COUNT(AB$5:AB$48)=0,"",IF(ISNUMBER(AB5),POINTS_CAP_B-AB5,0)) | AE5: =IF(COUNT(AB$5:AB$48)=0,"", IFERROR(CHOOSE($B5,HDCP_V_B1,HDCP_V_B2,HDCP_V_B3,HDCP_V_B4),0)) | AF5: =IF(COUNT(AB$5:AB$48)=0,"",MIN(AD5+AE5,POINTS_CAP_B)) | AJ5: =IF(COUNT(AH$5:AH$48)=0,"",IF(ISNUMBER(AH5),POINTS_CAP_B-AH5,0)) | AK5: =IF(COUNT(AH$5:AH$48)=0,"", IFERROR(CHOOSE($B5,HDCP_V_B1,HDCP_V_B2,HDCP_V_B3,HDCP_V_B4),0)) | AL5: =IF(COUNT(AH$5:AH$48)=0,"",MIN(AJ5+AK5,POINTS_CAP_B)) | AN5: =IF(F5="","",SUM(F5,L5,R5,X5,AD5,AJ5)) | AO5: =IF(H5="","",SUM(H5,N5,T5,Z5,AF5,AL5))
F6: =IF(COUNT(D$5:D$48)=0,"",IF(ISNUMBER(D6),POINTS_CAP_B-D6,0)) | G6: =IF(COUNT(D$5:D$48)=0,"", IFERROR(CHOOSE($B6,HDCP_V_B1,HDCP_V_B2,HDCP_V_B3,HDCP_V_B4),0)) | H6: =IF(COUNT(D$5:D$48)=0,"",MIN(F6+G6,POINTS_CAP_B)) | L6: =IF(COUNT(J$5:J$48)=0,"",IF(ISNUMBER(J6),POINTS_CAP_B-J6,0)) | M6: =IF(COUNT(J$5:J$48)=0,"", IFERROR(CHOOSE($B6,HDCP_V_B1,HDCP_V_B2,HDCP_V_B3,HDCP_V_B4),0)) | N6: =IF(COUNT(J$5:J$48)=0,"",MIN(L6+M6,POINTS_CAP_B)) | R6: =IF(COUNT(P$5:P$48)=0,"",IF(ISNUMBER(P6),POINTS_CAP_B-P6,0)) | S6: =IF(COUNT(P$5:P$48)=0,"", IFERROR(CHOOSE($B6,HDCP_V_B1,HDCP_V_B2,HDCP_V_B3,HDCP_V_B4),0)) | T6: =IF(COUNT(P$5:P$48)=0,"",MIN(R6+S6,POINTS_CAP_B)) | X6: =IF(COUNT(V$5:V$48)=0,"",IF(ISNUMBER(V6),POINTS_CAP_B-V6,0)) | Y6: =IF(COUNT(V$5:V$48)=0,"", IFERROR(CHOOSE($B6,HDCP_V_B1,HDCP_V_B2,HDCP_V_B3,HDCP_V_B4),0)) | Z6: =IF(COUNT(V$5:V$48)=0,"",MIN(X6+Y6,POINTS_CAP_B)) | AD6: =IF(COUNT(AB$5:AB$48)=0,"",IF(ISNUMBER(AB6),POINTS_CAP_B-AB6,0)) | AE6: =IF(COUNT(AB$5:AB$48)=0,"", IFERROR(CHOOSE($B6,HDCP_V_B1,HDCP_V_B2,HDCP_V_B3,HDCP_V_B4),0)) | AF6: =IF(COUNT(AB$5:AB$48)=0,"",MIN(AD6+AE6,POINTS_CAP_B)) | AJ6: =IF(COUNT(AH$5:AH$48)=0,"",IF(ISNUMBER(AH6),POINTS_CAP_B-AH6,0)) | AK6: =IF(COUNT(AH$5:AH$48)=0,"", IFERROR(CHOOSE($B6,HDCP_V_B1,HDCP_V_B2,HDCP_V_B3,HDCP_V_B4),0)) | AL6: =IF(COUNT(AH$5:AH$48)=0,"",MIN(AJ6+AK6,POINTS_CAP_B)) | AN6: =IF(F6="","",SUM(F6,L6,R6,X6,AD6,AJ6)) | AO6: =IF(H6="","",SUM(H6,N6,T6,Z6,AF6,AL6))
F7: =IF(COUNT(D$5:D$48)=0,"",IF(ISNUMBER(D7),POINTS_CAP_B-D7,0)) | G7: =IF(COUNT(D$5:D$48)=0,"", IFERROR(CHOOSE($B7,HDCP_V_B1,HDCP_V_B2,HDCP_V_B3,HDCP_V_B4),0)) | H7: =IF(COUNT(D$5:D$48)=0,"",MIN(F7+G7,POINTS_CAP_B)) | L7: =IF(COUNT(J$5:J$48)=0,"",IF(ISNUMBER(J7),POINTS_CAP_B-J7,0)) | M7: =IF(COUNT(J$5:J$48)=0,"", IFERROR(CHOOSE($B7,HDCP_V_B1,HDCP_V_B2,HDCP_V_B3,HDCP_V_B4),0)) | N7: =IF(COUNT(J$5:J$48)=0,"",MIN(L7+M7,POINTS_CAP_B)) | R7: =IF(COUNT(P$5:P$48)=0,"",IF(ISNUMBER(P7),POINTS_CAP_B-P7,0)) | S7: =IF(COUNT(P$5:P$48)=0,"", IFERROR(CHOOSE($B7,HDCP_V_B1,HDCP_V_B2,HDCP_V_B3,HDCP_V_B4),0)) | T7: =IF(COUNT(P$5:P$48)=0,"",MIN(R7+S7,POINTS_CAP_B)) | X7: =IF(COUNT(V$5:V$48)=0,"",IF(ISNUMBER(V7),POINTS_CAP_B-V7,0)) | Y7: =IF(COUNT(V$5:V$48)=0,"", IFERROR(CHOOSE($B7,HDCP_V_B1,HDCP_V_B2,HDCP_V_B3,HDCP_V_B4),0)) | Z7: =IF(COUNT(V$5:V$48)=0,"",MIN(X7+Y7,POINTS_CAP_B)) | AD7: =IF(COUNT(AB$5:AB$48)=0,"",IF(ISNUMBER(AB7),POINTS_CAP_B-AB7,0)) | AE7: =IF(COUNT(AB$5:AB$48)=0,"", IFERROR(CHOOSE($B7,HDCP_V_B1,HDCP_V_B2,HDCP_V_B3,HDCP_V_B4),0)) | AF7: =IF(COUNT(AB$5:AB$48)=0,"",MIN(AD7+AE7,POINTS_CAP_B)) | AJ7: =IF(COUNT(AH$5:AH$48)=0,"",IF(ISNUMBER(AH7),POINTS_CAP_B-AH7,0)) | AK7: =IF(COUNT(AH$5:AH$48)=0,"", IFERROR(CHOOSE($B7,HDCP_V_B1,HDCP_V_B2,HDCP_V_B3,HDCP_V_B4),0)) | AL7: =IF(COUNT(AH$5:AH$48)=0,"",MIN(AJ7+AK7,POINTS_CAP_B)) | AN7: =IF(F7="","",SUM(F7,L7,R7,X7,AD7,AJ7)) | AO7: =IF(H7="","",SUM(H7,N7,T7,Z7,AF7,AL7))
F8: =IF(COUNT(D$5:D$48)=0,"",IF(ISNUMBER(D8),POINTS_CAP_B-D8,0)) | G8: =IF(COUNT(D$5:D$48)=0,"", IFERROR(CHOOSE($B8,HDCP_V_B1,HDCP_V_B2,HDCP_V_B3,HDCP_V_B4),0)) | H8: =IF(COUNT(D$5:D$48)=0,"",MIN(F8+G8,POINTS_CAP_B)) | L8: =IF(COUNT(J$5:J$48)=0,"",IF(ISNUMBER(J8),POINTS_CAP_B-J8,0)) | M8: =IF(COUNT(J$5:J$48)=0,"", IFERROR(CHOOSE($B8,HDCP_V_B1,HDCP_V_B2,HDCP_V_B3,HDCP_V_B4),0)) | N8: =IF(COUNT(J$5:J$48)=0,"",MIN(L8+M8,POINTS_CAP_B)) | R8: =IF(COUNT(P$5:P$48)=0,"",IF(ISNUMBER(P8),POINTS_CAP_B-P8,0)) | S8: =IF(COUNT(P$5:P$48)=0,"", IFERROR(CHOOSE($B8,HDCP_V_B1,HDCP_V_B2,HDCP_V_B3,HDCP_V_B4),0)) | T8: =IF(COUNT(P$5:P$48)=0,"",MIN(R8+S8,POINTS_CAP_B)) | X8: =IF(COUNT(V$5:V$48)=0,"",IF(ISNUMBER(V8),POINTS_CAP_B-V8,0)) | Y8: =IF(COUNT(V$5:V$48)=0,"", IFERROR(CHOOSE($B8,HDCP_V_B1,HDCP_V_B2,HDCP_V_B3,HDCP_V_B4),0)) | Z8: =IF(COUNT(V$5:V$48)=0,"",MIN(X8+Y8,POINTS_CAP_B)) | AD8: =IF(COUNT(AB$5:AB$48)=0,"",IF(ISNUMBER(AB8),POINTS_CAP_B-AB8,0)) | AE8: =IF(COUNT(AB$5:AB$48)=0,"", IFERROR(CHOOSE($B8,HDCP_V_B1,HDCP_V_B2,HDCP_V_B3,HDCP_V_B4),0)) | AF8: =IF(COUNT(AB$5:AB$48)=0,"",MIN(AD8+AE8,POINTS_CAP_B)) | AJ8: =IF(COUNT(AH$5:AH$48)=0,"",IF(ISNUMBER(AH8),POINTS_CAP_B-AH8,0)) | AK8: =IF(COUNT(AH$5:AH$48)=0,"", IFERROR(CHOOSE($B8,HDCP_V_B1,HDCP_V_B2,HDCP_V_B3,HDCP_V_B4),0)) | AL8: =IF(COUNT(AH$5:AH$48)=0,"",MIN(AJ8+AK8,POINTS_CAP_B)) | AN8: =IF(F8="","",SUM(F8,L8,R8,X8,AD8,AJ8)) | AO8: =IF(H8="","",SUM(H8,N8,T8,Z8,AF8,AL8))
F9: =IF(COUNT(D$5:D$48)=0,"",IF(ISNUMBER(D9),POINTS_CAP_B-D9,0)) | G9: =IF(COUNT(D$5:D$48)=0,"", IFERROR(CHOOSE($B9,HDCP_V_B1,HDCP_V_B2,HDCP_V_B3,HDCP_V_B4),0)) | H9: =IF(COUNT(D$5:D$48)=0,"",MIN(F9+G9,POINTS_CAP_B)) | L9: =IF(COUNT(J$5:J$48)=0,"",IF(ISNUMBER(J9),POINTS_CAP_B-J9,0)) | M9: =IF(COUNT(J$5:J$48)=0,"", IFERROR(CHOOSE($B9,HDCP_V_B1,HDCP_V_B2,HDCP_V_B3,HDCP_V_B4),0)) | N9: =IF(COUNT(J$5:J$48)=0,"",MIN(L9+M9,POINTS_CAP_B)) | R9: =IF(COUNT(P$5:P$48)=0,"",IF(ISNUMBER(P9),POINTS_CAP_B-P9,0)) | S9: =IF(COUNT(P$5:P$48)=0,"", IFERROR(CHOOSE($B9,HDCP_V_B1,HDCP_V_B2,HDCP_V_B3,HDCP_V_B4),0)) | T9: =IF(COUNT(P$5:P$48)=0,"",MIN(R9+S9,POINTS_CAP_B)) | X9: =IF(COUNT(V$5:V$48)=0,"",IF(ISNUMBER(V9),POINTS_CAP_B-V9,0)) | Y9: =IF(COUNT(V$5:V$48)=0,"", IFERROR(CHOOSE($B9,HDCP_V_B1,HDCP_V_B2,HDCP_V_B3,HDCP_V_B4),0)) | Z9: =IF(COUNT(V$5:V$48)=0,"",MIN(X9+Y9,POINTS_CAP_B)) | AD9: =IF(COUNT(AB$5:AB$48)=0,"",IF(ISNUMBER(AB9),POINTS_CAP_B-AB9,0)) | AE9: =IF(COUNT(AB$5:AB$48)=0,"", IFERROR(CHOOSE($B9,HDCP_V_B1,HDCP_V_B2,HDCP_V_B3,HDCP_V_B4),0)) | AF9: =IF(COUNT(AB$5:AB$48)=0,"",MIN(AD9+AE9,POINTS_CAP_B)) | AJ9: =IF(COUNT(AH$5:AH$48)=0,"",IF(ISNUMBER(AH9),POINTS_CAP_B-AH9,0)) | AK9: =IF(COUNT(AH$5:AH$48)=0,"", IFERROR(CHOOSE($B9,HDCP_V_B1,HDCP_V_B2,HDCP_V_B3,HDCP_V_B4),0)) | AL9: =IF(COUNT(AH$5:AH$48)=0,"",MIN(AJ9+AK9,POINTS_CAP_B)) | AN9: =IF(F9="","",SUM(F9,L9,R9,X9,AD9,AJ9)) | AO9: =IF(H9="","",SUM(H9,N9,T9,Z9,AF9,AL9))
F10: =IF(COUNT(D$5:D$48)=0,"",IF(ISNUMBER(D10),POINTS_CAP_B-D10,0)) | G10: =IF(COUNT(D$5:D$48)=0,"", IFERROR(CHOOSE($B10,HDCP_V_B1,HDCP_V_B2,HDCP_V_B3,HDCP_V_B4),0)) | H10: =IF(COUNT(D$5:D$48)=0,"",MIN(F10+G10,POINTS_CAP_B)) | L10: =IF(COUNT(J$5:J$48)=0,"",IF(ISNUMBER(J10),POINTS_CAP_B-J10,0)) | M10: =IF(COUNT(J$5:J$48)=0,"", IFERROR(CHOOSE($B10,HDCP_V_B1,HDCP_V_B2,HDCP_V_B3,HDCP_V_B4),0)) | N10: =IF(COUNT(J$5:J$48)=0,"",MIN(L10+M10,POINTS_CAP_B)) | R10: =IF(COUNT(P$5:P$48)=0,"",IF(ISNUMBER(P10),POINTS_CAP_B-P10,0)) | S10: =IF(COUNT(P$5:P$48)=0,"", IFERROR(CHOOSE($B10,HDCP_V_B1,HDCP_V_B2,HDCP_V_B3,HDCP_V_B4),0)) | T10: =IF(COUNT(P$5:P$48)=0,"",MIN(R10+S10,POINTS_CAP_B)) | X10: =IF(COUNT(V$5:V$48)=0,"",IF(ISNUMBER(V10),POINTS_CAP_B-V10,0)) | Y10: =IF(COUNT(V$5:V$48)=0,"", IFERROR(CHOOSE($B10,HDCP_V_B1,HDCP_V_B2,HDCP_V_B3,HDCP_V_B4),0)) | Z10: =IF(COUNT(V$5:V$48)=0,"",MIN(X10+Y10,POINTS_CAP_B)) | AD10: =IF(COUNT(AB$5:AB$48)=0,"",IF(ISNUMBER(AB10),POINTS_CAP_B-AB10,0)) | AE10: =IF(COUNT(AB$5:AB$48)=0,"", IFERROR(CHOOSE($B10,HDCP_V_B1,HDCP_V_B2,HDCP_V_B3,HDCP_V_B4),0)) | AF10: =IF(COUNT(AB$5:AB$48)=0,"",MIN(AD10+AE10,POINTS_CAP_B)) | AJ10: =IF(COUNT(AH$5:AH$48)=0,"",IF(ISNUMBER(AH10),POINTS_CAP_B-AH10,0)) | AK10: =IF(COUNT(AH$5:AH$48)=0,"", IFERROR(CHOOSE($B10,HDCP_V_B1,HDCP_V_B2,HDCP_V_B3,HDCP_V_B4),0)) | AL10: =IF(COUNT(AH$5:AH$48)=0,"",MIN(AJ10+AK10,POINTS_CAP_B)) | AN10: =IF(F10="","",SUM(F10,L10,R10,X10,AD10,AJ10)) | AO10: =IF(H10="","",SUM(H10,N10,T10,Z10,AF10,AL10))
F11: =IF(COUNT(D$5:D$48)=0,"",IF(ISNUMBER(D11),POINTS_CAP_B-D11,0)) | G11: =IF(COUNT(D$5:D$48)=0,"", IFERROR(CHOOSE($B11,HDCP_V_B1,HDCP_V_B2,HDCP_V_B3,HDCP_V_B4),0)) | H11: =IF(COUNT(D$5:D$48)=0,"",MIN(F11+G11,POINTS_CAP_B)) | L11: =IF(COUNT(J$5:J$48)=0,"",IF(ISNUMBER(J11),POINTS_CAP_B-J11,0)) | M11: =IF(COUNT(J$5:J$48)=0,"", IFERROR(CHOOSE($B11,HDCP_V_B1,HDCP_V_B2,HDCP_V_B3,HDCP_V_B4),0)) | N11: =IF(COUNT(J$5:J$48)=0,"",MIN(L11+M11,POINTS_CAP_B)) | R11: =IF(COUNT(P$5:P$48)=0,"",IF(ISNUMBER(P11),POINTS_CAP_B-P11,0)) | S11: =IF(COUNT(P$5:P$48)=0,"", IFERROR(CHOOSE($B11,HDCP_V_B1,HDCP_V_B2,HDCP_V_B3,HDCP_V_B4),0)) | T11: =IF(COUNT(P$5:P$48)=0,"",MIN(R11+S11,POINTS_CAP_B)) | X11: =IF(COUNT(V$5:V$48)=0,"",IF(ISNUMBER(V11),POINTS_CAP_B-V11,0)) | Y11: =IF(COUNT(V$5:V$48)=0,"", IFERROR(CHOOSE($B11,HDCP_V_B1,HDCP_V_B2,HDCP_V_B3,HDCP_V_B4),0)) | Z11: =IF(COUNT(V$5:V$48)=0,"",MIN(X11+Y11,POINTS_CAP_B)) | AD11: =IF(COUNT(AB$5:AB$48)=0,"",IF(ISNUMBER(AB11),POINTS_CAP_B-AB11,0)) | AE11: =IF(COUNT(AB$5:AB$48)=0,"", IFERROR(CHOOSE($B11,HDCP_V_B1,HDCP_V_B2,HDCP_V_B3,HDCP_V_B4),0)) | AF11: =IF(COUNT(AB$5:AB$48)=0,"",MIN(AD11+AE11,POINTS_CAP_B)) | AJ11: =IF(COUNT(AH$5:AH$48)=0,"",IF(ISNUMBER(AH11),POINTS_CAP_B-AH11,0)) | AK11: =IF(COUNT(AH$5:AH$48)=0,"", IFERROR(CHOOSE($B11,HDCP_V_B1,HDCP_V_B2,HDCP_V_B3,HDCP_V_B4),0)) | AL11: =IF(COUNT(AH$5:AH$48)=0,"",MIN(AJ11+AK11,POINTS_CAP_B)) | AN11: =IF(F11="","",SUM(F11,L11,R11,X11,AD11,AJ11)) | AO11: =IF(H11="","",SUM(H11,N11,T11,Z11,AF11,AL11))
F12: =IF(COUNT(D$5:D$48)=0,"",IF(ISNUMBER(D12),POINTS_CAP_B-D12,0)) | G12: =IF(COUNT(D$5:D$48)=0,"", IFERROR(CHOOSE($B12,HDCP_V_B1,HDCP_V_B2,HDCP_V_B3,HDCP_V_B4),0)) | H12: =IF(COUNT(D$5:D$48)=0,"",MIN(F12+G12,POINTS_CAP_B)) | L12: =IF(COUNT(J$5:J$48)=0,"",IF(ISNUMBER(J12),POINTS_CAP_B-J12,0)) | M12: =IF(COUNT(J$5:J$48)=0,"", IFERROR(CHOOSE($B12,HDCP_V_B1,HDCP_V_B2,HDCP_V_B3,HDCP_V_B4),0)) | N12: =IF(COUNT(J$5:J$48)=0,"",MIN(L12+M12,POINTS_CAP_B)) | R12: =IF(COUNT(P$5:P$48)=0,"",IF(ISNUMBER(P12),POINTS_CAP_B-P12,0)) | S12: =IF(COUNT(P$5:P$48)=0,"", IFERROR(CHOOSE($B12,HDCP_V_B1,HDCP_V_B2,HDCP_V_B3,HDCP_V_B4),0)) | T12: =IF(COUNT(P$5:P$48)=0,"",MIN(R12+S12,POINTS_CAP_B)) | X12: =IF(COUNT(V$5:V$48)=0,"",IF(ISNUMBER(V12),POINTS_CAP_B-V12,0)) | Y12: =IF(COUNT(V$5:V$48)=0,"", IFERROR(CHOOSE($B12,HDCP_V_B1,HDCP_V_B2,HDCP_V_B3,HDCP_V_B4),0)) | Z12: =IF(COUNT(V$5:V$48)=0,"",MIN(X12+Y12,POINTS_CAP_B)) | AD12: =IF(COUNT(AB$5:AB$48)=0,"",IF(ISNUMBER(AB12),POINTS_CAP_B-AB12,0)) | AE12: =IF(COUNT(AB$5:AB$48)=0,"", IFERROR(CHOOSE($B12,HDCP_V_B1,HDCP_V_B2,HDCP_V_B3,HDCP_V_B4),0)) | AF12: =IF(COUNT(AB$5:AB$48)=0,"",MIN(AD12+AE12,POINTS_CAP_B)) | AJ12: =IF(COUNT(AH$5:AH$48)=0,"",IF(ISNUMBER(AH12),POINTS_CAP_B-AH12,0)) | AK12: =IF(COUNT(AH$5:AH$48)=0,"", IFERROR(CHOOSE($B12,HDCP_V_B1,HDCP_V_B2,HDCP_V_B3,HDCP_V_B4),0)) | AL12: =IF(COUNT(AH$5:AH$48)=0,"",MIN(AJ12+AK12,POINTS_CAP_B)) | AN12: =IF(F12="","",SUM(F12,L12,R12,X12,AD12,AJ12)) | AO12: =IF(H12="","",SUM(H12,N12,T12,Z12,AF12,AL12))
F13: =IF(COUNT(D$5:D$48)=0,"",IF(ISNUMBER(D13),POINTS_CAP_B-D13,0)) | G13: =IF(COUNT(D$5:D$48)=0,"", IFERROR(CHOOSE($B13,HDCP_V_B1,HDCP_V_B2,HDCP_V_B3,HDCP_V_B4),0)) | H13: =IF(COUNT(D$5:D$48)=0,"",MIN(F13+G13,POINTS_CAP_B)) | L13: =IF(COUNT(J$5:J$48)=0,"",IF(ISNUMBER(J13),POINTS_CAP_B-J13,0)) | M13: =IF(COUNT(J$5:J$48)=0,"", IFERROR(CHOOSE($B13,HDCP_V_B1,HDCP_V_B2,HDCP_V_B3,HDCP_V_B4),0)) | N13: =IF(COUNT(J$5:J$48)=0,"",MIN(L13+M13,POINTS_CAP_B)) | R13: =IF(COUNT(P$5:P$48)=0,"",IF(ISNUMBER(P13),POINTS_CAP_B-P13,0)) | S13: =IF(COUNT(P$5:P$48)=0,"", IFERROR(CHOOSE($B13,HDCP_V_B1,HDCP_V_B2,HDCP_V_B3,HDCP_V_B4),0)) | T13: =IF(COUNT(P$5:P$48)=0,"",MIN(R13+S13,POINTS_CAP_B)) | X13: =IF(COUNT(V$5:V$48)=0,"",IF(ISNUMBER(V13),POINTS_CAP_B-V13,0)) | Y13: =IF(COUNT(V$5:V$48)=0,"", IFERROR(CHOOSE($B13,HDCP_V_B1,HDCP_V_B2,HDCP_V_B3,HDCP_V_B4),0)) | Z13: =IF(COUNT(V$5:V$48)=0,"",MIN(X13+Y13,POINTS_CAP_B)) | AD13: =IF(COUNT(AB$5:AB$48)=0,"",IF(ISNUMBER(AB13),POINTS_CAP_B-AB13,0)) | AE13: =IF(COUNT(AB$5:AB$48)=0,"", IFERROR(CHOOSE($B13,HDCP_V_B1,HDCP_V_B2,HDCP_V_B3,HDCP_V_B4),0)) | AF13: =IF(COUNT(AB$5:AB$48)=0,"",MIN(AD13+AE13,POINTS_CAP_B)) | AJ13: =IF(COUNT(AH$5:AH$48)=0,"",IF(ISNUMBER(AH13),POINTS_CAP_B-AH13,0)) | AK13: =IF(COUNT(AH$5:AH$48)=0,"", IFERROR(CHOOSE($B13,HDCP_V_B1,HDCP_V_B2,HDCP_V_B3,HDCP_V_B4),0)) | AL13: =IF(COUNT(AH$5:AH$48)=0,"",MIN(AJ13+AK13,POINTS_CAP_B)) | AN13: =IF(F13="","",SUM(F13,L13,R13,X13,AD13,AJ13)) | AO13: =IF(H13="","",SUM(H13,N13,T13,Z13,AF13,AL13))
F14: =IF(COUNT(D$5:D$48)=0,"",IF(ISNUMBER(D14),POINTS_CAP_B-D14,0)) | G14: =IF(COUNT(D$5:D$48)=0,"", IFERROR(CHOOSE($B14,HDCP_V_B1,HDCP_V_B2,HDCP_V_B3,HDCP_V_B4),0)) | H14: =IF(COUNT(D$5:D$48)=0,"",MIN(F14+G14,POINTS_CAP_B)) | L14: =IF(COUNT(J$5:J$48)=0,"",IF(ISNUMBER(J14),POINTS_CAP_B-J14,0)) | M14: =IF(COUNT(J$5:J$48)=0,"", IFERROR(CHOOSE($B14,HDCP_V_B1,HDCP_V_B2,HDCP_V_B3,HDCP_V_B4),0)) | N14: =IF(COUNT(J$5:J$48)=0,"",MIN(L14+M14,POINTS_CAP_B)) | R14: =IF(COUNT(P$5:P$48)=0,"",IF(ISNUMBER(P14),POINTS_CAP_B-P14,0)) | S14: =IF(COUNT(P$5:P$48)=0,"", IFERROR(CHOOSE($B14,HDCP_V_B1,HDCP_V_B2,HDCP_V_B3,HDCP_V_B4),0)) | T14: =IF(COUNT(P$5:P$48)=0,"",MIN(R14+S14,POINTS_CAP_B)) | X14: =IF(COUNT(V$5:V$48)=0,"",IF(ISNUMBER(V14),POINTS_CAP_B-V14,0)) | Y14: =IF(COUNT(V$5:V$48)=0,"", IFERROR(CHOOSE($B14,HDCP_V_B1,HDCP_V_B2,HDCP_V_B3,HDCP_V_B4),0)) | Z14: =IF(COUNT(V$5:V$48)=0,"",MIN(X14+Y14,POINTS_CAP_B)) | AD14: =IF(COUNT(AB$5:AB$48)=0,"",IF(ISNUMBER(AB14),POINTS_CAP_B-AB14,0)) | AE14: =IF(COUNT(AB$5:AB$48)=0,"", IFERROR(CHOOSE($B14,HDCP_V_B1,HDCP_V_B2,HDCP_V_B3,HDCP_V_B4),0)) | AF14: =IF(COUNT(AB$5:AB$48)=0,"",MIN(AD14+AE14,POINTS_CAP_B)) | AJ14: =IF(COUNT(AH$5:AH$48)=0,"",IF(ISNUMBER(AH14),POINTS_CAP_B-AH14,0)) | AK14: =IF(COUNT(AH$5:AH$48)=0,"", IFERROR(CHOOSE($B14,HDCP_V_B1,HDCP_V_B2,HDCP_V_B3,HDCP_V_B4),0)) | AL14: =IF(COUNT(AH$5:AH$48)=0,"",MIN(AJ14+AK14,POINTS_CAP_B)) | AN14: =IF(F14="","",SUM(F14,L14,R14,X14,AD14,AJ14)) | AO14: =IF(H14="","",SUM(H14,N14,T14,Z14,AF14,AL14))
F15: =IF(COUNT(D$5:D$48)=0,"",IF(ISNUMBER(D15),POINTS_CAP_B-D15,0)) | G15: =IF(COUNT(D$5:D$48)=0,"", IFERROR(CHOOSE($B15,HDCP_V_B1,HDCP_V_B2,HDCP_V_B3,HDCP_V_B4),0)) | H15: =IF(COUNT(D$5:D$48)=0,"",MIN(F15+G15,POINTS_CAP_B)) | L15: =IF(COUNT(J$5:J$48)=0,"",IF(ISNUMBER(J15),POINTS_CAP_B-J15,0)) | M15: =IF(COUNT(J$5:J$48)=0,"", IFERROR(CHOOSE($B15,HDCP_V_B1,HDCP_V_B2,HDCP_V_B3,HDCP_V_B4),0)) | N15: =IF(COUNT(J$5:J$48)=0,"",MIN(L15+M15,POINTS_CAP_B)) | R15: =IF(COUNT(P$5:P$48)=0,"",IF(ISNUMBER(P15),POINTS_CAP_B-P15,0)) | S15: =IF(COUNT(P$5:P$48)=0,"", IFERROR(CHOOSE($B15,HDCP_V_B1,HDCP_V_B2,HDCP_V_B3,HDCP_V_B4),0)) | T15: =IF(COUNT(P$5:P$48)=0,"",MIN(R15+S15,POINTS_CAP_B)) | X15: =IF(COUNT(V$5:V$48)=0,"",IF(ISNUMBER(V15),POINTS_CAP_B-V15,0)) | Y15: =IF(COUNT(V$5:V$48)=0,"", IFERROR(CHOOSE($B15,HDCP_V_B1,HDCP_V_B2,HDCP_V_B3,HDCP_V_B4),0)) | Z15: =IF(COUNT(V$5:V$48)=0,"",MIN(X15+Y15,POINTS_CAP_B)) | AD15: =IF(COUNT(AB$5:AB$48)=0,"",IF(ISNUMBER(AB15),POINTS_CAP_B-AB15,0)) | AE15: =IF(COUNT(AB$5:AB$48)=0,"", IFERROR(CHOOSE($B15,HDCP_V_B1,HDCP_V_B2,HDCP_V_B3,HDCP_V_B4),0)) | AF15: =IF(COUNT(AB$5:AB$48)=0,"",MIN(AD15+AE15,POINTS_CAP_B)) | AJ15: =IF(COUNT(AH$5:AH$48)=0,"",IF(ISNUMBER(AH15),POINTS_CAP_B-AH15,0)) | AK15: =IF(COUNT(AH$5:AH$48)=0,"", IFERROR(CHOOSE($B15,HDCP_V_B1,HDCP_V_B2,HDCP_V_B3,HDCP_V_B4),0)) | AL15: =IF(COUNT(AH$5:AH$48)=0,"",MIN(AJ15+AK15,POINTS_CAP_B)) | AN15: =IF(F15="","",SUM(F15,L15,R15,X15,AD15,AJ15)) | AO15: =IF(H15="","",SUM(H15,N15,T15,Z15,AF15,AL15))
F16: =IF(COUNT(D$5:D$48)=0,"",IF(ISNUMBER(D16),POINTS_CAP_B-D16,0)) | G16: =IF(COUNT(D$5:D$48)=0,"", IFERROR(CHOOSE($B16,HDCP_V_B1,HDCP_V_B2,HDCP_V_B3,HDCP_V_B4),0)) | H16: =IF(COUNT(D$5:D$48)=0,"",MIN(F16+G16,POINTS_CAP_B)) | L16: =IF(COUNT(J$5:J$48)=0,"",IF(ISNUMBER(J16),POINTS_CAP_B-J16,0)) | M16: =IF(COUNT(J$5:J$48)=0,"", IFERROR(CHOOSE($B16,HDCP_V_B1,HDCP_V_B2,HDCP_V_B3,HDCP_V_B4),0)) | N16: =IF(COUNT(J$5:J$48)=0,"",MIN(L16+M16,POINTS_CAP_B)) | R16: =IF(COUNT(P$5:P$48)=0,"",IF(ISNUMBER(P16),POINTS_CAP_B-P16,0)) | S16: =IF(COUNT(P$5:P$48)=0,"", IFERROR(CHOOSE($B16,HDCP_V_B1,HDCP_V_B2,HDCP_V_B3,HDCP_V_B4),0)) | T16: =IF(COUNT(P$5:P$48)=0,"",MIN(R16+S16,POINTS_CAP_B)) | X16: =IF(COUNT(V$5:V$48)=0,"",IF(ISNUMBER(V16),POINTS_CAP_B-V16,0)) | Y16: =IF(COUNT(V$5:V$48)=0,"", IFERROR(CHOOSE($B16,HDCP_V_B1,HDCP_V_B2,HDCP_V_B3,HDCP_V_B4),0)) | Z16: =IF(COUNT(V$5:V$48)=0,"",MIN(X16+Y16,POINTS_CAP_B)) | AD16: =IF(COUNT(AB$5:AB$48)=0,"",IF(ISNUMBER(AB16),POINTS_CAP_B-AB16,0)) | AE16: =IF(COUNT(AB$5:AB$48)=0,"", IFERROR(CHOOSE($B16,HDCP_V_B1,HDCP_V_B2,HDCP_V_B3,HDCP_V_B4),0)) | AF16: =IF(COUNT(AB$5:AB$48)=0,"",MIN(AD16+AE16,POINTS_CAP_B)) | AJ16: =IF(COUNT(AH$5:AH$48)=0,"",IF(ISNUMBER(AH16),POINTS_CAP_B-AH16,0)) | AK16: =IF(COUNT(AH$5:AH$48)=0,"", IFERROR(CHOOSE($B16,HDCP_V_B1,HDCP_V_B2,HDCP_V_B3,HDCP_V_B4),0)) | AL16: =IF(COUNT(AH$5:AH$48)=0,"",MIN(AJ16+AK16,POINTS_CAP_B)) | AN16: =IF(F16="","",SUM(F16,L16,R16,X16,AD16,AJ16)) | AO16: =IF(H16="","",SUM(H16,N16,T16,Z16,AF16,AL16))
F17: =IF(COUNT(D$5:D$48)=0,"",IF(ISNUMBER(D17),POINTS_CAP_B-D17,0)) | G17: =IF(COUNT(D$5:D$48)=0,"", IFERROR(CHOOSE($B17,HDCP_V_B1,HDCP_V_B2,HDCP_V_B3,HDCP_V_B4),0)) | H17: =IF(COUNT(D$5:D$48)=0,"",MIN(F17+G17,POINTS_CAP_B)) | L17: =IF(COUNT(J$5:J$48)=0,"",IF(ISNUMBER(J17),POINTS_CAP_B-J17,0)) | M17: =IF(COUNT(J$5:J$48)=0,"", IFERROR(CHOOSE($B17,HDCP_V_B1,HDCP_V_B2,HDCP_V_B3,HDCP_V_B4),0)) | N17: =IF(COUNT(J$5:J$48)=0,"",MIN(L17+M17,POINTS_CAP_B)) | R17: =IF(COUNT(P$5:P$48)=0,"",IF(ISNUMBER(P17),POINTS_CAP_B-P17,0)) | S17: =IF(COUNT(P$5:P$48)=0,"", IFERROR(CHOOSE($B17,HDCP_V_B1,HDCP_V_B2,HDCP_V_B3,HDCP_V_B4),0)) | T17: =IF(COUNT(P$5:P$48)=0,"",MIN(R17+S17,POINTS_CAP_B)) | X17: =IF(COUNT(V$5:V$48)=0,"",IF(ISNUMBER(V17),POINTS_CAP_B-V17,0)) | Y17: =IF(COUNT(V$5:V$48)=0,"", IFERROR(CHOOSE($B17,HDCP_V_B1,HDCP_V_B2,HDCP_V_B3,HDCP_V_B4),0)) | Z17: =IF(COUNT(V$5:V$48)=0,"",MIN(X17+Y17,POINTS_CAP_B)) | AD17: =IF(COUNT(AB$5:AB$48)=0,"",IF(ISNUMBER(AB17),POINTS_CAP_B-AB17,0)) | AE17: =IF(COUNT(AB$5:AB$48)=0,"", IFERROR(CHOOSE($B17,HDCP_V_B1,HDCP_V_B2,HDCP_V_B3,HDCP_V_B4),0)) | AF17: =IF(COUNT(AB$5:AB$48)=0,"",MIN(AD17+AE17,POINTS_CAP_B)) | AJ17: =IF(COUNT(AH$5:AH$48)=0,"",IF(ISNUMBER(AH17),POINTS_CAP_B-AH17,0)) | AK17: =IF(COUNT(AH$5:AH$48)=0,"", IFERROR(CHOOSE($B17,HDCP_V_B1,HDCP_V_B2,HDCP_V_B3,HDCP_V_B4),0)) | AL17: =IF(COUNT(AH$5:AH$48)=0,"",MIN(AJ17+AK17,POINTS_CAP_B)) | AN17: =IF(F17="","",SUM(F17,L17,R17,X17,AD17,AJ17)) | AO17: =IF(H17="","",SUM(H17,N17,T17,Z17,AF17,AL17))
... F38: =IF(COUNT(D$5:D$48)=0,"",IF(ISNUMBER(D38),POINTS_CAP_B-D38,0)) | G38: =IF(COUNT(D$5:D$48)=0,"", IFERROR(CHOOSE($B38,HDCP_V_B1,HDCP_V_B2,HDCP_V_B3,HDCP_V_B4),0)) | H38: =IF(COUNT(D$5:D$48)=0,"",MIN(F38+G38,POINTS_CAP_B)) | L38: =IF(COUNT(J$5:J$48)=0,"",IF(ISNUMBER(J38),POINTS_CAP_B-J38,0)) | M38: =IF(COUNT(J$5:J$48)=0,"", IFERROR(CHOOSE($B38,HDCP_V_B1,HDCP_V_B2,HDCP_V_B3,HDCP_V_B4),0)) | N38: =IF(COUNT(J$5:J$48)=0,"",MIN(L38+M38,POINTS_CAP_B)) | R38: =IF(COUNT(P$5:P$48)=0,"",IF(ISNUMBER(P38),POINTS_CAP_B-P38,0)) | S38: =IF(COUNT(P$5:P$48)=0,"", IFERROR(CHOOSE($B38,HDCP_V_B1,HDCP_V_B2,HDCP_V_B3,HDCP_V_B4),0)) | T38: =IF(COUNT(P$5:P$48)=0,"",MIN(R38+S38,POINTS_CAP_B)) | X38: =IF(COUNT(V$5:V$48)=0,"",IF(ISNUMBER(V38),POINTS_CAP_B-V38,0)) | Y38: =IF(COUNT(V$5:V$48)=0,"", IFERROR(CHOOSE($B38,HDCP_V_B1,HDCP_V_B2,HDCP_V_B3,HDCP_V_B4),0)) | Z38: =IF(COUNT(V$5:V$48)=0,"",MIN(X38+Y38,POINTS_CAP_B)) | AD38: =IF(COUNT(AB$5:AB$48)=0,"",IF(ISNUMBER(AB38),POINTS_CAP_B-AB38,0)) | AE38: =IF(COUNT(AB$5:AB$48)=0,"", IFERROR(CHOOSE($B38,HDCP_V_B1,HDCP_V_B2,HDCP_V_B3,HDCP_V_B4),0)) | AF38: =IF(COUNT(AB$5:AB$48)=0,"",MIN(AD38+AE38,POINTS_CAP_B)) | AJ38: =IF(COUNT(AH$5:AH$48)=0,"",IF(ISNUMBER(AH38),POINTS_CAP_B-AH38,0)) | AK38: =IF(COUNT(AH$5:AH$48)=0,"", IFERROR(CHOOSE($B38,HDCP_V_B1,HDCP_V_B2,HDCP_V_B3,HDCP_V_B4),0)) | AL38: =IF(COUNT(AH$5:AH$48)=0,"",MIN(AJ38+AK38,POINTS_CAP_B)) | AN38: =IF(F38="","",SUM(F38,L38,R38,X38,AD38,AJ38)) | AO38: =IF(H38="","",SUM(H38,N38,T38,Z38,AF38,AL38))
AN39: =IF(F39="","",SUM(F39,L39,R39,X39,AD39,AJ39)) | AO39: =IF(H39="","",SUM(H39,N39,T39,Z39,AF39,AL39))
AN40: =IF(F40="","",SUM(F40,L40,R40,X40,AD40,AJ40)) | AO40: =IF(H40="","",SUM(H40,N40,T40,Z40,AF40,AL40))
AN41: =IF(F41="","",SUM(F41,L41,R41,X41,AD41,AJ41)) | AO41: =IF(H41="","",SUM(H41,N41,T41,Z41,AF41,AL41))
AN42: =IF(F42="","",SUM(F42,L42,R42,X42,AD42,AJ42)) | AO42: =IF(H42="","",SUM(H42,N42,T42,Z42,AF42,AL42))
AN43: =IF(F43="","",SUM(F43,L43,R43,X43,AD43,AJ43)) | AO43: =IF(H43="","",SUM(H43,N43,T43,Z43,AF43,AL43))
AN44: =IF(F44="","",SUM(F44,L44,R44,X44,AD44,AJ44)) | AO44: =IF(H44="","",SUM(H44,N44,T44,Z44,AF44,AL44))
AN45: =IF(F45="","",SUM(F45,L45,R45,X45,AD45,AJ45)) | AO45: =IF(H45="","",SUM(H45,N45,T45,Z45,AF45,AL45))
AN46: =IF(F46="","",SUM(F46,L46,R46,X46,AD46,AJ46)) | AO46: =IF(H46="","",SUM(H46,N46,T46,Z46,AF46,AL46))
AN47: =IF(F47="","",SUM(F47,L47,R47,X47,AD47,AJ47)) | AO47: =IF(H47="","",SUM(H47,N47,T47,Z47,AF47,AL47))
AN48: =IF(F48="","",SUM(F48,L48,R48,X48,AD48,AJ48)) | AO48: =IF(H48="","",SUM(H48,N48,T48,Z48,AF48,AL48))
AN49: =IF(F49="","",SUM(F49,L49,R49,X49,AD49,AJ49)) | AO49: =IF(H49="","",SUM(H49,N49,T49,Z49,AF49,AL49))
AN50: =IF(F50="","",SUM(F50,L50,R50,X50,AD50,AJ50)) | AO50: =IF(H50="","",SUM(H50,N50,T50,Z50,AF50,AL50))
... AN55: =IF(F55="","",SUM(F55,L55,R55,X55,AD55,AJ55)) | AO55: =IF(H55="","",SUM(H55,N55,T55,Z55,AF55,AL55))

Sheet Handicaps
A2: A1 | B2: 0 | D2: B1 | E2: 0
A3: A2 | B3: 5 | D3: B2 | E3: 5
A4: A3 | B4: 10 | D4: B2 | E4: 10
A5: A4 | B5: 15 | D5: B4 | E5: 15
A7: Cap (A) | B7: 30 | D7: Cap (B) | E7: 35

Sheet Results - A
A1: Overall | E1: Stage 1 | M1: Stage 2 | U1: Stage 3 | AC1: Stage 4 | AK1: Stage 5 | AS1: Stage 6
A2: Position | B2: Name | C2: Total Points | E2: Rank | F2: Name | G2: Pos. | H2: Time | I2: Base Pts. | J2: Handicap | K2: Points | M2: Rank | N2: Name | O2: Pos. | P2: Time | Q2: Base Pts. | R2: Handicap | S2: Points | U2: Rank | V2: Name | W2: Pos. | X2: Time | Y2: Base Pts. | Z2: Handicap | AA2: Points | AC2: Rank | AD2: Name | AE2: Pos. | AF2: Time | AG2: Base Pts. | AH2: Handicap | AI2: Points | AK2: Rank | AL2: Name | AM2: Pos. | AN2: Time | AO2: Base Pts. | AP2: Handicap | AQ2: Points | AS2: Rank | AT2: Name | AU2: Pos. | AV2: Time | AW2: Base Pts. | AX2: Handicap | AY2: Points
A4: {=_xlfn.LET( _xlpm.r,ROW()-ROW($A$4)+1, _xlpm.n,ROWS(_xlfn.ANCHORARRAY($B$4)), IF(_xlpm.r>_xlpm.n,"", _xlfn.LET( _xlpm.this,INDEX(_xlfn.ANCHORARRAY($B$4),_xlpm.r,2), _xlpm.pts,INDEX(_xlfn.ANCHORARRAY($B$4),0,2), IF(_xlpm.this="","",1+COUNTIF(_xlpm.pts,">"&_xlpm.this)) ) ) )} | B4: {=_xlfn.LET( _xlpm.names,'Stage Data - A'!$A$5:$A$48, _xlpm.total,'Stage Data - A'!$AO$5:$AO$48, _xlpm.data,_xlfn._xlws.FILTER(CHOOSE({1,2},_xlpm.names,_xlpm.total),_xlpm.names<>""), _xlfn.SORTBY(_xlpm.data,INDEX(_xlpm.data,,2),-1,INDEX(_xlpm.data,,1),1) )} -> A Person | E4: {=_xlfn.LET( _xlpm.r,ROW()-ROW($E$4)+1, _xlpm.n,ROWS(_xlfn.ANCHORARRAY($F$4)), IF(_xlpm.r>_xlpm.n,"", _xlfn.LET( _xlpm.this,INDEX(_xlfn.ANCHORARRAY($F$4),_xlpm.r,6), _xlpm.pts,INDEX(_xlfn.ANCHORARRAY($F$4),0,6), IF(_xlpm.this="","",1+COUNTIF(_xlpm.pts,">"&_xlpm.this)) ) ) )} -> #REF! | F4: {=_xlfn.LET( _xlpm.names,'Stage Data - A'!$A$5:$A$48, _xlpm.stpos,'Stage Data - A'!D$5:D$48, _xlpm.time,'Stage Data - A'!E$5:E$48, _xlpm.base,'Stage Data - A'!F$5:F$48, _xlpm.hdcp,'Stage Data - A'!G$5:G$48, _xlpm.adj,'Stage Data - A'!H$5:H$48, _xlpm.data,_xlfn._xlws.FILTER(CHOOSE({1,2,3,4,5,6},_xlpm.names,_xlpm.stpos,_xlpm.time,_xlpm.base,_xlpm.hdcp,_xlpm.adj), _xlpm.adj<>""), _xlfn.SORTBY(_xlpm.data, INDEX(_xlpm.data,,6), -1, INDEX(_xlpm.data,,1), 1) )} -> #VALUE! | M4: {=_xlfn.LET( _xlpm.r,ROW()-ROW($M$4)+1, _xlpm.n,ROWS(_xlfn.ANCHORARRAY($N$4)), IF(_xlpm.r>_xlpm.n,"", _xlfn.LET( _xlpm.this,INDEX(_xlfn.ANCHORARRAY($N$4),_xlpm.r,6), _xlpm.pts,INDEX(_xlfn.ANCHORARRAY($N$4),0,6), IF(_xlpm.this="","",1+COUNTIF(_xlpm.pts,">"&_xlpm.this)) ) ) )} -> #REF! | N4: {=_xlfn.LET( _xlpm.names,'Stage Data - A'!$A$5:$A$48, _xlpm.stpos,'Stage Data - A'!J$5:J$48, _xlpm.time,'Stage Data - A'!K$5:K$48, _xlpm.base,'Stage Data - A'!L$5:L$48, _xlpm.hdcp,'Stage Data - A'!M$5:M$48, _xlpm.adj,'Stage Data - A'!N$5:N$48, _xlpm.data,_xlfn._xlws.FILTER(CHOOSE({1,2,3,4,5,6},_xlpm.names,_xlpm.stpos,_xlpm.time,_xlpm.base,_xlpm.hdcp,_xlpm.adj), _xlpm.adj<>""), _xlfn.SORTBY(_xlpm.data, INDEX(_xlpm.data,,6), -1, INDEX(_xlpm.data,,1), 1) )} -> #VALUE! | U4: {=_xlfn.LET( _xlpm.r,ROW()-ROW($U$4)+1, _xlpm.n,ROWS(_xlfn.ANCHORARRAY($V$4)), IF(_xlpm.r>_xlpm.n,"", _xlfn.LET( _xlpm.this,INDEX(_xlfn.ANCHORARRAY($V$4),_xlpm.r,6), _xlpm.pts,INDEX(_xlfn.ANCHORARRAY($V$4),0,6), IF(_xlpm.this="","",1+COUNTIF(_xlpm.pts,">"&_xlpm.this)) ) ) )} -> #REF! | V4: {=_xlfn.LET( _xlpm.names,'Stage Data - A'!$A$5:$A$50, _xlpm.stpos,'Stage Data - A'!P$5:P$50, _xlpm.time,'Stage Data - A'!Q$5:Q$50, _xlpm.base,'Stage Data - A'!R$5:R$50, _xlpm.hdcp,'Stage Data - A'!S$5:S$50, _xlpm.adj,'Stage Data - A'!T$5:T$50, _xlpm.data,_xlfn._xlws.FILTER(CHOOSE({1,2,3,4,5,6},_xlpm.names,_xlpm.stpos,_xlpm.time,_xlpm.base,_xlpm.hdcp,_xlpm.adj), _xlpm.adj<>""), _xlfn.SORTBY(_xlpm.data, INDEX(_xlpm.data,,6), -1, INDEX(_xlpm.data,,1), 1) )} -> #VALUE! | AC4: {=_xlfn.LET( _xlpm.r,ROW()-ROW($AC$4)+1, _xlpm.n,ROWS(_xlfn.ANCHORARRAY($AD$4)), IF(_xlpm.r>_xlpm.n,"", _xlfn.LET( _xlpm.this,INDEX(_xlfn.ANCHORARRAY($AD$4),_xlpm.r,6), _xlpm.pts,INDEX(_xlfn.ANCHORARRAY($AD$4),0,6), IF(_xlpm.this="","",1+COUNTIF(_xlpm.pts,">"&_xlpm.this)) ) ) )} -> #REF! | AD4: {=_xlfn.LET( _xlpm.names,'Stage Data - A'!$A$5:$A$50, _xlpm.stpos,'Stage Data - A'!V$5:V$50, _xlpm.time,'Stage Data - A'!W$5:W$50, _xlpm.base,'Stage Data - A'!X$5:X$50, _xlpm.hdcp,'Stage Data - A'!Y$5:Y$50, _xlpm.adj,'Stage Data - A'!Z$5:Z$50, _xlpm.data,_xlfn._xlws.FILTER(CHOOSE({1,2,3,4,5,6},_xlpm.names,_xlpm.stpos,_xlpm.time,_xlpm.base,_xlpm.hdcp,_xlpm.adj), _xlpm.adj<>""), _xlfn.SORTBY(_xlpm.data, INDEX(_xlpm.data,,6), -1, INDEX(_xlpm.data,,1), 1) )} -> #VALUE! | AK4: {=_xlfn.LET( _xlpm.r,ROW()-ROW($AK$4)+1, _xlpm.n,ROWS(_xlfn.ANCHORARRAY($AL$4)), IF(_xlpm.r>_xlpm.n,"", _xlfn.LET( _xlpm.this,INDEX(_xlfn.ANCHORARRAY($AL$4),_xlpm.r,6), _xlpm.pts,INDEX(_xlfn.ANCHORARRAY($AL$4),0,6), IF(_xlpm.this="","",1+COUNTIF(_xlpm.pts,">"&_xlpm.this)) ) ) )} -> #REF! | AL4: {=_xlfn.LET( _xlpm.names,'Stage Data - A'!$A$5:$A$50, _xlpm.stpos,'Stage Data - A'!AB$5:AB$50, _xlpm.time,'Stage Data - A'!AC$5:AC$50, _xlpm.base,'Stage Data - A'!AD$5:AD$50, _xlpm.hdcp,'Stage Data - A'!AE$5:AE$50, _xlpm.adj,'Stage Data - A'!AF$5:AF$50, _xlpm.data,_xlfn._xlws.FILTER(CHOOSE({1,2,3,4,5,6},_xlpm.names,_xlpm.stpos,_xlpm.time,_xlpm.base,_xlpm.hdcp,_xlpm.adj), _xlpm.adj<>""), _xlfn.SORTBY(_xlpm.data, INDEX(_xlpm.data,,6), -1, INDEX(_xlpm.data,,1), 1) )} -> #VALUE! | AS4: {=_xlfn.LET( _xlpm.r,ROW()-ROW($AS$4)+1, _xlpm.n,ROWS(_xlfn.ANCHORARRAY($AT$4)), IF(_xlpm.r>_xlpm.n,"", _xlfn.LET( _xlpm.this,INDEX(_xlfn.ANCHORARRAY($AT$4),_xlpm.r,6), _xlpm.pts,INDEX(_xlfn.ANCHORARRAY($AT$4),0,6), IF(_xlpm.this="","",1+COUNTIF(_xlpm.pts,">"&_xlpm.this)) ) ) )} -> #REF! | AT4: {=_xlfn.LET( _xlpm.names,'Stage Data - A'!$A$5:$A$50, _xlpm.stpos,'Stage Data - A'!AH$5:AH$50, _xlpm.time,'Stage Data - A'!AI$5:AI$50, _xlpm.base,'Stage Data - A'!AJ$5:AJ$50, _xlpm.hdcp,'Stage Data - A'!AK$5:AK$50, _xlpm.adj,'Stage Data - A'!AL$5:AL$50, _xlpm.data,_xlfn._xlws.FILTER(CHOOSE({1,2,3,4,5,6},_xlpm.names,_xlpm.stpos,_xlpm.time,_xlpm.base,_xlpm.hdcp,_xlpm.adj), _xlpm.adj<>""), _xlfn.SORTBY(_xlpm.data, INDEX(_xlpm.data,,6), -1, INDEX(_xlpm.data,,1), 1) )} -> #VALUE!
A5: {=_xlfn.LET( _xlpm.r,ROW()-ROW($A$4)+1, _xlpm.n,ROWS(_xlfn.ANCHORARRAY($B$4)), IF(_xlpm.r>_xlpm.n,"", _xlfn.LET( _xlpm.this,INDEX(_xlfn.ANCHORARRAY($B$4),_xlpm.r,2), _xlpm.pts,INDEX(_xlfn.ANCHORARRAY($B$4),0,2), IF(_xlpm.this="","",1+COUNTIF(_xlpm.pts,">"&_xlpm.this)) ) ) )} | E5: {=_xlfn.LET( _xlpm.r,ROW()-ROW($E$4)+1, _xlpm.n,ROWS(_xlfn.ANCHORARRAY($F$4)), IF(_xlpm.r>_xlpm.n,"", _xlfn.LET( _xlpm.this,INDEX(_xlfn.ANCHORARRAY($F$4),_xlpm.r,6), _xlpm.pts,INDEX(_xlfn.ANCHORARRAY($F$4),0,6), IF(_xlpm.this="","",1+COUNTIF(_xlpm.pts,">"&_xlpm.this)) ) ) )} | M5: {=_xlfn.LET( _xlpm.r,ROW()-ROW($M$4)+1, _xlpm.n,ROWS(_xlfn.ANCHORARRAY($N$4)), IF(_xlpm.r>_xlpm.n,"", _xlfn.LET( _xlpm.this,INDEX(_xlfn.ANCHORARRAY($N$4),_xlpm.r,6), _xlpm.pts,INDEX(_xlfn.ANCHORARRAY($N$4),0,6), IF(_xlpm.this="","",1+COUNTIF(_xlpm.pts,">"&_xlpm.this)) ) ) )} | U5: {=_xlfn.LET( _xlpm.r,ROW()-ROW($U$4)+1, _xlpm.n,ROWS(_xlfn.ANCHORARRAY($V$4)), IF(_xlpm.r>_xlpm.n,"", _xlfn.LET( _xlpm.this,INDEX(_xlfn.ANCHORARRAY($V$4),_xlpm.r,6), _xlpm.pts,INDEX(_xlfn.ANCHORARRAY($V$4),0,6), IF(_xlpm.this="","",1+COUNTIF(_xlpm.pts,">"&_xlpm.this)) ) ) )} | AC5: {=_xlfn.LET( _xlpm.r,ROW()-ROW($AC$4)+1, _xlpm.n,ROWS(_xlfn.ANCHORARRAY($AD$4)), IF(_xlpm.r>_xlpm.n,"", _xlfn.LET( _xlpm.this,INDEX(_xlfn.ANCHORARRAY($AD$4),_xlpm.r,6), _xlpm.pts,INDEX(_xlfn.ANCHORARRAY($AD$4),0,6), IF(_xlpm.this="","",1+COUNTIF(_xlpm.pts,">"&_xlpm.this)) ) ) )} | AK5: {=_xlfn.LET( _xlpm.r,ROW()-ROW($AK$4)+1, _xlpm.n,ROWS(_xlfn.ANCHORARRAY($AL$4)), IF(_xlpm.r>_xlpm.n,"", _xlfn.LET( _xlpm.this,INDEX(_xlfn.ANCHORARRAY($AL$4),_xlpm.r,6), _xlpm.pts,INDEX(_xlfn.ANCHORARRAY($AL$4),0,6), IF(_xlpm.this="","",1+COUNTIF(_xlpm.pts,">"&_xlpm.this)) ) ) )} | AS5: {=_xlfn.LET( _xlpm.r,ROW()-ROW($AS$4)+1, _xlpm.n,ROWS(_xlfn.ANCHORARRAY($AT$4)), IF(_xlpm.r>_xlpm.n,"", _xlfn.LET( _xlpm.this,INDEX(_xlfn.ANCHORARRAY($AT$4),_xlpm.r,6), _xlpm.pts,INDEX(_xlfn.ANCHORARRAY($AT$4),0,6), IF(_xlpm.this="","",1+COUNTIF(_xlpm.pts,">"&_xlpm.this)) ) ) )}
A6: {=_xlfn.LET( _xlpm.r,ROW()-ROW($A$4)+1, _xlpm.n,ROWS(_xlfn.ANCHORARRAY($B$4)), IF(_xlpm.r>_xlpm.n,"", _xlfn.LET( _xlpm.this,INDEX(_xlfn.ANCHORARRAY($B$4),_xlpm.r,2), _xlpm.pts,INDEX(_xlfn.ANCHORARRAY($B$4),0,2), IF(_xlpm.this="","",1+COUNTIF(_xlpm.pts,">"&_xlpm.this)) ) ) )} | E6: {=_xlfn.LET( _xlpm.r,ROW()-ROW($E$4)+1, _xlpm.n,ROWS(_xlfn.ANCHORARRAY($F$4)), IF(_xlpm.r>_xlpm.n,"", _xlfn.LET( _xlpm.this,INDEX(_xlfn.ANCHORARRAY($F$4),_xlpm.r,6), _xlpm.pts,INDEX(_xlfn.ANCHORARRAY($F$4),0,6), IF(_xlpm.this="","",1+COUNTIF(_xlpm.pts,">"&_xlpm.this)) ) ) )} | M6: {=_xlfn.LET( _xlpm.r,ROW()-ROW($M$4)+1, _xlpm.n,ROWS(_xlfn.ANCHORARRAY($N$4)), IF(_xlpm.r>_xlpm.n,"", _xlfn.LET( _xlpm.this,INDEX(_xlfn.ANCHORARRAY($N$4),_xlpm.r,6), _xlpm.pts,INDEX(_xlfn.ANCHORARRAY($N$4),0,6), IF(_xlpm.this="","",1+COUNTIF(_xlpm.pts,">"&_xlpm.this)) ) ) )} | U6: {=_xlfn.LET( _xlpm.r,ROW()-ROW($U$4)+1, _xlpm.n,ROWS(_xlfn.ANCHORARRAY($V$4)), IF(_xlpm.r>_xlpm.n,"", _xlfn.LET( _xlpm.this,INDEX(_xlfn.ANCHORARRAY($V$4),_xlpm.r,6), _xlpm.pts,INDEX(_xlfn.ANCHORARRAY($V$4),0,6), IF(_xlpm.this="","",1+COUNTIF(_xlpm.pts,">"&_xlpm.this)) ) ) )} | AC6: {=_xlfn.LET( _xlpm.r,ROW()-ROW($AC$4)+1, _xlpm.n,ROWS(_xlfn.ANCHORARRAY($AD$4)), IF(_xlpm.r>_xlpm.n,"", _xlfn.LET( _xlpm.this,INDEX(_xlfn.ANCHORARRAY($AD$4),_xlpm.r,6), _xlpm.pts,INDEX(_xlfn.ANCHORARRAY($AD$4),0,6), IF(_xlpm.this="","",1+COUNTIF(_xlpm.pts,">"&_xlpm.this)) ) ) )} | AK6: {=_xlfn.LET( _xlpm.r,ROW()-ROW($AK$4)+1, _xlpm.n,ROWS(_xlfn.ANCHORARRAY($AL$4)), IF(_xlpm.r>_xlpm.n,"", _xlfn.LET( _xlpm.this,INDEX(_xlfn.ANCHORARRAY($AL$4),_xlpm.r,6), _xlpm.pts,INDEX(_xlfn.ANCHORARRAY($AL$4),0,6), IF(_xlpm.this="","",1+COUNTIF(_xlpm.pts,">"&_xlpm.this)) ) ) )} | AS6: {=_xlfn.LET( _xlpm.r,ROW()-ROW($AS$4)+1, _xlpm.n,ROWS(_xlfn.ANCHORARRAY($AT$4)), IF(_xlpm.r>_xlpm.n,"", _xlfn.LET( _xlpm.this,INDEX(_xlfn.ANCHORARRAY($AT$4),_xlpm.r,6), _xlpm.pts,INDEX(_xlfn.ANCHORARRAY($AT$4),0,6), IF(_xlpm.this="","",1+COUNTIF(_xlpm.pts,">"&_xlpm.this)) ) ) )}
A7: {=_xlfn.LET( _xlpm.r,ROW()-ROW($A$4)+1, _xlpm.n,ROWS(_xlfn.ANCHORARRAY($B$4)), IF(_xlpm.r>_xlpm.n,"", _xlfn.LET( _xlpm.this,INDEX(_xlfn.ANCHORARRAY($B$4),_xlpm.r,2), _xlpm.pts,INDEX(_xlfn.ANCHORARRAY($B$4),0,2), IF(_xlpm.this="","",1+COUNTIF(_xlpm.pts,">"&_xlpm.this)) ) ) )} | E7: {=_xlfn.LET( _xlpm.r,ROW()-ROW($E$4)+1, _xlpm.n,ROWS(_xlfn.ANCHORARRAY($F$4)), IF(_xlpm.r>_xlpm.n,"", _xlfn.LET( _xlpm.this,INDEX(_xlfn.ANCHORARRAY($F$4),_xlpm.r,6), _xlpm.pts,INDEX(_xlfn.ANCHORARRAY($F$4),0,6), IF(_xlpm.this="","",1+COUNTIF(_xlpm.pts,">"&_xlpm.this)) ) ) )} | M7: {=_xlfn.LET( _xlpm.r,ROW()-ROW($M$4)+1, _xlpm.n,ROWS(_xlfn.ANCHORARRAY($N$4)), IF(_xlpm.r>_xlpm.n,"", _xlfn.LET( _xlpm.this,INDEX(_xlfn.ANCHORARRAY($N$4),_xlpm.r,6), _xlpm.pts,INDEX(_xlfn.ANCHORARRAY($N$4),0,6), IF(_xlpm.this="","",1+COUNTIF(_xlpm.pts,">"&_xlpm.this)) ) ) )} | U7: {=_xlfn.LET( _xlpm.r,ROW()-ROW($U$4)+1, _xlpm.n,ROWS(_xlfn.ANCHORARRAY($V$4)), IF(_xlpm.r>_xlpm.n,"", _xlfn.LET( _xlpm.this,INDEX(_xlfn.ANCHORARRAY($V$4),_xlpm.r,6), _xlpm.pts,INDEX(_xlfn.ANCHORARRAY($V$4),0,6), IF(_xlpm.this="","",1+COUNTIF(_xlpm.pts,">"&_xlpm.this)) ) ) )} | AC7: {=_xlfn.LET( _xlpm.r,ROW()-ROW($AC$4)+1, _xlpm.n,ROWS(_xlfn.ANCHORARRAY($AD$4)), IF(_xlpm.r>_xlpm.n,"", _xlfn.LET( _xlpm.this,INDEX(_xlfn.ANCHORARRAY($AD$4),_xlpm.r,6), _xlpm.pts,INDEX(_xlfn.ANCHORARRAY($AD$4),0,6), IF(_xlpm.this="","",1+COUNTIF(_xlpm.pts,">"&_xlpm.this)) ) ) )} | AK7: {=_xlfn.LET( _xlpm.r,ROW()-ROW($AK$4)+1, _xlpm.n,ROWS(_xlfn.ANCHORARRAY($AL$4)), IF(_xlpm.r>_xlpm.n,"", _xlfn.LET( _xlpm.this,INDEX(_xlfn.ANCHORARRAY($AL$4),_xlpm.r,6), _xlpm.pts,INDEX(_xlfn.ANCHORARRAY($AL$4),0,6), IF(_xlpm.this="","",1+COUNTIF(_xlpm.pts,">"&_xlpm.this)) ) ) )} | AS7: {=_xlfn.LET( _xlpm.r,ROW()-ROW($AS$4)+1, _xlpm.n,ROWS(_xlfn.ANCHORARRAY($AT$4)), IF(_xlpm.r>_xlpm.n,"", _xlfn.LET( _xlpm.this,INDEX(_xlfn.ANCHORARRAY($AT$4),_xlpm.r,6), _xlpm.pts,INDEX(_xlfn.ANCHORARRAY($AT$4),0,6), IF(_xlpm.this="","",1+COUNTIF(_xlpm.pts,">"&_xlpm.this)) ) ) )}
A8: {=_xlfn.LET( _xlpm.r,ROW()-ROW($A$4)+1, _xlpm.n,ROWS(_xlfn.ANCHORARRAY($B$4)), IF(_xlpm.r>_xlpm.n,"", _xlfn.LET( _xlpm.this,INDEX(_xlfn.ANCHORARRAY($B$4),_xlpm.r,2), _xlpm.pts,INDEX(_xlfn.ANCHORARRAY($B$4),0,2), IF(_xlpm.this="","",1+COUNTIF(_xlpm.pts,">"&_xlpm.this)) ) ) )} | E8: {=_xlfn.LET( _xlpm.r,ROW()-ROW($E$4)+1, _xlpm.n,ROWS(_xlfn.ANCHORARRAY($F$4)), IF(_xlpm.r>_xlpm.n,"", _xlfn.LET( _xlpm.this,INDEX(_xlfn.ANCHORARRAY($F$4),_xlpm.r,6), _xlpm.pts,INDEX(_xlfn.ANCHORARRAY($F$4),0,6), IF(_xlpm.this="","",1+COUNTIF(_xlpm.pts,">"&_xlpm.this)) ) ) )} | M8: {=_xlfn.LET( _xlpm.r,ROW()-ROW($M$4)+1, _xlpm.n,ROWS(_xlfn.ANCHORARRAY($N$4)), IF(_xlpm.r>_xlpm.n,"", _xlfn.LET( _xlpm.this,INDEX(_xlfn.ANCHORARRAY($N$4),_xlpm.r,6), _xlpm.pts,INDEX(_xlfn.ANCHORARRAY($N$4),0,6), IF(_xlpm.this="","",1+COUNTIF(_xlpm.pts,">"&_xlpm.this)) ) ) )} | U8: {=_xlfn.LET( _xlpm.r,ROW()-ROW($U$4)+1, _xlpm.n,ROWS(_xlfn.ANCHORARRAY($V$4)), IF(_xlpm.r>_xlpm.n,"", _xlfn.LET( _xlpm.this,INDEX(_xlfn.ANCHORARRAY($V$4),_xlpm.r,6), _xlpm.pts,INDEX(_xlfn.ANCHORARRAY($V$4),0,6), IF(_xlpm.this="","",1+COUNTIF(_xlpm.pts,">"&_xlpm.this)) ) ) )} | AC8: {=_xlfn.LET( _xlpm.r,ROW()-ROW($AC$4)+1, _xlpm.n,ROWS(_xlfn.ANCHORARRAY($AD$4)), IF(_xlpm.r>_xlpm.n,"", _xlfn.LET( _xlpm.this,INDEX(_xlfn.ANCHORARRAY($AD$4),_xlpm.r,6), _xlpm.pts,INDEX(_xlfn.ANCHORARRAY($AD$4),0,6), IF(_xlpm.this="","",1+COUNTIF(_xlpm.pts,">"&_xlpm.this)) ) ) )} | AK8: {=_xlfn.LET( _xlpm.r,ROW()-ROW($AK$4)+1, _xlpm.n,ROWS(_xlfn.ANCHORARRAY($AL$4)), IF(_xlpm.r>_xlpm.n,"", _xlfn.LET( _xlpm.this,INDEX(_xlfn.ANCHORARRAY($AL$4),_xlpm.r,6), _xlpm.pts,INDEX(_xlfn.ANCHORARRAY($AL$4),0,6), IF(_xlpm.this="","",1+COUNTIF(_xlpm.pts,">"&_xlpm.this)) ) ) )} | AS8: {=_xlfn.LET( _xlpm.r,ROW()-ROW($AS$4)+1, _xlpm.n,ROWS(_xlfn.ANCHORARRAY($AT$4)), IF(_xlpm.r>_xlpm.n,"", _xlfn.LET( _xlpm.this,INDEX(_xlfn.ANCHORARRAY($AT$4),_xlpm.r,6), _xlpm.pts,INDEX(_xlfn.ANCHORARRAY($AT$4),0,6), IF(_xlpm.this="","",1+COUNTIF(_xlpm.pts,">"&_xlpm.this)) ) ) )}
